Workbook

Sheet 1.지출통계
A1: ■2026년 산업안전관리비 지출현황 통계
A2: ▶ [지출내역] 시트 데이터를 SUMIFS 함수로 자동 집계합니다. 지출내역 입력 즉시 반영됩니다.
A3: 본부 | B3: 항목 | C3: 1월 | D3: 2월 | E3: 3월 | F3: 4월 | G3: 5월 | H3: 6월 | I3: 7월 | J3: 8월 | K3: 9월 | L3: 10월 | M3: 11월 | N3: 12월 | O3: 합계 | P3: 산보위 건수
A4: 본사 | B4: 안전관리자 등 인건비 | C4: =IFERROR(SUMIFS(사용내역!$H$3:$H$2003,사용내역!$C$3:$C$2003,"본사",사용내역!$E$3:$E$2003,1,사용내역!$F$3:$F$2003,"안전관리자 등 인건비"),0) -> 0 | D4: =IFERROR(SUMIFS(사용내역!$H$3:$H$2003,사용내역!$C$3:$C$2003,"본사",사용내역!$E$3:$E$2003,2,사용내역!$F$3:$F$2003,"안전관리자 등 인건비"),0) -> 0 | E4: =IFERROR(SUMIFS(사용내역!$H$3:$H$2003,사용내역!$C$3:$C$2003,"본사",사용내역!$E$3:$E$2003,3,사용내역!$F$3:$F$2003,"안전관리자 등 인건비"),0) -> 0 | F4: =IFERROR(SUMIFS(사용내역!$H$3:$H$2003,사용내역!$C$3:$C$2003,"본사",사용내역!$E$3:$E$2003,4,사용내역!$F$3:$F$2003,"안전관리자 등 인건비"),0) -> 0 | G4: =IFERROR(SUMIFS(사용내역!$H$3:$H$2003,사용내역!$C$3:$C$2003,"본사",사용내역!$E$3:$E$2003,5,사용내역!$F$3:$F$2003,"안전관리자 등 인건비"),0) -> 0 | H4: =IFERROR(SUMIFS(사용내역!$H$3:$H$2003,사용내역!$C$3:$C$2003,"본사",사용내역!$E$3:$E$2003,6,사용내역!$F$3:$F$2003,"안전관리자 등 인건비"),0) -> 0 | I4: =IFERROR(SUMIFS(사용내역!$H$3:$H$2003,사용내역!$C$3:$C$2003,"본사",사용내역!$E$3:$E$2003,7,사용내역!$F$3:$F$2003,"안전관리자 등 인건비"),0) -> 0 | J4: =IFERROR(SUMIFS(사용내역!$H$3:$H$2003,사용내역!$C$3:$C$2003,"본사",사용내역!$E$3:$E$2003,8,사용내역!$F$3:$F$2003,"안전관리자 등 인건비"),0) -> 0 | K4: =IFERROR(SUMIFS(사용내역!$H$3:$H$2003,사용내역!$C$3:$C$2003,"본사",사용내역!$E$3:$E$2003,9,사용내역!$F$3:$F$2003,"안전관리자 등 인건비"),0) -> 0 | L4: =IFERROR(SUMIFS(사용내역!$H$3:$H$2003,사용내역!$C$3:$C$2003,"본사",사용내역!$E$3:$E$2003,10,사용내역!$F$3:$F$2003,"안전관리자 등 인건비"),0) -> 0 | M4: =IFERROR(SUMIFS(사용내역!$H$3:$H$2003,사용내역!$C$3:$C$2003,"본사",사용내역!$E$3:$E$2003,11,사용내역!$F$3:$F$2003,"안전관리자 등 인건비"),0) -> 0 | N4: =IFERROR(SUMIFS(사용내역!$H$3:$H$2003,사용내역!$C$3:$C$2003,"본사",사용내역!$E$3:$E$2003,12,사용내역!$F$3:$F$2003,"안전관리자 등 인건비"),0) -> 0 | O4: =SUM(C4:N4) -> 0 | P4: =IFERROR(COUNTIFS(사용내역!$C$3:$C$2003,"본사",사용내역!$F$3:$F$2003,"안전관리자 등 인건비",사용내역!$J$3:$J$2003,"Y"),0) -> 0
B5: 안전시설비 | C5: =IFERROR(SUMIFS(사용내역!$H$3:$H$2003,사용내역!$C$3:$C$2003,"본사",사용내역!$E$3:$E$2003,1,사용내역!$F$3:$F$2003,"안전시설비"),0) -> 0 | D5: =IFERROR(SUMIFS(사용내역!$H$3:$H$2003,사용내역!$C$3:$C$2003,"본사",사용내역!$E$3:$E$2003,2,사용내역!$F$3:$F$2003,"안전시설비"),0) -> 0 | E5: =IFERROR(SUMIFS(사용내역!$H$3:$H$2003,사용내역!$C$3:$C$2003,"본사",사용내역!$E$3:$E$2003,3,사용내역!$F$3:$F$2003,"안전시설비"),0) -> 0 | F5: =IFERROR(SUMIFS(사용내역!$H$3:$H$2003,사용내역!$C$3:$C$2003,"본사",사용내역!$E$3:$E$2003,4,사용내역!$F$3:$F$2003,"안전시설비"),0) -> 0 | G5: =IFERROR(SUMIFS(사용내역!$H$3:$H$2003,사용내역!$C$3:$C$2003,"본사",사용내역!$E$3:$E$2003,5,사용내역!$F$3:$F$2003,"안전시설비"),0) -> 0 | H5: =IFERROR(SUMIFS(사용내역!$H$3:$H$2003,사용내역!$C$3:$C$2003,"본사",사용내역!$E$3:$E$2003,6,사용내역!$F$3:$F$2003,"안전시설비"),0) -> 0 | I5: =IFERROR(SUMIFS(사용내역!$H$3:$H$2003,사용내역!$C$3:$C$2003,"본사",사용내역!$E$3:$E$2003,7,사용내역!$F$3:$F$2003,"안전시설비"),0) -> 0 | J5: =IFERROR(SUMIFS(사용내역!$H$3:$H$2003,사용내역!$C$3:$C$2003,"본사",사용내역!$E$3:$E$2003,8,사용내역!$F$3:$F$2003,"안전시설비"),0) -> 0 | K5: =IFERROR(SUMIFS(사용내역!$H$3:$H$2003,사용내역!$C$3:$C$2003,"본사",사용내역!$E$3:$E$2003,9,사용내역!$F$3:$F$2003,"안전시설비"),0) -> 0 | L5: =IFERROR(SUMIFS(사용내역!$H$3:$H$2003,사용내역!$C$3:$C$2003,"본사",사용내역!$E$3:$E$2003,10,사용내역!$F$3:$F$2003,"안전시설비"),0) -> 0 | M5: =IFERROR(SUMIFS(사용내역!$H$3:$H$2003,사용내역!$C$3:$C$2003,"본사",사용내역!$E$3:$E$2003,11,사용내역!$F$3:$F$2003,"안전시설비"),0) -> 0 | N5: =IFERROR(SUMIFS(사용내역!$H$3:$H$2003,사용내역!$C$3:$C$2003,"본사",사용내역!$E$3:$E$2003,12,사용내역!$F$3:$F$2003,"안전시설비"),0) -> 0 | O5: =SUM(C5:N5) -> 0 | P5: =IFERROR(COUNTIFS(사용내역!$C$3:$C$2003,"본사",사용내역!$F$3:$F$2003,"안전시설비",사용내역!$J$3:$J$2003,"Y"),0) -> 0
B6: 보호구·안전용품 | C6: =IFERROR(SUMIFS(사용내역!$H$3:$H$2003,사용내역!$C$3:$C$2003,"본사",사용내역!$E$3:$E$2003,1,사용내역!$F$3:$F$2003,"보호구·안전용품"),0) -> 0 | D6: =IFERROR(SUMIFS(사용내역!$H$3:$H$2003,사용내역!$C$3:$C$2003,"본사",사용내역!$E$3:$E$2003,2,사용내역!$F$3:$F$2003,"보호구·안전용품"),0) -> 0 | E6: =IFERROR(SUMIFS(사용내역!$H$3:$H$2003,사용내역!$C$3:$C$2003,"본사",사용내역!$E$3:$E$2003,3,사용내역!$F$3:$F$2003,"보호구·안전용품"),0) -> 0 | F6: =IFERROR(SUMIFS(사용내역!$H$3:$H$2003,사용내역!$C$3:$C$2003,"본사",사용내역!$E$3:$E$2003,4,사용내역!$F$3:$F$2003,"보호구·안전용품"),0) -> 0 | G6: =IFERROR(SUMIFS(사용내역!$H$3:$H$2003,사용내역!$C$3:$C$2003,"본사",사용내역!$E$3:$E$2003,5,사용내역!$F$3:$F$2003,"보호구·안전용품"),0) -> 0 | H6: =IFERROR(SUMIFS(사용내역!$H$3:$H$2003,사용내역!$C$3:$C$2003,"본사",사용내역!$E$3:$E$2003,6,사용내역!$F$3:$F$2003,"보호구·안전용품"),0) -> 0 | I6: =IFERROR(SUMIFS(사용내역!$H$3:$H$2003,사용내역!$C$3:$C$2003,"본사",사용내역!$E$3:$E$2003,7,사용내역!$F$3:$F$2003,"보호구·안전용품"),0) -> 0 | J6: =IFERROR(SUMIFS(사용내역!$H$3:$H$2003,사용내역!$C$3:$C$2003,"본사",사용내역!$E$3:$E$2003,8,사용내역!$F$3:$F$2003,"보호구·안전용품"),0) -> 0 | K6: =IFERROR(SUMIFS(사용내역!$H$3:$H$2003,사용내역!$C$3:$C$2003,"본사",사용내역!$E$3:$E$2003,9,사용내역!$F$3:$F$2003,"보호구·안전용품"),0) -> 0 | L6: =IFERROR(SUMIFS(사용내역!$H$3:$H$2003,사용내역!$C$3:$C$2003,"본사",사용내역!$E$3:$E$2003,10,사용내역!$F$3:$F$2003,"보호구·안전용품"),0) -> 0 | M6: =IFERROR(SUMIFS(사용내역!$H$3:$H$2003,사용내역!$C$3:$C$2003,"본사",사용내역!$E$3:$E$2003,11,사용내역!$F$3:$F$2003,"보호구·안전용품"),0) -> 0 | N6: =IFERROR(SUMIFS(사용내역!$H$3:$H$2003,사용내역!$C$3:$C$2003,"본사",사용내역!$E$3:$E$2003,12,사용내역!$F$3:$F$2003,"보호구·안전용품"),0) -> 0 | O6: =SUM(C6:N6) -> 0 | P6: =IFERROR(COUNTIFS(사용내역!$C$3:$C$2003,"본사",사용내역!$F$3:$F$2003,"보호구·안전용품",사용내역!$J$3:$J$2003,"Y"),0) -> 0
B7: 안전진단비 | C7: =IFERROR(SUMIFS(사용내역!$H$3:$H$2003,사용내역!$C$3:$C$2003,"본사",사용내역!$E$3:$E$2003,1,사용내역!$F$3:$F$2003,"안전진단비"),0) -> 0 | D7: =IFERROR(SUMIFS(사용내역!$H$3:$H$2003,사용내역!$C$3:$C$2003,"본사",사용내역!$E$3:$E$2003,2,사용내역!$F$3:$F$2003,"안전진단비"),0) -> 0 | E7: =IFERROR(SUMIFS(사용내역!$H$3:$H$2003,사용내역!$C$3:$C$2003,"본사",사용내역!$E$3:$E$2003,3,사용내역!$F$3:$F$2003,"안전진단비"),0) -> 0 | F7: =IFERROR(SUMIFS(사용내역!$H$3:$H$2003,사용내역!$C$3:$C$2003,"본사",사용내역!$E$3:$E$2003,4,사용내역!$F$3:$F$2003,"안전진단비"),0) -> 0 | G7: =IFERROR(SUMIFS(사용내역!$H$3:$H$2003,사용내역!$C$3:$C$2003,"본사",사용내역!$E$3:$E$2003,5,사용내역!$F$3:$F$2003,"안전진단비"),0) -> 0 | H7: =IFERROR(SUMIFS(사용내역!$H$3:$H$2003,사용내역!$C$3:$C$2003,"본사",사용내역!$E$3:$E$2003,6,사용내역!$F$3:$F$2003,"안전진단비"),0) -> 0 | I7: =IFERROR(SUMIFS(사용내역!$H$3:$H$2003,사용내역!$C$3:$C$2003,"본사",사용내역!$E$3:$E$2003,7,사용내역!$F$3:$F$2003,"안전진단비"),0) -> 0 | J7: =IFERROR(SUMIFS(사용내역!$H$3:$H$2003,사용내역!$C$3:$C$2003,"본사",사용내역!$E$3:$E$2003,8,사용내역!$F$3:$F$2003,"안전진단비"),0) -> 0 | K7: =IFERROR(SUMIFS(사용내역!$H$3:$H$2003,사용내역!$C$3:$C$2003,"본사",사용내역!$E$3:$E$2003,9,사용내역!$F$3:$F$2003,"안전진단비"),0) -> 0 | L7: =IFERROR(SUMIFS(사용내역!$H$3:$H$2003,사용내역!$C$3:$C$2003,"본사",사용내역!$E$3:$E$2003,10,사용내역!$F$3:$F$2003,"안전진단비"),0) -> 0 | M7: =IFERROR(SUMIFS(사용내역!$H$3:$H$2003,사용내역!$C$3:$C$2003,"본사",사용내역!$E$3:$E$2003,11,사용내역!$F$3:$F$2003,"안전진단비"),0) -> 0 | N7: =IFERROR(SUMIFS(사용내역!$H$3:$H$2003,사용내역!$C$3:$C$2003,"본사",사용내역!$E$3:$E$2003,12,사용내역!$F$3:$F$2003,"안전진단비"),0) -> 0 | O7: =SUM(C7:N7) -> 0 | P7: =IFERROR(COUNTIFS(사용내역!$C$3:$C$2003,"본사",사용내역!$F$3:$F$2003,"안전진단비",사용내역!$J$3:$J$2003,"Y"),0) -> 0
B8: 안전보건교육비·행사비 등 | C8: =IFERROR(SUMIFS(사용내역!$H$3:$H$2003,사용내역!$C$3:$C$2003,"본사",사용내역!$E$3:$E$2003,1,사용내역!$F$3:$F$2003,"안전보건교육비·행사비 등"),0) -> 0 | D8: =IFERROR(SUMIFS(사용내역!$H$3:$H$2003,사용내역!$C$3:$C$2003,"본사",사용내역!$E$3:$E$2003,2,사용내역!$F$3:$F$2003,"안전보건교육비·행사비 등"),0) -> 0 | E8: =IFERROR(SUMIFS(사용내역!$H$3:$H$2003,사용내역!$C$3:$C$2003,"본사",사용내역!$E$3:$E$2003,3,사용내역!$F$3:$F$2003,"안전보건교육비·행사비 등"),0) -> 0 | F8: =IFERROR(SUMIFS(사용내역!$H$3:$H$2003,사용내역!$C$3:$C$2003,"본사",사용내역!$E$3:$E$2003,4,사용내역!$F$3:$F$2003,"안전보건교육비·행사비 등"),0) -> 0 | G8: =IFERROR(SUMIFS(사용내역!$H$3:$H$2003,사용내역!$C$3:$C$2003,"본사",사용내역!$E$3:$E$2003,5,사용내역!$F$3:$F$2003,"안전보건교육비·행사비 등"),0) -> 0 | H8: =IFERROR(SUMIFS(사용내역!$H$3:$H$2003,사용내역!$C$3:$C$2003,"본사",사용내역!$E$3:$E$2003,6,사용내역!$F$3:$F$2003,"안전보건교육비·행사비 등"),0) -> 0 | I8: =IFERROR(SUMIFS(사용내역!$H$3:$H$2003,사용내역!$C$3:$C$2003,"본사",사용내역!$E$3:$E$2003,7,사용내역!$F$3:$F$2003,"안전보건교육비·행사비 등"),0) -> 0 | J8: =IFERROR(SUMIFS(사용내역!$H$3:$H$2003,사용내역!$C$3:$C$2003,"본사",사용내역!$E$3:$E$2003,8,사용내역!$F$3:$F$2003,"안전보건교육비·행사비 등"),0) -> 0 | K8: =IFERROR(SUMIFS(사용내역!$H$3:$H$2003,사용내역!$C$3:$C$2003,"본사",사용내역!$E$3:$E$2003,9,사용내역!$F$3:$F$2003,"안전보건교육비·행사비 등"),0) -> 0 | L8: =IFERROR(SUMIFS(사용내역!$H$3:$H$2003,사용내역!$C$3:$C$2003,"본사",사용내역!$E$3:$E$2003,10,사용내역!$F$3:$F$2003,"안전보건교육비·행사비 등"),0) -> 0 | M8: =IFERROR(SUMIFS(사용내역!$H$3:$H$2003,사용내역!$C$3:$C$2003,"본사",사용내역!$E$3:$E$2003,11,사용내역!$F$3:$F$2003,"안전보건교육비·행사비 등"),0) -> 0 | N8: =IFERROR(SUMIFS(사용내역!$H$3:$H$2003,사용내역!$C$3:$C$2003,"본사",사용내역!$E$3:$E$2003,12,사용내역!$F$3:$F$2003,"안전보건교육비·행사비 등"),0) -> 0 | O8: =SUM(C8:N8) -> 0 | P8: =IFERROR(COUNTIFS(사용내역!$C$3:$C$2003,"본사",사용내역!$F$3:$F$2003,"안전보건교육비·행사비 등",사용내역!$J$3:$J$2003,"Y"),0) -> 0
B9: 근로자 건강관리비 등 | C9: =IFERROR(SUMIFS(사용내역!$H$3:$H$2003,사용내역!$C$3:$C$2003,"본사",사용내역!$E$3:$E$2003,1,사용내역!$F$3:$F$2003,"근로자 건강관리비 등"),0) -> 0 | D9: =IFERROR(SUMIFS(사용내역!$H$3:$H$2003,사용내역!$C$3:$C$2003,"본사",사용내역!$E$3:$E$2003,2,사용내역!$F$3:$F$2003,"근로자 건강관리비 등"),0) -> 0 | E9: =IFERROR(SUMIFS(사용내역!$H$3:$H$2003,사용내역!$C$3:$C$2003,"본사",사용내역!$E$3:$E$2003,3,사용내역!$F$3:$F$2003,"근로자 건강관리비 등"),0) -> 0 | F9: =IFERROR(SUMIFS(사용내역!$H$3:$H$2003,사용내역!$C$3:$C$2003,"본사",사용내역!$E$3:$E$2003,4,사용내역!$F$3:$F$2003,"근로자 건강관리비 등"),0) -> 0 | G9: =IFERROR(SUMIFS(사용내역!$H$3:$H$2003,사용내역!$C$3:$C$2003,"본사",사용내역!$E$3:$E$2003,5,사용내역!$F$3:$F$2003,"근로자 건강관리비 등"),0) -> 0 | H9: =IFERROR(SUMIFS(사용내역!$H$3:$H$2003,사용내역!$C$3:$C$2003,"본사",사용내역!$E$3:$E$2003,6,사용내역!$F$3:$F$2003,"근로자 건강관리비 등"),0) -> 0 | I9: =IFERROR(SUMIFS(사용내역!$H$3:$H$2003,사용내역!$C$3:$C$2003,"본사",사용내역!$E$3:$E$2003,7,사용내역!$F$3:$F$2003,"근로자 건강관리비 등"),0) -> 0 | J9: =IFERROR(SUMIFS(사용내역!$H$3:$H$2003,사용내역!$C$3:$C$2003,"본사",사용내역!$E$3:$E$2003,8,사용내역!$F$3:$F$2003,"근로자 건강관리비 등"),0) -> 0 | K9: =IFERROR(SUMIFS(사용내역!$H$3:$H$2003,사용내역!$C$3:$C$2003,"본사",사용내역!$E$3:$E$2003,9,사용내역!$F$3:$F$2003,"근로자 건강관리비 등"),0) -> 0 | L9: =IFERROR(SUMIFS(사용내역!$H$3:$H$2003,사용내역!$C$3:$C$2003,"본사",사용내역!$E$3:$E$2003,10,사용내역!$F$3:$F$2003,"근로자 건강관리비 등"),0) -> 0 | M9: =IFERROR(SUMIFS(사용내역!$H$3:$H$2003,사용내역!$C$3:$C$2003,"본사",사용내역!$E$3:$E$2003,11,사용내역!$F$3:$F$2003,"근로자 건강관리비 등"),0) -> 0 | N9: =IFERROR(SUMIFS(사용내역!$H$3:$H$2003,사용내역!$C$3:$C$2003,"본사",사용내역!$E$3:$E$2003,12,사용내역!$F$3:$F$2003,"근로자 건강관리비 등"),0) -> 0 | O9: =SUM(C9:N9) -> 0 | P9: =IFERROR(COUNTIFS(사용내역!$C$3:$C$2003,"본사",사용내역!$F$3:$F$2003,"근로자 건강관리비 등",사용내역!$J$3:$J$2003,"Y"),0) -> 0
B10: 건설재해예방 기술지도비 | C10: =IFERROR(SUMIFS(사용내역!$H$3:$H$2003,사용내역!$C$3:$C$2003,"본사",사용내역!$E$3:$E$2003,1,사용내역!$F$3:$F$2003,"건설재해예방 기술지도비"),0) -> 0 | D10: =IFERROR(SUMIFS(사용내역!$H$3:$H$2003,사용내역!$C$3:$C$2003,"본사",사용내역!$E$3:$E$2003,2,사용내역!$F$3:$F$2003,"건설재해예방 기술지도비"),0) -> 0 | E10: =IFERROR(SUMIFS(사용내역!$H$3:$H$2003,사용내역!$C$3:$C$2003,"본사",사용내역!$E$3:$E$2003,3,사용내역!$F$3:$F$2003,"건설재해예방 기술지도비"),0) -> 0 | F10: =IFERROR(SUMIFS(사용내역!$H$3:$H$2003,사용내역!$C$3:$C$2003,"본사",사용내역!$E$3:$E$2003,4,사용내역!$F$3:$F$2003,"건설재해예방 기술지도비"),0) -> 0 | G10: =IFERROR(SUMIFS(사용내역!$H$3:$H$2003,사용내역!$C$3:$C$2003,"본사",사용내역!$E$3:$E$2003,5,사용내역!$F$3:$F$2003,"건설재해예방 기술지도비"),0) -> 0 | H10: =IFERROR(SUMIFS(사용내역!$H$3:$H$2003,사용내역!$C$3:$C$2003,"본사",사용내역!$E$3:$E$2003,6,사용내역!$F$3:$F$2003,"건설재해예방 기술지도비"),0) -> 0 | I10: =IFERROR(SUMIFS(사용내역!$H$3:$H$2003,사용내역!$C$3:$C$2003,"본사",사용내역!$E$3:$E$2003,7,사용내역!$F$3:$F$2003,"건설재해예방 기술지도비"),0) -> 0 | J10: =IFERROR(SUMIFS(사용내역!$H$3:$H$2003,사용내역!$C$3:$C$2003,"본사",사용내역!$E$3:$E$2003,8,사용내역!$F$3:$F$2003,"건설재해예방 기술지도비"),0) -> 0 | K10: =IFERROR(SUMIFS(사용내역!$H$3:$H$2003,사용내역!$C$3:$C$2003,"본사",사용내역!$E$3:$E$2003,9,사용내역!$F$3:$F$2003,"건설재해예방 기술지도비"),0) -> 0 | L10: =IFERROR(SUMIFS(사용내역!$H$3:$H$2003,사용내역!$C$3:$C$2003,"본사",사용내역!$E$3:$E$2003,10,사용내역!$F$3:$F$2003,"건설재해예방 기술지도비"),0) -> 0 | M10: =IFERROR(SUMIFS(사용내역!$H$3:$H$2003,사용내역!$C$3:$C$2003,"본사",사용내역!$E$3:$E$2003,11,사용내역!$F$3:$F$2003,"건설재해예방 기술지도비"),0) -> 0 | N10: =IFERROR(SUMIFS(사용내역!$H$3:$H$2003,사용내역!$C$3:$C$2003,"본사",사용내역!$E$3:$E$2003,12,사용내역!$F$3:$F$2003,"건설재해예방 기술지도비"),0) -> 0 | O10: =SUM(C10:N10) -> 0 | P10: =IFERROR(COUNTIFS(사용내역!$C$3:$C$2003,"본사",사용내역!$F$3:$F$2003,"건설재해예방 기술지도비",사용내역!$J$3:$J$2003,"Y"),0) -> 0
B11: 기타 | C11: =IFERROR(SUMIFS(사용내역!$H$3:$H$2003,사용내역!$C$3:$C$2003,"본사",사용내역!$E$3:$E$2003,1,사용내역!$F$3:$F$2003,"기타"),0) -> 0 | D11: =IFERROR(SUMIFS(사용내역!$H$3:$H$2003,사용내역!$C$3:$C$2003,"본사",사용내역!$E$3:$E$2003,2,사용내역!$F$3:$F$2003,"기타"),0) -> 0 | E11: =IFERROR(SUMIFS(사용내역!$H$3:$H$2003,사용내역!$C$3:$C$2003,"본사",사용내역!$E$3:$E$2003,3,사용내역!$F$3:$F$2003,"기타"),0) -> 0 | F11: =IFERROR(SUMIFS(사용내역!$H$3:$H$2003,사용내역!$C$3:$C$2003,"본사",사용내역!$E$3:$E$2003,4,사용내역!$F$3:$F$2003,"기타"),0) -> 0 | G11: =IFERROR(SUMIFS(사용내역!$H$3:$H$2003,사용내역!$C$3:$C$2003,"본사",사용내역!$E$3:$E$2003,5,사용내역!$F$3:$F$2003,"기타"),0) -> 0 | H11: =IFERROR(SUMIFS(사용내역!$H$3:$H$2003,사용내역!$C$3:$C$2003,"본사",사용내역!$E$3:$E$2003,6,사용내역!$F$3:$F$2003,"기타"),0) -> 0 | I11: =IFERROR(SUMIFS(사용내역!$H$3:$H$2003,사용내역!$C$3:$C$2003,"본사",사용내역!$E$3:$E$2003,7,사용내역!$F$3:$F$2003,"기타"),0) -> 0 | J11: =IFERROR(SUMIFS(사용내역!$H$3:$H$2003,사용내역!$C$3:$C$2003,"본사",사용내역!$E$3:$E$2003,8,사용내역!$F$3:$F$2003,"기타"),0) -> 0 | K11: =IFERROR(SUMIFS(사용내역!$H$3:$H$2003,사용내역!$C$3:$C$2003,"본사",사용내역!$E$3:$E$2003,9,사용내역!$F$3:$F$2003,"기타"),0) -> 0 | L11: =IFERROR(SUMIFS(사용내역!$H$3:$H$2003,사용내역!$C$3:$C$2003,"본사",사용내역!$E$3:$E$2003,10,사용내역!$F$3:$F$2003,"기타"),0) -> 0 | M11: =IFERROR(SUMIFS(사용내역!$H$3:$H$2003,사용내역!$C$3:$C$2003,"본사",사용내역!$E$3:$E$2003,11,사용내역!$F$3:$F$2003,"기타"),0) -> 0 | N11: =IFERROR(SUMIFS(사용내역!$H$3:$H$2003,사용내역!$C$3:$C$2003,"본사",사용내역!$E$3:$E$2003,12,사용내역!$F$3:$F$2003,"기타"),0) -> 0 | O11: =SUM(C11:N11) -> 0 | P11: =IFERROR(COUNTIFS(사용내역!$C$3:$C$2003,"본사",사용내역!$F$3:$F$2003,"기타",사용내역!$J$3:$J$2003,"Y"),0) -> 0
B12: 산보위·위험성평가 안건 | C12: =IFERROR(SUMIFS(사용내역!$H$3:$H$2003,사용내역!$C$3:$C$2003,"본사",사용내역!$E$3:$E$2003,1,사용내역!$F$3:$F$2003,"산보위·위험성평가 안건"),0) -> 0 | D12: =IFERROR(SUMIFS(사용내역!$H$3:$H$2003,사용내역!$C$3:$C$2003,"본사",사용내역!$E$3:$E$2003,2,사용내역!$F$3:$F$2003,"산보위·위험성평가 안건"),0) -> 0 | E12: =IFERROR(SUMIFS(사용내역!$H$3:$H$2003,사용내역!$C$3:$C$2003,"본사",사용내역!$E$3:$E$2003,3,사용내역!$F$3:$F$2003,"산보위·위험성평가 안건"),0) -> 0 | F12: =IFERROR(SUMIFS(사용내역!$H$3:$H$2003,사용내역!$C$3:$C$2003,"본사",사용내역!$E$3:$E$2003,4,사용내역!$F$3:$F$2003,"산보위·위험성평가 안건"),0) -> 0 | G12: =IFERROR(SUMIFS(사용내역!$H$3:$H$2003,사용내역!$C$3:$C$2003,"본사",사용내역!$E$3:$E$2003,5,사용내역!$F$3:$F$2003,"산보위·위험성평가 안건"),0) -> 0 | H12: =IFERROR(SUMIFS(사용내역!$H$3:$H$2003,사용내역!$C$3:$C$2003,"본사",사용내역!$E$3:$E$2003,6,사용내역!$F$3:$F$2003,"산보위·위험성평가 안건"),0) -> 0 | I12: =IFERROR(SUMIFS(사용내역!$H$3:$H$2003,사용내역!$C$3:$C$2003,"본사",사용내역!$E$3:$E$2003,7,사용내역!$F$3:$F$2003,"산보위·위험성평가 안건"),0) -> 0 | J12: =IFERROR(SUMIFS(사용내역!$H$3:$H$2003,사용내역!$C$3:$C$2003,"본사",사용내역!$E$3:$E$2003,8,사용내역!$F$3:$F$2003,"산보위·위험성평가 안건"),0) -> 0 | K12: =IFERROR(SUMIFS(사용내역!$H$3:$H$2003,사용내역!$C$3:$C$2003,"본사",사용내역!$E$3:$E$2003,9,사용내역!$F$3:$F$2003,"산보위·위험성평가 안건"),0) -> 0 | L12: =IFERROR(SUMIFS(사용내역!$H$3:$H$2003,사용내역!$C$3:$C$2003,"본사",사용내역!$E$3:$E$2003,10,사용내역!$F$3:$F$2003,"산보위·위험성평가 안건"),0) -> 0 | M12: =IFERROR(SUMIFS(사용내역!$H$3:$H$2003,사용내역!$C$3:$C$2003,"본사",사용내역!$E$3:$E$2003,11,사용내역!$F$3:$F$2003,"산보위·위험성평가 안건"),0) -> 0 | N12: =IFERROR(SUMIFS(사용내역!$H$3:$H$2003,사용내역!$C$3:$C$2003,"본사",사용내역!$E$3:$E$2003,12,사용내역!$F$3:$F$2003,"산보위·위험성평가 안건"),0) -> 0 | O12: =SUM(C12:N12) -> 0 | P12: =IFERROR(COUNTIFS(사용내역!$C$3:$C$2003,"본사",사용내역!$F$3:$F$2003,"산보위·위험성평가 안건",사용내역!$J$3:$J$2003,"Y"),0) -> 0
A13: 본사 소계 | C13: =SUM(C4:C12) -> 0 | D13: =SUM(D4:D12) -> 0 | E13: =SUM(E4:E12) -> 0 | F13: =SUM(F4:F12) -> 0 | G13: =SUM(G4:G12) -> 0 | H13: =SUM(H4:H12) -> 0 | I13: =SUM(I4:I12) -> 0 | J13: =SUM(J4:J12) -> 0 | ... P13: =SUM(P4:P12) -> 0
A14: 충청본부 | B14: 안전관리자 등 인건비 | C14: =IFERROR(SUMIFS(사용내역!$H$3:$H$2003,사용내역!$C$3:$C$2003,"충청",사용내역!$E$3:$E$2003,1,사용내역!$F$3:$F$2003,"안전관리자 등 인건비"),0) -> 0 | D14: =IFERROR(SUMIFS(사용내역!$H$3:$H$2003,사용내역!$C$3:$C$2003,"충청",사용내역!$E$3:$E$2003,2,사용내역!$F$3:$F$2003,"안전관리자 등 인건비"),0) -> 0 | E14: =IFERROR(SUMIFS(사용내역!$H$3:$H$2003,사용내역!$C$3:$C$2003,"충청",사용내역!$E$3:$E$2003,3,사용내역!$F$3:$F$2003,"안전관리자 등 인건비"),0) -> 0 | F14: =IFERROR(SUMIFS(사용내역!$H$3:$H$2003,사용내역!$C$3:$C$2003,"충청",사용내역!$E$3:$E$2003,4,사용내역!$F$3:$F$2003,"안전관리자 등 인건비"),0) -> 0 | G14: =IFERROR(SUMIFS(사용내역!$H$3:$H$2003,사용내역!$C$3:$C$2003,"충청",사용내역!$E$3:$E$2003,5,사용내역!$F$3:$F$2003,"안전관리자 등 인건비"),0) -> 0 | H14: =IFERROR(SUMIFS(사용내역!$H$3:$H$2003,사용내역!$C$3:$C$2003,"충청",사용내역!$E$3:$E$2003,6,사용내역!$F$3:$F$2003,"안전관리자 등 인건비"),0) -> 0 | I14: =IFERROR(SUMIFS(사용내역!$H$3:$H$2003,사용내역!$C$3:$C$2003,"충청",사용내역!$E$3:$E$2003,7,사용내역!$F$3:$F$2003,"안전관리자 등 인건비"),0) -> 0 | J14: =IFERROR(SUMIFS(사용내역!$H$3:$H$2003,사용내역!$C$3:$C$2003,"충청",사용내역!$E$3:$E$2003,8,사용내역!$F$3:$F$2003,"안전관리자 등 인건비"),0) -> 0 | K14: =IFERROR(SUMIFS(사용내역!$H$3:$H$2003,사용내역!$C$3:$C$2003,"충청",사용내역!$E$3:$E$2003,9,사용내역!$F$3:$F$2003,"안전관리자 등 인건비"),0) -> 0 | L14: =IFERROR(SUMIFS(사용내역!$H$3:$H$2003,사용내역!$C$3:$C$2003,"충청",사용내역!$E$3:$E$2003,10,사용내역!$F$3:$F$2003,"안전관리자 등 인건비"),0) -> 0 | M14: =IFERROR(SUMIFS(사용내역!$H$3:$H$2003,사용내역!$C$3:$C$2003,"충청",사용내역!$E$3:$E$2003,11,사용내역!$F$3:$F$2003,"안전관리자 등 인건비"),0) -> 0 | N14: =IFERROR(SUMIFS(사용내역!$H$3:$H$2003,사용내역!$C$3:$C$2003,"충청",사용내역!$E$3:$E$2003,12,사용내역!$F$3:$F$2003,"안전관리자 등 인건비"),0) -> 0 | O14: =SUM(C14:N14) -> 0 | P14: =IFERROR(COUNTIFS(사용내역!$C$3:$C$2003,"충청",사용내역!$F$3:$F$2003,"안전관리자 등 인건비",사용내역!$J$3:$J$2003,"Y"),0) -> 0
B15: 안전시설비 | C15: =IFERROR(SUMIFS(사용내역!$H$3:$H$2003,사용내역!$C$3:$C$2003,"충청",사용내역!$E$3:$E$2003,1,사용내역!$F$3:$F$2003,"안전시설비"),0) -> 0 | D15: =IFERROR(SUMIFS(사용내역!$H$3:$H$2003,사용내역!$C$3:$C$2003,"충청",사용내역!$E$3:$E$2003,2,사용내역!$F$3:$F$2003,"안전시설비"),0) -> 0 | E15: =IFERROR(SUMIFS(사용내역!$H$3:$H$2003,사용내역!$C$3:$C$2003,"충청",사용내역!$E$3:$E$2003,3,사용내역!$F$3:$F$2003,"안전시설비"),0) -> 0 | F15: =IFERROR(SUMIFS(사용내역!$H$3:$H$2003,사용내역!$C$3:$C$2003,"충청",사용내역!$E$3:$E$2003,4,사용내역!$F$3:$F$2003,"안전시설비"),0) -> 0 | G15: =IFERROR(SUMIFS(사용내역!$H$3:$H$2003,사용내역!$C$3:$C$2003,"충청",사용내역!$E$3:$E$2003,5,사용내역!$F$3:$F$2003,"안전시설비"),0) -> 0 | H15: =IFERROR(SUMIFS(사용내역!$H$3:$H$2003,사용내역!$C$3:$C$2003,"충청",사용내역!$E$3:$E$2003,6,사용내역!$F$3:$F$2003,"안전시설비"),0) -> 0 | I15: =IFERROR(SUMIFS(사용내역!$H$3:$H$2003,사용내역!$C$3:$C$2003,"충청",사용내역!$E$3:$E$2003,7,사용내역!$F$3:$F$2003,"안전시설비"),0) -> 0 | J15: =IFERROR(SUMIFS(사용내역!$H$3:$H$2003,사용내역!$C$3:$C$2003,"충청",사용내역!$E$3:$E$2003,8,사용내역!$F$3:$F$2003,"안전시설비"),0) -> 0 | K15: =IFERROR(SUMIFS(사용내역!$H$3:$H$2003,사용내역!$C$3:$C$2003,"충청",사용내역!$E$3:$E$2003,9,사용내역!$F$3:$F$2003,"안전시설비"),0) -> 0 | L15: =IFERROR(SUMIFS(사용내역!$H$3:$H$2003,사용내역!$C$3:$C$2003,"충청",사용내역!$E$3:$E$2003,10,사용내역!$F$3:$F$2003,"안전시설비"),0) -> 0 | M15: =IFERROR(SUMIFS(사용내역!$H$3:$H$2003,사용내역!$C$3:$C$2003,"충청",사용내역!$E$3:$E$2003,11,사용내역!$F$3:$F$2003,"안전시설비"),0) -> 0 | N15: =IFERROR(SUMIFS(사용내역!$H$3:$H$2003,사용내역!$C$3:$C$2003,"충청",사용내역!$E$3:$E$2003,12,사용내역!$F$3:$F$2003,"안전시설비"),0) -> 0 | O15: =SUM(C15:N15) -> 0 | P15: =IFERROR(COUNTIFS(사용내역!$C$3:$C$2003,"충청",사용내역!$F$3:$F$2003,"안전시설비",사용내역!$J$3:$J$2003,"Y"),0) -> 0
B16: 보호구·안전용품 | C16: =IFERROR(SUMIFS(사용내역!$H$3:$H$2003,사용내역!$C$3:$C$2003,"충청",사용내역!$E$3:$E$2003,1,사용내역!$F$3:$F$2003,"보호구·안전용품"),0) -> 0 | D16: =IFERROR(SUMIFS(사용내역!$H$3:$H$2003,사용내역!$C$3:$C$2003,"충청",사용내역!$E$3:$E$2003,2,사용내역!$F$3:$F$2003,"보호구·안전용품"),0) -> 0 | E16: =IFERROR(SUMIFS(사용내역!$H$3:$H$2003,사용내역!$C$3:$C$2003,"충청",사용내역!$E$3:$E$2003,3,사용내역!$F$3:$F$2003,"보호구·안전용품"),0) -> 0 | F16: =IFERROR(SUMIFS(사용내역!$H$3:$H$2003,사용내역!$C$3:$C$2003,"충청",사용내역!$E$3:$E$2003,4,사용내역!$F$3:$F$2003,"보호구·안전용품"),0) -> 0 | G16: =IFERROR(SUMIFS(사용내역!$H$3:$H$2003,사용내역!$C$3:$C$2003,"충청",사용내역!$E$3:$E$2003,5,사용내역!$F$3:$F$2003,"보호구·안전용품"),0) -> 0 | H16: =IFERROR(SUMIFS(사용내역!$H$3:$H$2003,사용내역!$C$3:$C$2003,"충청",사용내역!$E$3:$E$2003,6,사용내역!$F$3:$F$2003,"보호구·안전용품"),0) -> 0 | I16: =IFERROR(SUMIFS(사용내역!$H$3:$H$2003,사용내역!$C$3:$C$2003,"충청",사용내역!$E$3:$E$2003,7,사용내역!$F$3:$F$2003,"보호구·안전용품"),0) -> 0 | J16: =IFERROR(SUMIFS(사용내역!$H$3:$H$2003,사용내역!$C$3:$C$2003,"충청",사용내역!$E$3:$E$2003,8,사용내역!$F$3:$F$2003,"보호구·안전용품"),0) -> 0 | K16: =IFERROR(SUMIFS(사용내역!$H$3:$H$2003,사용내역!$C$3:$C$2003,"충청",사용내역!$E$3:$E$2003,9,사용내역!$F$3:$F$2003,"보호구·안전용품"),0) -> 0 | L16: =IFERROR(SUMIFS(사용내역!$H$3:$H$2003,사용내역!$C$3:$C$2003,"충청",사용내역!$E$3:$E$2003,10,사용내역!$F$3:$F$2003,"보호구·안전용품"),0) -> 0 | M16: =IFERROR(SUMIFS(사용내역!$H$3:$H$2003,사용내역!$C$3:$C$2003,"충청",사용내역!$E$3:$E$2003,11,사용내역!$F$3:$F$2003,"보호구·안전용품"),0) -> 0 | N16: =IFERROR(SUMIFS(사용내역!$H$3:$H$2003,사용내역!$C$3:$C$2003,"충청",사용내역!$E$3:$E$2003,12,사용내역!$F$3:$F$2003,"보호구·안전용품"),0) -> 0 | O16: =SUM(C16:N16) -> 0 | P16: =IFERROR(COUNTIFS(사용내역!$C$3:$C$2003,"충청",사용내역!$F$3:$F$2003,"보호구·안전용품",사용내역!$J$3:$J$2003,"Y"),0) -> 0
B17: 안전진단비 | C17: =IFERROR(SUMIFS(사용내역!$H$3:$H$2003,사용내역!$C$3:$C$2003,"충청",사용내역!$E$3:$E$2003,1,사용내역!$F$3:$F$2003,"안전진단비"),0) -> 0 | D17: =IFERROR(SUMIFS(사용내역!$H$3:$H$2003,사용내역!$C$3:$C$2003,"충청",사용내역!$E$3:$E$2003,2,사용내역!$F$3:$F$2003,"안전진단비"),0) -> 0 | E17: =IFERROR(SUMIFS(사용내역!$H$3:$H$2003,사용내역!$C$3:$C$2003,"충청",사용내역!$E$3:$E$2003,3,사용내역!$F$3:$F$2003,"안전진단비"),0) -> 0 | F17: =IFERROR(SUMIFS(사용내역!$H$3:$H$2003,사용내역!$C$3:$C$2003,"충청",사용내역!$E$3:$E$2003,4,사용내역!$F$3:$F$2003,"안전진단비"),0) -> 0 | G17: =IFERROR(SUMIFS(사용내역!$H$3:$H$2003,사용내역!$C$3:$C$2003,"충청",사용내역!$E$3:$E$2003,5,사용내역!$F$3:$F$2003,"안전진단비"),0) -> 0 | H17: =IFERROR(SUMIFS(사용내역!$H$3:$H$2003,사용내역!$C$3:$C$2003,"충청",사용내역!$E$3:$E$2003,6,사용내역!$F$3:$F$2003,"안전진단비"),0) -> 0 | I17: =IFERROR(SUMIFS(사용내역!$H$3:$H$2003,사용내역!$C$3:$C$2003,"충청",사용내역!$E$3:$E$2003,7,사용내역!$F$3:$F$2003,"안전진단비"),0) -> 0 | J17: =IFERROR(SUMIFS(사용내역!$H$3:$H$2003,사용내역!$C$3:$C$2003,"충청",사용내역!$E$3:$E$2003,8,사용내역!$F$3:$F$2003,"안전진단비"),0) -> 0 | K17: =IFERROR(SUMIFS(사용내역!$H$3:$H$2003,사용내역!$C$3:$C$2003,"충청",사용내역!$E$3:$E$2003,9,사용내역!$F$3:$F$2003,"안전진단비"),0) -> 0 | L17: =IFERROR(SUMIFS(사용내역!$H$3:$H$2003,사용내역!$C$3:$C$2003,"충청",사용내역!$E$3:$E$2003,10,사용내역!$F$3:$F$2003,"안전진단비"),0) -> 0 | M17: =IFERROR(SUMIFS(사용내역!$H$3:$H$2003,사용내역!$C$3:$C$2003,"충청",사용내역!$E$3:$E$2003,11,사용내역!$F$3:$F$2003,"안전진단비"),0) -> 0 | N17: =IFERROR(SUMIFS(사용내역!$H$3:$H$2003,사용내역!$C$3:$C$2003,"충청",사용내역!$E$3:$E$2003,12,사용내역!$F$3:$F$2003,"안전진단비"),0) -> 0 | O17: =SUM(C17:N17) -> 0 | P17: =IFERROR(COUNTIFS(사용내역!$C$3:$C$2003,"충청",사용내역!$F$3:$F$2003,"안전진단비",사용내역!$J$3:$J$2003,"Y"),0) -> 0
B18: 안전보건교육비·행사비 등 | C18: =IFERROR(SUMIFS(사용내역!$H$3:$H$2003,사용내역!$C$3:$C$2003,"충청",사용내역!$E$3:$E$2003,1,사용내역!$F$3:$F$2003,"안전보건교육비·행사비 등"),0) -> 0 | D18: =IFERROR(SUMIFS(사용내역!$H$3:$H$2003,사용내역!$C$3:$C$2003,"충청",사용내역!$E$3:$E$2003,2,사용내역!$F$3:$F$2003,"안전보건교육비·행사비 등"),0) -> 0 | E18: =IFERROR(SUMIFS(사용내역!$H$3:$H$2003,사용내역!$C$3:$C$2003,"충청",사용내역!$E$3:$E$2003,3,사용내역!$F$3:$F$2003,"안전보건교육비·행사비 등"),0) -> 0 | F18: =IFERROR(SUMIFS(사용내역!$H$3:$H$2003,사용내역!$C$3:$C$2003,"충청",사용내역!$E$3:$E$2003,4,사용내역!$F$3:$F$2003,"안전보건교육비·행사비 등"),0) -> 0 | G18: =IFERROR(SUMIFS(사용내역!$H$3:$H$2003,사용내역!$C$3:$C$2003,"충청",사용내역!$E$3:$E$2003,5,사용내역!$F$3:$F$2003,"안전보건교육비·행사비 등"),0) -> 0 | H18: =IFERROR(SUMIFS(사용내역!$H$3:$H$2003,사용내역!$C$3:$C$2003,"충청",사용내역!$E$3:$E$2003,6,사용내역!$F$3:$F$2003,"안전보건교육비·행사비 등"),0) -> 0 | I18: =IFERROR(SUMIFS(사용내역!$H$3:$H$2003,사용내역!$C$3:$C$2003,"충청",사용내역!$E$3:$E$2003,7,사용내역!$F$3:$F$2003,"안전보건교육비·행사비 등"),0) -> 0 | J18: =IFERROR(SUMIFS(사용내역!$H$3:$H$2003,사용내역!$C$3:$C$2003,"충청",사용내역!$E$3:$E$2003,8,사용내역!$F$3:$F$2003,"안전보건교육비·행사비 등"),0) -> 0 | K18: =IFERROR(SUMIFS(사용내역!$H$3:$H$2003,사용내역!$C$3:$C$2003,"충청",사용내역!$E$3:$E$2003,9,사용내역!$F$3:$F$2003,"안전보건교육비·행사비 등"),0) -> 0 | L18: =IFERROR(SUMIFS(사용내역!$H$3:$H$2003,사용내역!$C$3:$C$2003,"충청",사용내역!$E$3:$E$2003,10,사용내역!$F$3:$F$2003,"안전보건교육비·행사비 등"),0) -> 0 | M18: =IFERROR(SUMIFS(사용내역!$H$3:$H$2003,사용내역!$C$3:$C$2003,"충청",사용내역!$E$3:$E$2003,11,사용내역!$F$3:$F$2003,"안전보건교육비·행사비 등"),0) -> 0 | N18: =IFERROR(SUMIFS(사용내역!$H$3:$H$2003,사용내역!$C$3:$C$2003,"충청",사용내역!$E$3:$E$2003,12,사용내역!$F$3:$F$2003,"안전보건교육비·행사비 등"),0) -> 0 | O18: =SUM(C18:N18) -> 0 | P18: =IFERROR(COUNTIFS(사용내역!$C$3:$C$2003,"충청",사용내역!$F$3:$F$2003,"안전보건교육비·행사비 등",사용내역!$J$3:$J$2003,"Y"),0) -> 0
B19: 근로자 건강관리비 등 | C19: =IFERROR(SUMIFS(사용내역!$H$3:$H$2003,사용내역!$C$3:$C$2003,"충청",사용내역!$E$3:$E$2003,1,사용내역!$F$3:$F$2003,"근로자 건강관리비 등"),0) -> 0 | D19: =IFERROR(SUMIFS(사용내역!$H$3:$H$2003,사용내역!$C$3:$C$2003,"충청",사용내역!$E$3:$E$2003,2,사용내역!$F$3:$F$2003,"근로자 건강관리비 등"),0) -> 0 | E19: =IFERROR(SUMIFS(사용내역!$H$3:$H$2003,사용내역!$C$3:$C$2003,"충청",사용내역!$E$3:$E$2003,3,사용내역!$F$3:$F$2003,"근로자 건강관리비 등"),0) -> 0 | F19: =IFERROR(SUMIFS(사용내역!$H$3:$H$2003,사용내역!$C$3:$C$2003,"충청",사용내역!$E$3:$E$2003,4,사용내역!$F$3:$F$2003,"근로자 건강관리비 등"),0) -> 0 | G19: =IFERROR(SUMIFS(사용내역!$H$3:$H$2003,사용내역!$C$3:$C$2003,"충청",사용내역!$E$3:$E$2003,5,사용내역!$F$3:$F$2003,"근로자 건강관리비 등"),0) -> 0 | H19: =IFERROR(SUMIFS(사용내역!$H$3:$H$2003,사용내역!$C$3:$C$2003,"충청",사용내역!$E$3:$E$2003,6,사용내역!$F$3:$F$2003,"근로자 건강관리비 등"),0) -> 0 | I19: =IFERROR(SUMIFS(사용내역!$H$3:$H$2003,사용내역!$C$3:$C$2003,"충청",사용내역!$E$3:$E$2003,7,사용내역!$F$3:$F$2003,"근로자 건강관리비 등"),0) -> 0 | J19: =IFERROR(SUMIFS(사용내역!$H$3:$H$2003,사용내역!$C$3:$C$2003,"충청",사용내역!$E$3:$E$2003,8,사용내역!$F$3:$F$2003,"근로자 건강관리비 등"),0) -> 0 | K19: =IFERROR(SUMIFS(사용내역!$H$3:$H$2003,사용내역!$C$3:$C$2003,"충청",사용내역!$E$3:$E$2003,9,사용내역!$F$3:$F$2003,"근로자 건강관리비 등"),0) -> 0 | L19: =IFERROR(SUMIFS(사용내역!$H$3:$H$2003,사용내역!$C$3:$C$2003,"충청",사용내역!$E$3:$E$2003,10,사용내역!$F$3:$F$2003,"근로자 건강관리비 등"),0) -> 0 | M19: =IFERROR(SUMIFS(사용내역!$H$3:$H$2003,사용내역!$C$3:$C$2003,"충청",사용내역!$E$3:$E$2003,11,사용내역!$F$3:$F$2003,"근로자 건강관리비 등"),0) -> 0 | N19: =IFERROR(SUMIFS(사용내역!$H$3:$H$2003,사용내역!$C$3:$C$2003,"충청",사용내역!$E$3:$E$2003,12,사용내역!$F$3:$F$2003,"근로자 건강관리비 등"),0) -> 0 | O19: =SUM(C19:N19) -> 0 | P19: =IFERROR(COUNTIFS(사용내역!$C$3:$C$2003,"충청",사용내역!$F$3:$F$2003,"근로자 건강관리비 등",사용내역!$J$3:$J$2003,"Y"),0) -> 0
B20: 건설재해예방 기술지도비 | C20: =IFERROR(SUMIFS(사용내역!$H$3:$H$2003,사용내역!$C$3:$C$2003,"충청",사용내역!$E$3:$E$2003,1,사용내역!$F$3:$F$2003,"건설재해예방 기술지도비"),0) -> 0 | D20: =IFERROR(SUMIFS(사용내역!$H$3:$H$2003,사용내역!$C$3:$C$2003,"충청",사용내역!$E$3:$E$2003,2,사용내역!$F$3:$F$2003,"건설재해예방 기술지도비"),0) -> 0 | E20: =IFERROR(SUMIFS(사용내역!$H$3:$H$2003,사용내역!$C$3:$C$2003,"충청",사용내역!$E$3:$E$2003,3,사용내역!$F$3:$F$2003,"건설재해예방 기술지도비"),0) -> 0 | F20: =IFERROR(SUMIFS(사용내역!$H$3:$H$2003,사용내역!$C$3:$C$2003,"충청",사용내역!$E$3:$E$2003,4,사용내역!$F$3:$F$2003,"건설재해예방 기술지도비"),0) -> 0 | G20: =IFERROR(SUMIFS(사용내역!$H$3:$H$2003,사용내역!$C$3:$C$2003,"충청",사용내역!$E$3:$E$2003,5,사용내역!$F$3:$F$2003,"건설재해예방 기술지도비"),0) -> 0 | H20: =IFERROR(SUMIFS(사용내역!$H$3:$H$2003,사용내역!$C$3:$C$2003,"충청",사용내역!$E$3:$E$2003,6,사용내역!$F$3:$F$2003,"건설재해예방 기술지도비"),0) -> 0 | I20: =IFERROR(SUMIFS(사용내역!$H$3:$H$2003,사용내역!$C$3:$C$2003,"충청",사용내역!$E$3:$E$2003,7,사용내역!$F$3:$F$2003,"건설재해예방 기술지도비"),0) -> 0 | J20: =IFERROR(SUMIFS(사용내역!$H$3:$H$2003,사용내역!$C$3:$C$2003,"충청",사용내역!$E$3:$E$2003,8,사용내역!$F$3:$F$2003,"건설재해예방 기술지도비"),0) -> 0 | K20: =IFERROR(SUMIFS(사용내역!$H$3:$H$2003,사용내역!$C$3:$C$2003,"충청",사용내역!$E$3:$E$2003,9,사용내역!$F$3:$F$2003,"건설재해예방 기술지도비"),0) -> 0 | L20: =IFERROR(SUMIFS(사용내역!$H$3:$H$2003,사용내역!$C$3:$C$2003,"충청",사용내역!$E$3:$E$2003,10,사용내역!$F$3:$F$2003,"건설재해예방 기술지도비"),0) -> 0 | M20: =IFERROR(SUMIFS(사용내역!$H$3:$H$2003,사용내역!$C$3:$C$2003,"충청",사용내역!$E$3:$E$2003,11,사용내역!$F$3:$F$2003,"건설재해예방 기술지도비"),0) -> 0 | N20: =IFERROR(SUMIFS(사용내역!$H$3:$H$2003,사용내역!$C$3:$C$2003,"충청",사용내역!$E$3:$E$2003,12,사용내역!$F$3:$F$2003,"건설재해예방 기술지도비"),0) -> 0 | O20: =SUM(C20:N20) -> 0 | P20: =IFERROR(COUNTIFS(사용내역!$C$3:$C$2003,"충청",사용내역!$F$3:$F$2003,"건설재해예방 기술지도비",사용내역!$J$3:$J$2003,"Y"),0) -> 0
B21: 기타 | C21: =IFERROR(SUMIFS(사용내역!$H$3:$H$2003,사용내역!$C$3:$C$2003,"충청",사용내역!$E$3:$E$2003,1,사용내역!$F$3:$F$2003,"기타"),0) -> 0 | D21: =IFERROR(SUMIFS(사용내역!$H$3:$H$2003,사용내역!$C$3:$C$2003,"충청",사용내역!$E$3:$E$2003,2,사용내역!$F$3:$F$2003,"기타"),0) -> 0 | E21: =IFERROR(SUMIFS(사용내역!$H$3:$H$2003,사용내역!$C$3:$C$2003,"충청",사용내역!$E$3:$E$2003,3,사용내역!$F$3:$F$2003,"기타"),0) -> 0 | F21: =IFERROR(SUMIFS(사용내역!$H$3:$H$2003,사용내역!$C$3:$C$2003,"충청",사용내역!$E$3:$E$2003,4,사용내역!$F$3:$F$2003,"기타"),0) -> 0 | G21: =IFERROR(SUMIFS(사용내역!$H$3:$H$2003,사용내역!$C$3:$C$2003,"충청",사용내역!$E$3:$E$2003,5,사용내역!$F$3:$F$2003,"기타"),0) -> 0 | H21: =IFERROR(SUMIFS(사용내역!$H$3:$H$2003,사용내역!$C$3:$C$2003,"충청",사용내역!$E$3:$E$2003,6,사용내역!$F$3:$F$2003,"기타"),0) -> 0 | I21: =IFERROR(SUMIFS(사용내역!$H$3:$H$2003,사용내역!$C$3:$C$2003,"충청",사용내역!$E$3:$E$2003,7,사용내역!$F$3:$F$2003,"기타"),0) -> 0 | J21: =IFERROR(SUMIFS(사용내역!$H$3:$H$2003,사용내역!$C$3:$C$2003,"충청",사용내역!$E$3:$E$2003,8,사용내역!$F$3:$F$2003,"기타"),0) -> 0 | K21: =IFERROR(SUMIFS(사용내역!$H$3:$H$2003,사용내역!$C$3:$C$2003,"충청",사용내역!$E$3:$E$2003,9,사용내역!$F$3:$F$2003,"기타"),0) -> 0 | L21: =IFERROR(SUMIFS(사용내역!$H$3:$H$2003,사용내역!$C$3:$C$2003,"충청",사용내역!$E$3:$E$2003,10,사용내역!$F$3:$F$2003,"기타"),0) -> 0 | M21: =IFERROR(SUMIFS(사용내역!$H$3:$H$2003,사용내역!$C$3:$C$2003,"충청",사용내역!$E$3:$E$2003,11,사용내역!$F$3:$F$2003,"기타"),0) -> 0 | N21: =IFERROR(SUMIFS(사용내역!$H$3:$H$2003,사용내역!$C$3:$C$2003,"충청",사용내역!$E$3:$E$2003,12,사용내역!$F$3:$F$2003,"기타"),0) -> 0 | O21: =SUM(C21:N21) -> 0 | P21: =IFERROR(COUNTIFS(사용내역!$C$3:$C$2003,"충청",사용내역!$F$3:$F$2003,"기타",사용내역!$J$3:$J$2003,"Y"),0) -> 0
B22: 산보위·위험성평가 안건 | C22: =IFERROR(SUMIFS(사용내역!$H$3:$H$2003,사용내역!$C$3:$C$2003,"충청",사용내역!$E$3:$E$2003,1,사용내역!$F$3:$F$2003,"산보위·위험성평가 안건"),0) -> 0 | D22: =IFERROR(SUMIFS(사용내역!$H$3:$H$2003,사용내역!$C$3:$C$2003,"충청",사용내역!$E$3:$E$2003,2,사용내역!$F$3:$F$2003,"산보위·위험성평가 안건"),0) -> 0 | E22: =IFERROR(SUMIFS(사용내역!$H$3:$H$2003,사용내역!$C$3:$C$2003,"충청",사용내역!$E$3:$E$2003,3,사용내역!$F$3:$F$2003,"산보위·위험성평가 안건"),0) -> 0 | F22: =IFERROR(SUMIFS(사용내역!$H$3:$H$2003,사용내역!$C$3:$C$2003,"충청",사용내역!$E$3:$E$2003,4,사용내역!$F$3:$F$2003,"산보위·위험성평가 안건"),0) -> 0 | G22: =IFERROR(SUMIFS(사용내역!$H$3:$H$2003,사용내역!$C$3:$C$2003,"충청",사용내역!$E$3:$E$2003,5,사용내역!$F$3:$F$2003,"산보위·위험성평가 안건"),0) -> 0 | H22: =IFERROR(SUMIFS(사용내역!$H$3:$H$2003,사용내역!$C$3:$C$2003,"충청",사용내역!$E$3:$E$2003,6,사용내역!$F$3:$F$2003,"산보위·위험성평가 안건"),0) -> 0 | I22: =IFERROR(SUMIFS(사용내역!$H$3:$H$2003,사용내역!$C$3:$C$2003,"충청",사용내역!$E$3:$E$2003,7,사용내역!$F$3:$F$2003,"산보위·위험성평가 안건"),0) -> 0 | J22: =IFERROR(SUMIFS(사용내역!$H$3:$H$2003,사용내역!$C$3:$C$2003,"충청",사용내역!$E$3:$E$2003,8,사용내역!$F$3:$F$2003,"산보위·위험성평가 안건"),0) -> 0 | K22: =IFERROR(SUMIFS(사용내역!$H$3:$H$2003,사용내역!$C$3:$C$2003,"충청",사용내역!$E$3:$E$2003,9,사용내역!$F$3:$F$2003,"산보위·위험성평가 안건"),0) -> 0 | L22: =IFERROR(SUMIFS(사용내역!$H$3:$H$2003,사용내역!$C$3:$C$2003,"충청",사용내역!$E$3:$E$2003,10,사용내역!$F$3:$F$2003,"산보위·위험성평가 안건"),0) -> 0 | M22: =IFERROR(SUMIFS(사용내역!$H$3:$H$2003,사용내역!$C$3:$C$2003,"충청",사용내역!$E$3:$E$2003,11,사용내역!$F$3:$F$2003,"산보위·위험성평가 안건"),0) -> 0 | N22: =IFERROR(SUMIFS(사용내역!$H$3:$H$2003,사용내역!$C$3:$C$2003,"충청",사용내역!$E$3:$E$2003,12,사용내역!$F$3:$F$2003,"산보위·위험성평가 안건"),0) -> 0 | O22: =SUM(C22:N22) -> 0 | P22: =IFERROR(COUNTIFS(사용내역!$C$3:$C$2003,"충청",사용내역!$F$3:$F$2003,"산보위·위험성평가 안건",사용내역!$J$3:$J$2003,"Y"),0) -> 0
A23: 충청본부 소계 | C23: =SUM(C14:C22) -> 0 | D23: =SUM(D14:D22) -> 0 | E23: =SUM(E14:E22) -> 0 | F23: =SUM(F14:F22) -> 0 | G23: =SUM(G14:G22) -> 0 | H23: =SUM(H14:H22) -> 0 | I23: =SUM(I14:I22) -> 0 | J23: =SUM(J14:J22) -> 0 | ... P23: =SUM(P14:P22) -> 0
A24: 호남본부 | B24: 안전관리자 등 인건비 | C24: =IFERROR(SUMIFS(사용내역!$H$3:$H$2003,사용내역!$C$3:$C$2003,"호남",사용내역!$E$3:$E$2003,1,사용내역!$F$3:$F$2003,"안전관리자 등 인건비"),0) -> 0 | D24: =IFERROR(SUMIFS(사용내역!$H$3:$H$2003,사용내역!$C$3:$C$2003,"호남",사용내역!$E$3:$E$2003,2,사용내역!$F$3:$F$2003,"안전관리자 등 인건비"),0) -> 0 | E24: =IFERROR(SUMIFS(사용내역!$H$3:$H$2003,사용내역!$C$3:$C$2003,"호남",사용내역!$E$3:$E$2003,3,사용내역!$F$3:$F$2003,"안전관리자 등 인건비"),0) -> 0 | F24: =IFERROR(SUMIFS(사용내역!$H$3:$H$2003,사용내역!$C$3:$C$2003,"호남",사용내역!$E$3:$E$2003,4,사용내역!$F$3:$F$2003,"안전관리자 등 인건비"),0) -> 0 | G24: =IFERROR(SUMIFS(사용내역!$H$3:$H$2003,사용내역!$C$3:$C$2003,"호남",사용내역!$E$3:$E$2003,5,사용내역!$F$3:$F$2003,"안전관리자 등 인건비"),0) -> 0 | H24: =IFERROR(SUMIFS(사용내역!$H$3:$H$2003,사용내역!$C$3:$C$2003,"호남",사용내역!$E$3:$E$2003,6,사용내역!$F$3:$F$2003,"안전관리자 등 인건비"),0) -> 0 | I24: =IFERROR(SUMIFS(사용내역!$H$3:$H$2003,사용내역!$C$3:$C$2003,"호남",사용내역!$E$3:$E$2003,7,사용내역!$F$3:$F$2003,"안전관리자 등 인건비"),0) -> 0 | J24: =IFERROR(SUMIFS(사용내역!$H$3:$H$2003,사용내역!$C$3:$C$2003,"호남",사용내역!$E$3:$E$2003,8,사용내역!$F$3:$F$2003,"안전관리자 등 인건비"),0) -> 0 | K24: =IFERROR(SUMIFS(사용내역!$H$3:$H$2003,사용내역!$C$3:$C$2003,"호남",사용내역!$E$3:$E$2003,9,사용내역!$F$3:$F$2003,"안전관리자 등 인건비"),0) -> 0 | L24: =IFERROR(SUMIFS(사용내역!$H$3:$H$2003,사용내역!$C$3:$C$2003,"호남",사용내역!$E$3:$E$2003,10,사용내역!$F$3:$F$2003,"안전관리자 등 인건비"),0) -> 0 | M24: =IFERROR(SUMIFS(사용내역!$H$3:$H$2003,사용내역!$C$3:$C$2003,"호남",사용내역!$E$3:$E$2003,11,사용내역!$F$3:$F$2003,"안전관리자 등 인건비"),0) -> 0 | N24: =IFERROR(SUMIFS(사용내역!$H$3:$H$2003,사용내역!$C$3:$C$2003,"호남",사용내역!$E$3:$E$2003,12,사용내역!$F$3:$F$2003,"안전관리자 등 인건비"),0) -> 0 | O24: =SUM(C24:N24) -> 0 | P24: =IFERROR(COUNTIFS(사용내역!$C$3:$C$2003,"호남",사용내역!$F$3:$F$2003,"안전관리자 등 인건비",사용내역!$J$3:$J$2003,"Y"),0) -> 0
B25: 안전시설비 | C25: =IFERROR(SUMIFS(사용내역!$H$3:$H$2003,사용내역!$C$3:$C$2003,"호남",사용내역!$E$3:$E$2003,1,사용내역!$F$3:$F$2003,"안전시설비"),0) -> 0 | D25: =IFERROR(SUMIFS(사용내역!$H$3:$H$2003,사용내역!$C$3:$C$2003,"호남",사용내역!$E$3:$E$2003,2,사용내역!$F$3:$F$2003,"안전시설비"),0) -> 0 | E25: =IFERROR(SUMIFS(사용내역!$H$3:$H$2003,사용내역!$C$3:$C$2003,"호남",사용내역!$E$3:$E$2003,3,사용내역!$F$3:$F$2003,"안전시설비"),0) -> 0 | F25: =IFERROR(SUMIFS(사용내역!$H$3:$H$2003,사용내역!$C$3:$C$2003,"호남",사용내역!$E$3:$E$2003,4,사용내역!$F$3:$F$2003,"안전시설비"),0) -> 0 | G25: =IFERROR(SUMIFS(사용내역!$H$3:$H$2003,사용내역!$C$3:$C$2003,"호남",사용내역!$E$3:$E$2003,5,사용내역!$F$3:$F$2003,"안전시설비"),0) -> 0 | H25: =IFERROR(SUMIFS(사용내역!$H$3:$H$2003,사용내역!$C$3:$C$2003,"호남",사용내역!$E$3:$E$2003,6,사용내역!$F$3:$F$2003,"안전시설비"),0) -> 0 | I25: =IFERROR(SUMIFS(사용내역!$H$3:$H$2003,사용내역!$C$3:$C$2003,"호남",사용내역!$E$3:$E$2003,7,사용내역!$F$3:$F$2003,"안전시설비"),0) -> 0 | J25: =IFERROR(SUMIFS(사용내역!$H$3:$H$2003,사용내역!$C$3:$C$2003,"호남",사용내역!$E$3:$E$2003,8,사용내역!$F$3:$F$2003,"안전시설비"),0) -> 0 | K25: =IFERROR(SUMIFS(사용내역!$H$3:$H$2003,사용내역!$C$3:$C$2003,"호남",사용내역!$E$3:$E$2003,9,사용내역!$F$3:$F$2003,"안전시설비"),0) -> 0 | L25: =IFERROR(SUMIFS(사용내역!$H$3:$H$2003,사용내역!$C$3:$C$2003,"호남",사용내역!$E$3:$E$2003,10,사용내역!$F$3:$F$2003,"안전시설비"),0) -> 0 | M25: =IFERROR(SUMIFS(사용내역!$H$3:$H$2003,사용내역!$C$3:$C$2003,"호남",사용내역!$E$3:$E$2003,11,사용내역!$F$3:$F$2003,"안전시설비"),0) -> 0 | N25: =IFERROR(SUMIFS(사용내역!$H$3:$H$2003,사용내역!$C$3:$C$2003,"호남",사용내역!$E$3:$E$2003,12,사용내역!$F$3:$F$2003,"안전시설비"),0) -> 0 | O25: =SUM(C25:N25) -> 0 | P25: =IFERROR(COUNTIFS(사용내역!$C$3:$C$2003,"호남",사용내역!$F$3:$F$2003,"안전시설비",사용내역!$J$3:$J$2003,"Y"),0) -> 0
B26: 보호구·안전용품 | C26: =IFERROR(SUMIFS(사용내역!$H$3:$H$2003,사용내역!$C$3:$C$2003,"호남",사용내역!$E$3:$E$2003,1,사용내역!$F$3:$F$2003,"보호구·안전용품"),0) -> 0 | D26: =IFERROR(SUMIFS(사용내역!$H$3:$H$2003,사용내역!$C$3:$C$2003,"호남",사용내역!$E$3:$E$2003,2,사용내역!$F$3:$F$2003,"보호구·안전용품"),0) -> 0 | E26: =IFERROR(SUMIFS(사용내역!$H$3:$H$2003,사용내역!$C$3:$C$2003,"호남",사용내역!$E$3:$E$2003,3,사용내역!$F$3:$F$2003,"보호구·안전용품"),0) -> 0 | F26: =IFERROR(SUMIFS(사용내역!$H$3:$H$2003,사용내역!$C$3:$C$2003,"호남",사용내역!$E$3:$E$2003,4,사용내역!$F$3:$F$2003,"보호구·안전용품"),0) -> 0 | G26: =IFERROR(SUMIFS(사용내역!$H$3:$H$2003,사용내역!$C$3:$C$2003,"호남",사용내역!$E$3:$E$2003,5,사용내역!$F$3:$F$2003,"보호구·안전용품"),0) -> 0 | H26: =IFERROR(SUMIFS(사용내역!$H$3:$H$2003,사용내역!$C$3:$C$2003,"호남",사용내역!$E$3:$E$2003,6,사용내역!$F$3:$F$2003,"보호구·안전용품"),0) -> 0 | I26: =IFERROR(SUMIFS(사용내역!$H$3:$H$2003,사용내역!$C$3:$C$2003,"호남",사용내역!$E$3:$E$2003,7,사용내역!$F$3:$F$2003,"보호구·안전용품"),0) -> 0 | J26: =IFERROR(SUMIFS(사용내역!$H$3:$H$2003,사용내역!$C$3:$C$2003,"호남",사용내역!$E$3:$E$2003,8,사용내역!$F$3:$F$2003,"보호구·안전용품"),0) -> 0 | K26: =IFERROR(SUMIFS(사용내역!$H$3:$H$2003,사용내역!$C$3:$C$2003,"호남",사용내역!$E$3:$E$2003,9,사용내역!$F$3:$F$2003,"보호구·안전용품"),0) -> 0 | L26: =IFERROR(SUMIFS(사용내역!$H$3:$H$2003,사용내역!$C$3:$C$2003,"호남",사용내역!$E$3:$E$2003,10,사용내역!$F$3:$F$2003,"보호구·안전용품"),0) -> 0 | M26: =IFERROR(SUMIFS(사용내역!$H$3:$H$2003,사용내역!$C$3:$C$2003,"호남",사용내역!$E$3:$E$2003,11,사용내역!$F$3:$F$2003,"보호구·안전용품"),0) -> 0 | N26: =IFERROR(SUMIFS(사용내역!$H$3:$H$2003,사용내역!$C$3:$C$2003,"호남",사용내역!$E$3:$E$2003,12,사용내역!$F$3:$F$2003,"보호구·안전용품"),0) -> 0 | O26: =SUM(C26:N26) -> 0 | P26: =IFERROR(COUNTIFS(사용내역!$C$3:$C$2003,"호남",사용내역!$F$3:$F$2003,"보호구·안전용품",사용내역!$J$3:$J$2003,"Y"),0) -> 0
B27: 안전진단비 | C27: =IFERROR(SUMIFS(사용내역!$H$3:$H$2003,사용내역!$C$3:$C$2003,"호남",사용내역!$E$3:$E$2003,1,사용내역!$F$3:$F$2003,"안전진단비"),0) -> 0 | D27: =IFERROR(SUMIFS(사용내역!$H$3:$H$2003,사용내역!$C$3:$C$2003,"호남",사용내역!$E$3:$E$2003,2,사용내역!$F$3:$F$2003,"안전진단비"),0) -> 0 | E27: =IFERROR(SUMIFS(사용내역!$H$3:$H$2003,사용내역!$C$3:$C$2003,"호남",사용내역!$E$3:$E$2003,3,사용내역!$F$3:$F$2003,"안전진단비"),0) -> 0 | F27: =IFERROR(SUMIFS(사용내역!$H$3:$H$2003,사용내역!$C$3:$C$2003,"호남",사용내역!$E$3:$E$2003,4,사용내역!$F$3:$F$2003,"안전진단비"),0) -> 0 | G27: =IFERROR(SUMIFS(사용내역!$H$3:$H$2003,사용내역!$C$3:$C$2003,"호남",사용내역!$E$3:$E$2003,5,사용내역!$F$3:$F$2003,"안전진단비"),0) -> 0 | H27: =IFERROR(SUMIFS(사용내역!$H$3:$H$2003,사용내역!$C$3:$C$2003,"호남",사용내역!$E$3:$E$2003,6,사용내역!$F$3:$F$2003,"안전진단비"),0) -> 0 | I27: =IFERROR(SUMIFS(사용내역!$H$3:$H$2003,사용내역!$C$3:$C$2003,"호남",사용내역!$E$3:$E$2003,7,사용내역!$F$3:$F$2003,"안전진단비"),0) -> 0 | J27: =IFERROR(SUMIFS(사용내역!$H$3:$H$2003,사용내역!$C$3:$C$2003,"호남",사용내역!$E$3:$E$2003,8,사용내역!$F$3:$F$2003,"안전진단비"),0) -> 0 | K27: =IFERROR(SUMIFS(사용내역!$H$3:$H$2003,사용내역!$C$3:$C$2003,"호남",사용내역!$E$3:$E$2003,9,사용내역!$F$3:$F$2003,"안전진단비"),0) -> 0 | L27: =IFERROR(SUMIFS(사용내역!$H$3:$H$2003,사용내역!$C$3:$C$2003,"호남",사용내역!$E$3:$E$2003,10,사용내역!$F$3:$F$2003,"안전진단비"),0) -> 0 | M27: =IFERROR(SUMIFS(사용내역!$H$3:$H$2003,사용내역!$C$3:$C$2003,"호남",사용내역!$E$3:$E$2003,11,사용내역!$F$3:$F$2003,"안전진단비"),0) -> 0 | N27: =IFERROR(SUMIFS(사용내역!$H$3:$H$2003,사용내역!$C$3:$C$2003,"호남",사용내역!$E$3:$E$2003,12,사용내역!$F$3:$F$2003,"안전진단비"),0) -> 0 | O27: =SUM(C27:N27) -> 0 | P27: =IFERROR(COUNTIFS(사용내역!$C$3:$C$2003,"호남",사용내역!$F$3:$F$2003,"안전진단비",사용내역!$J$3:$J$2003,"Y"),0) -> 0
B28: 안전보건교육비·행사비 등 | C28: =IFERROR(SUMIFS(사용내역!$H$3:$H$2003,사용내역!$C$3:$C$2003,"호남",사용내역!$E$3:$E$2003,1,사용내역!$F$3:$F$2003,"안전보건교육비·행사비 등"),0) -> 0 | D28: =IFERROR(SUMIFS(사용내역!$H$3:$H$2003,사용내역!$C$3:$C$2003,"호남",사용내역!$E$3:$E$2003,2,사용내역!$F$3:$F$2003,"안전보건교육비·행사비 등"),0) -> 0 | E28: =IFERROR(SUMIFS(사용내역!$H$3:$H$2003,사용내역!$C$3:$C$2003,"호남",사용내역!$E$3:$E$2003,3,사용내역!$F$3:$F$2003,"안전보건교육비·행사비 등"),0) -> 0 | F28: =IFERROR(SUMIFS(사용내역!$H$3:$H$2003,사용내역!$C$3:$C$2003,"호남",사용내역!$E$3:$E$2003,4,사용내역!$F$3:$F$2003,"안전보건교육비·행사비 등"),0) -> 0 | G28: =IFERROR(SUMIFS(사용내역!$H$3:$H$2003,사용내역!$C$3:$C$2003,"호남",사용내역!$E$3:$E$2003,5,사용내역!$F$3:$F$2003,"안전보건교육비·행사비 등"),0) -> 0 | H28: =IFERROR(SUMIFS(사용내역!$H$3:$H$2003,사용내역!$C$3:$C$2003,"호남",사용내역!$E$3:$E$2003,6,사용내역!$F$3:$F$2003,"안전보건교육비·행사비 등"),0) -> 0 | I28: =IFERROR(SUMIFS(사용내역!$H$3:$H$2003,사용내역!$C$3:$C$2003,"호남",사용내역!$E$3:$E$2003,7,사용내역!$F$3:$F$2003,"안전보건교육비·행사비 등"),0) -> 0 | J28: =IFERROR(SUMIFS(사용내역!$H$3:$H$2003,사용내역!$C$3:$C$2003,"호남",사용내역!$E$3:$E$2003,8,사용내역!$F$3:$F$2003,"안전보건교육비·행사비 등"),0) -> 0 | K28: =IFERROR(SUMIFS(사용내역!$H$3:$H$2003,사용내역!$C$3:$C$2003,"호남",사용내역!$E$3:$E$2003,9,사용내역!$F$3:$F$2003,"안전보건교육비·행사비 등"),0) -> 0 | L28: =IFERROR(SUMIFS(사용내역!$H$3:$H$2003,사용내역!$C$3:$C$2003,"호남",사용내역!$E$3:$E$2003,10,사용내역!$F$3:$F$2003,"안전보건교육비·행사비 등"),0) -> 0 | M28: =IFERROR(SUMIFS(사용내역!$H$3:$H$2003,사용내역!$C$3:$C$2003,"호남",사용내역!$E$3:$E$2003,11,사용내역!$F$3:$F$2003,"안전보건교육비·행사비 등"),0) -> 0 | N28: =IFERROR(SUMIFS(사용내역!$H$3:$H$2003,사용내역!$C$3:$C$2003,"호남",사용내역!$E$3:$E$2003,12,사용내역!$F$3:$F$2003,"안전보건교육비·행사비 등"),0) -> 0 | O28: =SUM(C28:N28) -> 0 | P28: =IFERROR(COUNTIFS(사용내역!$C$3:$C$2003,"호남",사용내역!$F$3:$F$2003,"안전보건교육비·행사비 등",사용내역!$J$3:$J$2003,"Y"),0) -> 0
B29: 근로자 건강관리비 등 | C29: =IFERROR(SUMIFS(사용내역!$H$3:$H$2003,사용내역!$C$3:$C$2003,"호남",사용내역!$E$3:$E$2003,1,사용내역!$F$3:$F$2003,"근로자 건강관리비 등"),0) -> 0 | D29: =IFERROR(SUMIFS(사용내역!$H$3:$H$2003,사용내역!$C$3:$C$2003,"호남",사용내역!$E$3:$E$2003,2,사용내역!$F$3:$F$2003,"근로자 건강관리비 등"),0) -> 0 | E29: =IFERROR(SUMIFS(사용내역!$H$3:$H$2003,사용내역!$C$3:$C$2003,"호남",사용내역!$E$3:$E$2003,3,사용내역!$F$3:$F$2003,"근로자 건강관리비 등"),0) -> 0 | F29: =IFERROR(SUMIFS(사용내역!$H$3:$H$2003,사용내역!$C$3:$C$2003,"호남",사용내역!$E$3:$E$2003,4,사용내역!$F$3:$F$2003,"근로자 건강관리비 등"),0) -> 0 | G29: =IFERROR(SUMIFS(사용내역!$H$3:$H$2003,사용내역!$C$3:$C$2003,"호남",사용내역!$E$3:$E$2003,5,사용내역!$F$3:$F$2003,"근로자 건강관리비 등"),0) -> 0 | H29: =IFERROR(SUMIFS(사용내역!$H$3:$H$2003,사용내역!$C$3:$C$2003,"호남",사용내역!$E$3:$E$2003,6,사용내역!$F$3:$F$2003,"근로자 건강관리비 등"),0) -> 0 | I29: =IFERROR(SUMIFS(사용내역!$H$3:$H$2003,사용내역!$C$3:$C$2003,"호남",사용내역!$E$3:$E$2003,7,사용내역!$F$3:$F$2003,"근로자 건강관리비 등"),0) -> 0 | J29: =IFERROR(SUMIFS(사용내역!$H$3:$H$2003,사용내역!$C$3:$C$2003,"호남",사용내역!$E$3:$E$2003,8,사용내역!$F$3:$F$2003,"근로자 건강관리비 등"),0) -> 0 | K29: =IFERROR(SUMIFS(사용내역!$H$3:$H$2003,사용내역!$C$3:$C$2003,"호남",사용내역!$E$3:$E$2003,9,사용내역!$F$3:$F$2003,"근로자 건강관리비 등"),0) -> 0 | L29: =IFERROR(SUMIFS(사용내역!$H$3:$H$2003,사용내역!$C$3:$C$2003,"호남",사용내역!$E$3:$E$2003,10,사용내역!$F$3:$F$2003,"근로자 건강관리비 등"),0) -> 0 | M29: =IFERROR(SUMIFS(사용내역!$H$3:$H$2003,사용내역!$C$3:$C$2003,"호남",사용내역!$E$3:$E$2003,11,사용내역!$F$3:$F$2003,"근로자 건강관리비 등"),0) -> 0 | N29: =IFERROR(SUMIFS(사용내역!$H$3:$H$2003,사용내역!$C$3:$C$2003,"호남",사용내역!$E$3:$E$2003,12,사용내역!$F$3:$F$2003,"근로자 건강관리비 등"),0) -> 0 | O29: =SUM(C29:N29) -> 0 | P29: =IFERROR(COUNTIFS(사용내역!$C$3:$C$2003,"호남",사용내역!$F$3:$F$2003,"근로자 건강관리비 등",사용내역!$J$3:$J$2003,"Y"),0) -> 0
B30: 건설재해예방 기술지도비 | C30: =IFERROR(SUMIFS(사용내역!$H$3:$H$2003,사용내역!$C$3:$C$2003,"호남",사용내역!$E$3:$E$2003,1,사용내역!$F$3:$F$2003,"건설재해예방 기술지도비"),0) -> 0 | D30: =IFERROR(SUMIFS(사용내역!$H$3:$H$2003,사용내역!$C$3:$C$2003,"호남",사용내역!$E$3:$E$2003,2,사용내역!$F$3:$F$2003,"건설재해예방 기술지도비"),0) -> 0 | E30: =IFERROR(SUMIFS(사용내역!$H$3:$H$2003,사용내역!$C$3:$C$2003,"호남",사용내역!$E$3:$E$2003,3,사용내역!$F$3:$F$2003,"건설재해예방 기술지도비"),0) -> 0 | F30: =IFERROR(SUMIFS(사용내역!$H$3:$H$2003,사용내역!$C$3:$C$2003,"호남",사용내역!$E$3:$E$2003,4,사용내역!$F$3:$F$2003,"건설재해예방 기술지도비"),0) -> 0 | G30: =IFERROR(SUMIFS(사용내역!$H$3:$H$2003,사용내역!$C$3:$C$2003,"호남",사용내역!$E$3:$E$2003,5,사용내역!$F$3:$F$2003,"건설재해예방 기술지도비"),0) -> 0 | H30: =IFERROR(SUMIFS(사용내역!$H$3:$H$2003,사용내역!$C$3:$C$2003,"호남",사용내역!$E$3:$E$2003,6,사용내역!$F$3:$F$2003,"건설재해예방 기술지도비"),0) -> 0 | I30: =IFERROR(SUMIFS(사용내역!$H$3:$H$2003,사용내역!$C$3:$C$2003,"호남",사용내역!$E$3:$E$2003,7,사용내역!$F$3:$F$2003,"건설재해예방 기술지도비"),0) -> 0 | J30: =IFERROR(SUMIFS(사용내역!$H$3:$H$2003,사용내역!$C$3:$C$2003,"호남",사용내역!$E$3:$E$2003,8,사용내역!$F$3:$F$2003,"건설재해예방 기술지도비"),0) -> 0 | K30: =IFERROR(SUMIFS(사용내역!$H$3:$H$2003,사용내역!$C$3:$C$2003,"호남",사용내역!$E$3:$E$2003,9,사용내역!$F$3:$F$2003,"건설재해예방 기술지도비"),0) -> 0 | L30: =IFERROR(SUMIFS(사용내역!$H$3:$H$2003,사용내역!$C$3:$C$2003,"호남",사용내역!$E$3:$E$2003,10,사용내역!$F$3:$F$2003,"건설재해예방 기술지도비"),0) -> 0 | M30: =IFERROR(SUMIFS(사용내역!$H$3:$H$2003,사용내역!$C$3:$C$2003,"호남",사용내역!$E$3:$E$2003,11,사용내역!$F$3:$F$2003,"건설재해예방 기술지도비"),0) -> 0 | N30: =IFERROR(SUMIFS(사용내역!$H$3:$H$2003,사용내역!$C$3:$C$2003,"호남",사용내역!$E$3:$E$2003,12,사용내역!$F$3:$F$2003,"건설재해예방 기술지도비"),0) -> 0 | O30: =SUM(C30:N30) -> 0 | P30: =IFERROR(COUNTIFS(사용내역!$C$3:$C$2003,"호남",사용내역!$F$3:$F$2003,"건설재해예방 기술지도비",사용내역!$J$3:$J$2003,"Y"),0) -> 0
B31: 기타 | C31: =IFERROR(SUMIFS(사용내역!$H$3:$H$2003,사용내역!$C$3:$C$2003,"호남",사용내역!$E$3:$E$2003,1,사용내역!$F$3:$F$2003,"기타"),0) -> 0 | D31: =IFERROR(SUMIFS(사용내역!$H$3:$H$2003,사용내역!$C$3:$C$2003,"호남",사용내역!$E$3:$E$2003,2,사용내역!$F$3:$F$2003,"기타"),0) -> 0 | E31: =IFERROR(SUMIFS(사용내역!$H$3:$H$2003,사용내역!$C$3:$C$2003,"호남",사용내역!$E$3:$E$2003,3,사용내역!$F$3:$F$2003,"기타"),0) -> 0 | F31: =IFERROR(SUMIFS(사용내역!$H$3:$H$2003,사용내역!$C$3:$C$2003,"호남",사용내역!$E$3:$E$2003,4,사용내역!$F$3:$F$2003,"기타"),0) -> 0 | G31: =IFERROR(SUMIFS(사용내역!$H$3:$H$2003,사용내역!$C$3:$C$2003,"호남",사용내역!$E$3:$E$2003,5,사용내역!$F$3:$F$2003,"기타"),0) -> 0 | H31: =IFERROR(SUMIFS(사용내역!$H$3:$H$2003,사용내역!$C$3:$C$2003,"호남",사용내역!$E$3:$E$2003,6,사용내역!$F$3:$F$2003,"기타"),0) -> 0 | I31: =IFERROR(SUMIFS(사용내역!$H$3:$H$2003,사용내역!$C$3:$C$2003,"호남",사용내역!$E$3:$E$2003,7,사용내역!$F$3:$F$2003,"기타"),0) -> 0 | J31: =IFERROR(SUMIFS(사용내역!$H$3:$H$2003,사용내역!$C$3:$C$2003,"호남",사용내역!$E$3:$E$2003,8,사용내역!$F$3:$F$2003,"기타"),0) -> 0 | K31: =IFERROR(SUMIFS(사용내역!$H$3:$H$2003,사용내역!$C$3:$C$2003,"호남",사용내역!$E$3:$E$2003,9,사용내역!$F$3:$F$2003,"기타"),0) -> 0 | L31: =IFERROR(SUMIFS(사용내역!$H$3:$H$2003,사용내역!$C$3:$C$2003,"호남",사용내역!$E$3:$E$2003,10,사용내역!$F$3:$F$2003,"기타"),0) -> 0 | M31: =IFERROR(SUMIFS(사용내역!$H$3:$H$2003,사용내역!$C$3:$C$2003,"호남",사용내역!$E$3:$E$2003,11,사용내역!$F$3:$F$2003,"기타"),0) -> 0 | N31: =IFERROR(SUMIFS(사용내역!$H$3:$H$2003,사용내역!$C$3:$C$2003,"호남",사용내역!$E$3:$E$2003,12,사용내역!$F$3:$F$2003,"기타"),0) -> 0 | O31: =SUM(C31:N31) -> 0 | P31: =IFERROR(COUNTIFS(사용내역!$C$3:$C$2003,"호남",사용내역!$F$3:$F$2003,"기타",사용내역!$J$3:$J$2003,"Y"),0) -> 0
B32: 산보위·위험성평가 안건 | C32: =IFERROR(SUMIFS(사용내역!$H$3:$H$2003,사용내역!$C$3:$C$2003,"호남",사용내역!$E$3:$E$2003,1,사용내역!$F$3:$F$2003,"산보위·위험성평가 안건"),0) -> 0 | D32: =IFERROR(SUMIFS(사용내역!$H$3:$H$2003,사용내역!$C$3:$C$2003,"호남",사용내역!$E$3:$E$2003,2,사용내역!$F$3:$F$2003,"산보위·위험성평가 안건"),0) -> 0 | E32: =IFERROR(SUMIFS(사용내역!$H$3:$H$2003,사용내역!$C$3:$C$2003,"호남",사용내역!$E$3:$E$2003,3,사용내역!$F$3:$F$2003,"산보위·위험성평가 안건"),0) -> 0 | F32: =IFERROR(SUMIFS(사용내역!$H$3:$H$2003,사용내역!$C$3:$C$2003,"호남",사용내역!$E$3:$E$2003,4,사용내역!$F$3:$F$2003,"산보위·위험성평가 안건"),0) -> 0 | G32: =IFERROR(SUMIFS(사용내역!$H$3:$H$2003,사용내역!$C$3:$C$2003,"호남",사용내역!$E$3:$E$2003,5,사용내역!$F$3:$F$2003,"산보위·위험성평가 안건"),0) -> 0 | H32: =IFERROR(SUMIFS(사용내역!$H$3:$H$2003,사용내역!$C$3:$C$2003,"호남",사용내역!$E$3:$E$2003,6,사용내역!$F$3:$F$2003,"산보위·위험성평가 안건"),0) -> 0 | I32: =IFERROR(SUMIFS(사용내역!$H$3:$H$2003,사용내역!$C$3:$C$2003,"호남",사용내역!$E$3:$E$2003,7,사용내역!$F$3:$F$2003,"산보위·위험성평가 안건"),0) -> 0 | J32: =IFERROR(SUMIFS(사용내역!$H$3:$H$2003,사용내역!$C$3:$C$2003,"호남",사용내역!$E$3:$E$2003,8,사용내역!$F$3:$F$2003,"산보위·위험성평가 안건"),0) -> 0 | K32: =IFERROR(SUMIFS(사용내역!$H$3:$H$2003,사용내역!$C$3:$C$2003,"호남",사용내역!$E$3:$E$2003,9,사용내역!$F$3:$F$2003,"산보위·위험성평가 안건"),0) -> 0 | L32: =IFERROR(SUMIFS(사용내역!$H$3:$H$2003,사용내역!$C$3:$C$2003,"호남",사용내역!$E$3:$E$2003,10,사용내역!$F$3:$F$2003,"산보위·위험성평가 안건"),0) -> 0 | M32: =IFERROR(SUMIFS(사용내역!$H$3:$H$2003,사용내역!$C$3:$C$2003,"호남",사용내역!$E$3:$E$2003,11,사용내역!$F$3:$F$2003,"산보위·위험성평가 안건"),0) -> 0 | N32: =IFERROR(SUMIFS(사용내역!$H$3:$H$2003,사용내역!$C$3:$C$2003,"호남",사용내역!$E$3:$E$2003,12,사용내역!$F$3:$F$2003,"산보위·위험성평가 안건"),0) -> 0 | O32: =SUM(C32:N32) -> 0 | P32: =IFERROR(COUNTIFS(사용내역!$C$3:$C$2003,"호남",사용내역!$F$3:$F$2003,"산보위·위험성평가 안건",사용내역!$J$3:$J$2003,"Y"),0) -> 0
A33: 호남본부 소계 | C33: =SUM(C24:C32) -> 0 | D33: =SUM(D24:D32) -> 0 | E33: =SUM(E24:E32) -> 0 | F33: =SUM(F24:F32) -> 0 | G33: =SUM(G24:G32) -> 0 | H33: =SUM(H24:H32) -> 0 | I33: =SUM(I24:I32) -> 0 | J33: =SUM(J24:J32) -> 0 | ... P33: =SUM(P24:P32) -> 0
A34: 부산본부 | B34: 안전관리자 등 인건비 | C34: =IFERROR(SUMIFS(사용내역!$H$3:$H$2003,사용내역!$C$3:$C$2003,"부산",사용내역!$E$3:$E$2003,1,사용내역!$F$3:$F$2003,"안전관리자 등 인건비"),0) -> 0 | D34: =IFERROR(SUMIFS(사용내역!$H$3:$H$2003,사용내역!$C$3:$C$2003,"부산",사용내역!$E$3:$E$2003,2,사용내역!$F$3:$F$2003,"안전관리자 등 인건비"),0) -> 0 | E34: =IFERROR(SUMIFS(사용내역!$H$3:$H$2003,사용내역!$C$3:$C$2003,"부산",사용내역!$E$3:$E$2003,3,사용내역!$F$3:$F$2003,"안전관리자 등 인건비"),0) -> 0 | F34: =IFERROR(SUMIFS(사용내역!$H$3:$H$2003,사용내역!$C$3:$C$2003,"부산",사용내역!$E$3:$E$2003,4,사용내역!$F$3:$F$2003,"안전관리자 등 인건비"),0) -> 0 | G34: =IFERROR(SUMIFS(사용내역!$H$3:$H$2003,사용내역!$C$3:$C$2003,"부산",사용내역!$E$3:$E$2003,5,사용내역!$F$3:$F$2003,"안전관리자 등 인건비"),0) -> 0 | H34: =IFERROR(SUMIFS(사용내역!$H$3:$H$2003,사용내역!$C$3:$C$2003,"부산",사용내역!$E$3:$E$2003,6,사용내역!$F$3:$F$2003,"안전관리자 등 인건비"),0) -> 0 | I34: =IFERROR(SUMIFS(사용내역!$H$3:$H$2003,사용내역!$C$3:$C$2003,"부산",사용내역!$E$3:$E$2003,7,사용내역!$F$3:$F$2003,"안전관리자 등 인건비"),0) -> 0 | J34: =IFERROR(SUMIFS(사용내역!$H$3:$H$2003,사용내역!$C$3:$C$2003,"부산",사용내역!$E$3:$E$2003,8,사용내역!$F$3:$F$2003,"안전관리자 등 인건비"),0) -> 0 | K34: =IFERROR(SUMIFS(사용내역!$H$3:$H$2003,사용내역!$C$3:$C$2003,"부산",사용내역!$E$3:$E$2003,9,사용내역!$F$3:$F$2003,"안전관리자 등 인건비"),0) -> 0 | L34: =IFERROR(SUMIFS(사용내역!$H$3:$H$2003,사용내역!$C$3:$C$2003,"부산",사용내역!$E$3:$E$2003,10,사용내역!$F$3:$F$2003,"안전관리자 등 인건비"),0) -> 0 | M34: =IFERROR(SUMIFS(사용내역!$H$3:$H$2003,사용내역!$C$3:$C$2003,"부산",사용내역!$E$3:$E$2003,11,사용내역!$F$3:$F$2003,"안전관리자 등 인건비"),0) -> 0 | N34: =IFERROR(SUMIFS(사용내역!$H$3:$H$2003,사용내역!$C$3:$C$2003,"부산",사용내역!$E$3:$E$2003,12,사용내역!$F$3:$F$2003,"안전관리자 등 인건비"),0) -> 0 | O34: =SUM(C34:N34) -> 0 | P34: =IFERROR(COUNTIFS(사용내역!$C$3:$C$2003,"부산",사용내역!$F$3:$F$2003,"안전관리자 등 인건비",사용내역!$J$3:$J$2003,"Y"),0) -> 0
B35: 안전시설비 | C35: =IFERROR(SUMIFS(사용내역!$H$3:$H$2003,사용내역!$C$3:$C$2003,"부산",사용내역!$E$3:$E$2003,1,사용내역!$F$3:$F$2003,"안전시설비"),0) -> 0 | D35: =IFERROR(SUMIFS(사용내역!$H$3:$H$2003,사용내역!$C$3:$C$2003,"부산",사용내역!$E$3:$E$2003,2,사용내역!$F$3:$F$2003,"안전시설비"),0) -> 0 | E35: =IFERROR(SUMIFS(사용내역!$H$3:$H$2003,사용내역!$C$3:$C$2003,"부산",사용내역!$E$3:$E$2003,3,사용내역!$F$3:$F$2003,"안전시설비"),0) -> 0 | F35: =IFERROR(SUMIFS(사용내역!$H$3:$H$2003,사용내역!$C$3:$C$2003,"부산",사용내역!$E$3:$E$2003,4,사용내역!$F$3:$F$2003,"안전시설비"),0) -> 0 | G35: =IFERROR(SUMIFS(사용내역!$H$3:$H$2003,사용내역!$C$3:$C$2003,"부산",사용내역!$E$3:$E$2003,5,사용내역!$F$3:$F$2003,"안전시설비"),0) -> 0 | H35: =IFERROR(SUMIFS(사용내역!$H$3:$H$2003,사용내역!$C$3:$C$2003,"부산",사용내역!$E$3:$E$2003,6,사용내역!$F$3:$F$2003,"안전시설비"),0) -> 0 | I35: =IFERROR(SUMIFS(사용내역!$H$3:$H$2003,사용내역!$C$3:$C$2003,"부산",사용내역!$E$3:$E$2003,7,사용내역!$F$3:$F$2003,"안전시설비"),0) -> 0 | J35: =IFERROR(SUMIFS(사용내역!$H$3:$H$2003,사용내역!$C$3:$C$2003,"부산",사용내역!$E$3:$E$2003,8,사용내역!$F$3:$F$2003,"안전시설비"),0) -> 0 | K35: =IFERROR(SUMIFS(사용내역!$H$3:$H$2003,사용내역!$C$3:$C$2003,"부산",사용내역!$E$3:$E$2003,9,사용내역!$F$3:$F$2003,"안전시설비"),0) -> 0 | L35: =IFERROR(SUMIFS(사용내역!$H$3:$H$2003,사용내역!$C$3:$C$2003,"부산",사용내역!$E$3:$E$2003,10,사용내역!$F$3:$F$2003,"안전시설비"),0) -> 0 | M35: =IFERROR(SUMIFS(사용내역!$H$3:$H$2003,사용내역!$C$3:$C$2003,"부산",사용내역!$E$3:$E$2003,11,사용내역!$F$3:$F$2003,"안전시설비"),0) -> 0 | N35: =IFERROR(SUMIFS(사용내역!$H$3:$H$2003,사용내역!$C$3:$C$2003,"부산",사용내역!$E$3:$E$2003,12,사용내역!$F$3:$F$2003,"안전시설비"),0) -> 0 | O35: =SUM(C35:N35) -> 0 | P35: =IFERROR(COUNTIFS(사용내역!$C$3:$C$2003,"부산",사용내역!$F$3:$F$2003,"안전시설비",사용내역!$J$3:$J$2003,"Y"),0) -> 0
B36: 보호구·안전용품 | C36: =IFERROR(SUMIFS(사용내역!$H$3:$H$2003,사용내역!$C$3:$C$2003,"부산",사용내역!$E$3:$E$2003,1,사용내역!$F$3:$F$2003,"보호구·안전용품"),0) -> 0 | D36: =IFERROR(SUMIFS(사용내역!$H$3:$H$2003,사용내역!$C$3:$C$2003,"부산",사용내역!$E$3:$E$2003,2,사용내역!$F$3:$F$2003,"보호구·안전용품"),0) -> 0 | E36: =IFERROR(SUMIFS(사용내역!$H$3:$H$2003,사용내역!$C$3:$C$2003,"부산",사용내역!$E$3:$E$2003,3,사용내역!$F$3:$F$2003,"보호구·안전용품"),0) -> 0 | F36: =IFERROR(SUMIFS(사용내역!$H$3:$H$2003,사용내역!$C$3:$C$2003,"부산",사용내역!$E$3:$E$2003,4,사용내역!$F$3:$F$2003,"보호구·안전용품"),0) -> 0 | G36: =IFERROR(SUMIFS(사용내역!$H$3:$H$2003,사용내역!$C$3:$C$2003,"부산",사용내역!$E$3:$E$2003,5,사용내역!$F$3:$F$2003,"보호구·안전용품"),0) -> 0 | H36: =IFERROR(SUMIFS(사용내역!$H$3:$H$2003,사용내역!$C$3:$C$2003,"부산",사용내역!$E$3:$E$2003,6,사용내역!$F$3:$F$2003,"보호구·안전용품"),0) -> 0 | I36: =IFERROR(SUMIFS(사용내역!$H$3:$H$2003,사용내역!$C$3:$C$2003,"부산",사용내역!$E$3:$E$2003,7,사용내역!$F$3:$F$2003,"보호구·안전용품"),0) -> 0 | J36: =IFERROR(SUMIFS(사용내역!$H$3:$H$2003,사용내역!$C$3:$C$2003,"부산",사용내역!$E$3:$E$2003,8,사용내역!$F$3:$F$2003,"보호구·안전용품"),0) -> 0 | K36: =IFERROR(SUMIFS(사용내역!$H$3:$H$2003,사용내역!$C$3:$C$2003,"부산",사용내역!$E$3:$E$2003,9,사용내역!$F$3:$F$2003,"보호구·안전용품"),0) -> 0 | L36: =IFERROR(SUMIFS(사용내역!$H$3:$H$2003,사용내역!$C$3:$C$2003,"부산",사용내역!$E$3:$E$2003,10,사용내역!$F$3:$F$2003,"보호구·안전용품"),0) -> 0 | M36: =IFERROR(SUMIFS(사용내역!$H$3:$H$2003,사용내역!$C$3:$C$2003,"부산",사용내역!$E$3:$E$2003,11,사용내역!$F$3:$F$2003,"보호구·안전용품"),0) -> 0 | N36: =IFERROR(SUMIFS(사용내역!$H$3:$H$2003,사용내역!$C$3:$C$2003,"부산",사용내역!$E$3:$E$2003,12,사용내역!$F$3:$F$2003,"보호구·안전용품"),0) -> 0 | O36: =SUM(C36:N36) -> 0 | P36: =IFERROR(COUNTIFS(사용내역!$C$3:$C$2003,"부산",사용내역!$F$3:$F$2003,"보호구·안전용품",사용내역!$J$3:$J$2003,"Y"),0) -> 0
B37: 안전진단비 | C37: =IFERROR(SUMIFS(사용내역!$H$3:$H$2003,사용내역!$C$3:$C$2003,"부산",사용내역!$E$3:$E$2003,1,사용내역!$F$3:$F$2003,"안전진단비"),0) -> 0 | D37: =IFERROR(SUMIFS(사용내역!$H$3:$H$2003,사용내역!$C$3:$C$2003,"부산",사용내역!$E$3:$E$2003,2,사용내역!$F$3:$F$2003,"안전진단비"),0) -> 0 | E37: =IFERROR(SUMIFS(사용내역!$H$3:$H$2003,사용내역!$C$3:$C$2003,"부산",사용내역!$E$3:$E$2003,3,사용내역!$F$3:$F$2003,"안전진단비"),0) -> 0 | F37: =IFERROR(SUMIFS(사용내역!$H$3:$H$2003,사용내역!$C$3:$C$2003,"부산",사용내역!$E$3:$E$2003,4,사용내역!$F$3:$F$2003,"안전진단비"),0) -> 0 | G37: =IFERROR(SUMIFS(사용내역!$H$3:$H$2003,사용내역!$C$3:$C$2003,"부산",사용내역!$E$3:$E$2003,5,사용내역!$F$3:$F$2003,"안전진단비"),0) -> 0 | H37: =IFERROR(SUMIFS(사용내역!$H$3:$H$2003,사용내역!$C$3:$C$2003,"부산",사용내역!$E$3:$E$2003,6,사용내역!$F$3:$F$2003,"안전진단비"),0) -> 0 | I37: =IFERROR(SUMIFS(사용내역!$H$3:$H$2003,사용내역!$C$3:$C$2003,"부산",사용내역!$E$3:$E$2003,7,사용내역!$F$3:$F$2003,"안전진단비"),0) -> 0 | J37: =IFERROR(SUMIFS(사용내역!$H$3:$H$2003,사용내역!$C$3:$C$2003,"부산",사용내역!$E$3:$E$2003,8,사용내역!$F$3:$F$2003,"안전진단비"),0) -> 0 | K37: =IFERROR(SUMIFS(사용내역!$H$3:$H$2003,사용내역!$C$3:$C$2003,"부산",사용내역!$E$3:$E$2003,9,사용내역!$F$3:$F$2003,"안전진단비"),0) -> 0 | L37: =IFERROR(SUMIFS(사용내역!$H$3:$H$2003,사용내역!$C$3:$C$2003,"부산",사용내역!$E$3:$E$2003,10,사용내역!$F$3:$F$2003,"안전진단비"),0) -> 0 | M37: =IFERROR(SUMIFS(사용내역!$H$3:$H$2003,사용내역!$C$3:$C$2003,"부산",사용내역!$E$3:$E$2003,11,사용내역!$F$3:$F$2003,"안전진단비"),0) -> 0 | N37: =IFERROR(SUMIFS(사용내역!$H$3:$H$2003,사용내역!$C$3:$C$2003,"부산",사용내역!$E$3:$E$2003,12,사용내역!$F$3:$F$2003,"안전진단비"),0) -> 0 | O37: =SUM(C37:N37) -> 0 | P37: =IFERROR(COUNTIFS(사용내역!$C$3:$C$2003,"부산",사용내역!$F$3:$F$2003,"안전진단비",사용내역!$J$3:$J$2003,"Y"),0) -> 0
B38: 안전보건교육비·행사비 등 | C38: =IFERROR(SUMIFS(사용내역!$H$3:$H$2003,사용내역!$C$3:$C$2003,"부산",사용내역!$E$3:$E$2003,1,사용내역!$F$3:$F$2003,"안전보건교육비·행사비 등"),0) -> 0 | D38: =IFERROR(SUMIFS(사용내역!$H$3:$H$2003,사용내역!$C$3:$C$2003,"부산",사용내역!$E$3:$E$2003,2,사용내역!$F$3:$F$2003,"안전보건교육비·행사비 등"),0) -> 0 | E38: =IFERROR(SUMIFS(사용내역!$H$3:$H$2003,사용내역!$C$3:$C$2003,"부산",사용내역!$E$3:$E$2003,3,사용내역!$F$3:$F$2003,"안전보건교육비·행사비 등"),0) -> 0 | F38: =IFERROR(SUMIFS(사용내역!$H$3:$H$2003,사용내역!$C$3:$C$2003,"부산",사용내역!$E$3:$E$2003,4,사용내역!$F$3:$F$2003,"안전보건교육비·행사비 등"),0) -> 0 | G38: =IFERROR(SUMIFS(사용내역!$H$3:$H$2003,사용내역!$C$3:$C$2003,"부산",사용내역!$E$3:$E$2003,5,사용내역!$F$3:$F$2003,"안전보건교육비·행사비 등"),0) -> 0 | H38: =IFERROR(SUMIFS(사용내역!$H$3:$H$2003,사용내역!$C$3:$C$2003,"부산",사용내역!$E$3:$E$2003,6,사용내역!$F$3:$F$2003,"안전보건교육비·행사비 등"),0) -> 0 | I38: =IFERROR(SUMIFS(사용내역!$H$3:$H$2003,사용내역!$C$3:$C$2003,"부산",사용내역!$E$3:$E$2003,7,사용내역!$F$3:$F$2003,"안전보건교육비·행사비 등"),0) -> 0 | J38: =IFERROR(SUMIFS(사용내역!$H$3:$H$2003,사용내역!$C$3:$C$2003,"부산",사용내역!$E$3:$E$2003,8,사용내역!$F$3:$F$2003,"안전보건교육비·행사비 등"),0) -> 0 | K38: =IFERROR(SUMIFS(사용내역!$H$3:$H$2003,사용내역!$C$3:$C$2003,"부산",사용내역!$E$3:$E$2003,9,사용내역!$F$3:$F$2003,"안전보건교육비·행사비 등"),0) -> 0 | L38: =IFERROR(SUMIFS(사용내역!$H$3:$H$2003,사용내역!$C$3:$C$2003,"부산",사용내역!$E$3:$E$2003,10,사용내역!$F$3:$F$2003,"안전보건교육비·행사비 등"),0) -> 0 | M38: =IFERROR(SUMIFS(사용내역!$H$3:$H$2003,사용내역!$C$3:$C$2003,"부산",사용내역!$E$3:$E$2003,11,사용내역!$F$3:$F$2003,"안전보건교육비·행사비 등"),0) -> 0 | N38: =IFERROR(SUMIFS(사용내역!$H$3:$H$2003,사용내역!$C$3:$C$2003,"부산",사용내역!$E$3:$E$2003,12,사용내역!$F$3:$F$2003,"안전보건교육비·행사비 등"),0) -> 0 | O38: =SUM(C38:N38) -> 0 | P38: =IFERROR(COUNTIFS(사용내역!$C$3:$C$2003,"부산",사용내역!$F$3:$F$2003,"안전보건교육비·행사비 등",사용내역!$J$3:$J$2003,"Y"),0) -> 0
B39: 근로자 건강관리비 등 | C39: =IFERROR(SUMIFS(사용내역!$H$3:$H$2003,사용내역!$C$3:$C$2003,"부산",사용내역!$E$3:$E$2003,1,사용내역!$F$3:$F$2003,"근로자 건강관리비 등"),0) -> 0 | D39: =IFERROR(SUMIFS(사용내역!$H$3:$H$2003,사용내역!$C$3:$C$2003,"부산",사용내역!$E$3:$E$2003,2,사용내역!$F$3:$F$2003,"근로자 건강관리비 등"),0) -> 0 | E39: =IFERROR(SUMIFS(사용내역!$H$3:$H$2003,사용내역!$C$3:$C$2003,"부산",사용내역!$E$3:$E$2003,3,사용내역!$F$3:$F$2003,"근로자 건강관리비 등"),0) -> 0 | F39: =IFERROR(SUMIFS(사용내역!$H$3:$H$2003,사용내역!$C$3:$C$2003,"부산",사용내역!$E$3:$E$2003,4,사용내역!$F$3:$F$2003,"근로자 건강관리비 등"),0) -> 0 | G39: =IFERROR(SUMIFS(사용내역!$H$3:$H$2003,사용내역!$C$3:$C$2003,"부산",사용내역!$E$3:$E$2003,5,사용내역!$F$3:$F$2003,"근로자 건강관리비 등"),0) -> 0 | H39: =IFERROR(SUMIFS(사용내역!$H$3:$H$2003,사용내역!$C$3:$C$2003,"부산",사용내역!$E$3:$E$2003,6,사용내역!$F$3:$F$2003,"근로자 건강관리비 등"),0) -> 0 | I39: =IFERROR(SUMIFS(사용내역!$H$3:$H$2003,사용내역!$C$3:$C$2003,"부산",사용내역!$E$3:$E$2003,7,사용내역!$F$3:$F$2003,"근로자 건강관리비 등"),0) -> 0 | J39: =IFERROR(SUMIFS(사용내역!$H$3:$H$2003,사용내역!$C$3:$C$2003,"부산",사용내역!$E$3:$E$2003,8,사용내역!$F$3:$F$2003,"근로자 건강관리비 등"),0) -> 0 | K39: =IFERROR(SUMIFS(사용내역!$H$3:$H$2003,사용내역!$C$3:$C$2003,"부산",사용내역!$E$3:$E$2003,9,사용내역!$F$3:$F$2003,"근로자 건강관리비 등"),0) -> 0 | L39: =IFERROR(SUMIFS(사용내역!$H$3:$H$2003,사용내역!$C$3:$C$2003,"부산",사용내역!$E$3:$E$2003,10,사용내역!$F$3:$F$2003,"근로자 건강관리비 등"),0) -> 0 | M39: =IFERROR(SUMIFS(사용내역!$H$3:$H$2003,사용내역!$C$3:$C$2003,"부산",사용내역!$E$3:$E$2003,11,사용내역!$F$3:$F$2003,"근로자 건강관리비 등"),0) -> 0 | N39: =IFERROR(SUMIFS(사용내역!$H$3:$H$2003,사용내역!$C$3:$C$2003,"부산",사용내역!$E$3:$E$2003,12,사용내역!$F$3:$F$2003,"근로자 건강관리비 등"),0) -> 0 | O39: =SUM(C39:N39) -> 0 | P39: =IFERROR(COUNTIFS(사용내역!$C$3:$C$2003,"부산",사용내역!$F$3:$F$2003,"근로자 건강관리비 등",사용내역!$J$3:$J$2003,"Y"),0) -> 0
B40: 건설재해예방 기술지도비 | C40: =IFERROR(SUMIFS(사용내역!$H$3:$H$2003,사용내역!$C$3:$C$2003,"부산",사용내역!$E$3:$E$2003,1,사용내역!$F$3:$F$2003,"건설재해예방 기술지도비"),0) -> 0 | D40: =IFERROR(SUMIFS(사용내역!$H$3:$H$2003,사용내역!$C$3:$C$2003,"부산",사용내역!$E$3:$E$2003,2,사용내역!$F$3:$F$2003,"건설재해예방 기술지도비"),0) -> 0 | E40: =IFERROR(SUMIFS(사용내역!$H$3:$H$2003,사용내역!$C$3:$C$2003,"부산",사용내역!$E$3:$E$2003,3,사용내역!$F$3:$F$2003,"건설재해예방 기술지도비"),0) -> 0 | F40: =IFERROR(SUMIFS(사용내역!$H$3:$H$2003,사용내역!$C$3:$C$2003,"부산",사용내역!$E$3:$E$2003,4,사용내역!$F$3:$F$2003,"건설재해예방 기술지도비"),0) -> 0 | G40: =IFERROR(SUMIFS(사용내역!$H$3:$H$2003,사용내역!$C$3:$C$2003,"부산",사용내역!$E$3:$E$2003,5,사용내역!$F$3:$F$2003,"건설재해예방 기술지도비"),0) -> 0 | H40: =IFERROR(SUMIFS(사용내역!$H$3:$H$2003,사용내역!$C$3:$C$2003,"부산",사용내역!$E$3:$E$2003,6,사용내역!$F$3:$F$2003,"건설재해예방 기술지도비"),0) -> 0 | I40: =IFERROR(SUMIFS(사용내역!$H$3:$H$2003,사용내역!$C$3:$C$2003,"부산",사용내역!$E$3:$E$2003,7,사용내역!$F$3:$F$2003,"건설재해예방 기술지도비"),0) -> 0 | J40: =IFERROR(SUMIFS(사용내역!$H$3:$H$2003,사용내역!$C$3:$C$2003,"부산",사용내역!$E$3:$E$2003,8,사용내역!$F$3:$F$2003,"건설재해예방 기술지도비"),0) -> 0 | K40: =IFERROR(SUMIFS(사용내역!$H$3:$H$2003,사용내역!$C$3:$C$2003,"부산",사용내역!$E$3:$E$2003,9,사용내역!$F$3:$F$2003,"건설재해예방 기술지도비"),0) -> 0 | L40: =IFERROR(SUMIFS(사용내역!$H$3:$H$2003,사용내역!$C$3:$C$2003,"부산",사용내역!$E$3:$E$2003,10,사용내역!$F$3:$F$2003,"건설재해예방 기술지도비"),0) -> 0 | M40: =IFERROR(SUMIFS(사용내역!$H$3:$H$2003,사용내역!$C$3:$C$2003,"부산",사용내역!$E$3:$E$2003,11,사용내역!$F$3:$F$2003,"건설재해예방 기술지도비"),0) -> 0 | N40: =IFERROR(SUMIFS(사용내역!$H$3:$H$2003,사용내역!$C$3:$C$2003,"부산",사용내역!$E$3:$E$2003,12,사용내역!$F$3:$F$2003,"건설재해예방 기술지도비"),0) -> 0 | O40: =SUM(C40:N40) -> 0 | P40: =IFERROR(COUNTIFS(사용내역!$C$3:$C$2003,"부산",사용내역!$F$3:$F$2003,"건설재해예방 기술지도비",사용내역!$J$3:$J$2003,"Y"),0) -> 0
...

Sheet 2.예산입력
A1: ■ 연간 예산 입력표 — 노란색 셀에 금액(원)을 입력하세요
A2: ⚠ 이 시트의 예산을 입력하면 [예산대비_지출통계] 시트에 자동 반영됩니다. 본부별 / 항목별 연간 예산을 입력하세요.
A3: 본부 | B3: 항목 | C3: 연간 예산(원) | D3: 상반기 예산 | E3: 하반기 예산 | F3: 비고
A4: 본사 | B4: 안전관리자 등 인건비 | C4: =E4+D4 -> 0 | D4: 0 | E4: 0
B5: 안전시설비 | C5: =E5+D5 -> 0 | D5: 0 | E5: 0
B6: 보호구·안전용품 | C6: =E6+D6 -> 0 | D6: 0 | E6: 0
B7: 안전진단비 | C7: =E7+D7 -> 0 | D7: 0 | E7: 0
B8: 안전보건교육비·행사비 등 | C8: =E8+D8 -> 0 | D8: 0 | E8: 0
B9: 근로자 건강관리비 등 | C9: =E9+D9 -> 0 | D9: 0 | E9: 0
B10: 건설재해예방 기술지도비 | C10: =E10+D10 -> 0 | D10: 0 | E10: 0
B11: 기타 | C11: =E11+D11 -> 0 | D11: 0 | E11: 0
B12: 산보위·위험성평가 안건 | C12: =E12+D12 -> 0 | D12: 0 | E12: 0
A13: 본사 소계 | C13: =SUM(C4:C12) -> 0 | D13: =SUM(D4:D12) -> 0 | E13: =SUM(E4:E12) -> 0
A14: 충청본부 | B14: 안전관리자 등 인건비 | C14: =SUM(D14:E14) -> 0 | D14: 0 | E14: 0
B15: 안전시설비 | C15: =SUM(D15:E15) -> 0 | D15: 0 | E15: 0
B16: 보호구·안전용품 | C16: =SUM(D16:E16) -> 0 | D16: 0 | E16: 0
B17: 안전진단비 | C17: =SUM(D17:E17) -> 0 | D17: 0 | E17: 0
B18: 안전보건교육비·행사비 등 | C18: =SUM(D18:E18) -> 0 | D18: 0 | E18: 0
B19: 근로자 건강관리비 등 | C19: =SUM(D19:E19) -> 0 | D19: 0 | E19: 0
B20: 건설재해예방 기술지도비 | C20: =SUM(D20:E20) -> 0 | D20: 0 | E20: 0
B21: 기타 | C21: =SUM(D21:E21) -> 0 | D21: 0 | E21: 0
B22: 산보위·위험성평가 안건 | C22: =SUM(D22:E22) -> 0 | D22: 0 | E22: 0
A23: 충청본부 소계 | C23: =SUM(C14:C22) -> 0 | D23: =SUM(D14:D22) -> 0 | E23: =SUM(E14:E22) -> 0
A24: 호남본부 | B24: 안전관리자 등 인건비 | C24: =SUM(D24:E24) -> 0 | D24: 0 | E24: 0
B25: 안전시설비 | C25: =SUM(D25:E25) -> 0 | D25: 0 | E25: 0
B26: 보호구·안전용품 | C26: =SUM(D26:E26) -> 0 | D26: 0 | E26: 0
B27: 안전진단비 | C27: =SUM(D27:E27) -> 0 | D27: 0 | E27: 0
B28: 안전보건교육비·행사비 등 | C28: =SUM(D28:E28) -> 0 | D28: 0 | E28: 0
B29: 근로자 건강관리비 등 | C29: =SUM(D29:E29) -> 0 | D29: 0 | E29: 0
B30: 건설재해예방 기술지도비 | C30: 5 | D30: 0 | E30: 0
B31: 기타 | C31: =SUM(D31:E31) -> 0 | D31: 0 | E31: 0
B32: 산보위·위험성평가 안건 | C32: =SUM(D32:E32) -> 0 | D32: 0 | E32: 0
A33: 호남본부 소계 | C33: 0 | D33: =SUM(D24:D32) -> 0 | E33: =SUM(E24:E32) -> 0
A34: 부산본부 | B34: 안전관리자 등 인건비 | C34: =SUM(D34:E34) -> 0 | D34: 0 | E34: 0
B35: 안전시설비 | C35: =SUM(D35:E35) -> 0 | D35: 0 | E35: 0
B36: 보호구·안전용품 | C36: =SUM(D36:E36) -> 0 | D36: 0 | E36: 0
B37: 안전진단비 | C37: =SUM(D37:E37) -> 0 | D37: 0 | E37: 0
B38: 안전보건교육비·행사비 등 | C38: =SUM(D38:E38) -> 0 | D38: 0 | E38: 0
B39: 근로자 건강관리비 등 | C39: =SUM(D39:E39) -> 0 | D39: 0 | E39: 0
B40: 건설재해예방 기술지도비 | C40: =SUM(D40:E40) -> 0 | D40: 0 | E40: 0
...

Sheet 3.예산대비_지출통계
A1: ■ 산업안전관리비 예산 대비 지출 현황
A2: ▶ 예산: [예산입력] 시트 참조 | 지출: [지출통계] 시트 참조 | 잔액·집행률 자동 계산 | 월별 지출은 [지출통계] 월별 합계 참조
A3: 본부 | B3: 항목 | C3: 연간예산 | D3: 누계지출 | E3: 잔액 | F3: 집행률 | G3: 월별 지출
G4: 1월 | H4: 2월 | I4: 3월 | J4: 4월 | K4: 5월 | L4: 6월 | M4: 7월 | N4: 8월 | O4: 9월 | P4: 10월 | Q4: 11월 | R4: 12월
A5: 본사 | B5: 안전관리자 등 인건비 | C5: ='2.예산입력'!C4 -> 0 | D5: ='1.지출통계'!O4 -> 0 | E5: =C5-D5 -> 0 | F5: =IF(C5=0,"-",TEXT(D5/C5,"0.0%")) -> - | G5: ='1.지출통계'!C4 -> 0 | H5: ='1.지출통계'!D4 -> 0 | I5: ='1.지출통계'!E4 -> 0 | J5: ='1.지출통계'!F4 -> 0 | K5: ='1.지출통계'!G4 -> 0 | L5: ='1.지출통계'!H4 -> 0 | M5: ='1.지출통계'!I4 -> 0 | N5: ='1.지출통계'!J4 -> 0 | ... R5: ='1.지출통계'!N4 -> 0
B6: 안전시설비 | C6: ='2.예산입력'!C5 -> 0 | D6: ='1.지출통계'!O5 -> 0 | E6: =C6-D6 -> 0 | F6: =IF(C6=0,"-",TEXT(D6/C6,"0.0%")) -> - | G6: ='1.지출통계'!C5 -> 0 | H6: ='1.지출통계'!D5 -> 0 | I6: ='1.지출통계'!E5 -> 0 | J6: ='1.지출통계'!F5 -> 0 | K6: ='1.지출통계'!G5 -> 0 | L6: ='1.지출통계'!H5 -> 0 | M6: ='1.지출통계'!I5 -> 0 | N6: ='1.지출통계'!J5 -> 0 | ... R6: ='1.지출통계'!N5 -> 0
B7: 보호구·안전용품 | C7: 0 | D7: ='1.지출통계'!O6 -> 0 | E7: =C7-D7 -> 0 | F7: =IF(C7=0,"-",TEXT(D7/C7,"0.0%")) -> - | G7: ='1.지출통계'!C6 -> 0 | H7: ='1.지출통계'!D6 -> 0 | I7: ='1.지출통계'!E6 -> 0 | J7: ='1.지출통계'!F6 -> 0 | K7: ='1.지출통계'!G6 -> 0 | L7: ='1.지출통계'!H6 -> 0 | M7: ='1.지출통계'!I6 -> 0 | N7: ='1.지출통계'!J6 -> 0 | ... R7: ='1.지출통계'!N6 -> 0
