Workbook

Sheet 월별현황
A1: ■ 월별 사용내역
A2: 본부 | B2: 항목 | C2: 합계 | D2: 1월 | E2: 2월 | F2: 3월 | G2: 4월 | H2: 5월 | I2: 6월 | J2: 7월 | K2: 8월 | L2: 9월 | M2: 10월 | N2: 11월 | O2: 12월
A3: 대구본부 | B3: 1. 안전관리자 등 인건비 및 각종 업무수당 등 | C3: =SUM(D3:O3) -> 10533600 | D3: ='1.~8.항목별 사용 세부내역'!D4+'1.~8.항목별 사용 세부내역'!D5 -> 2633400 | E3: ='1.~8.항목별 사용 세부내역'!F4+'1.~8.항목별 사용 세부내역'!F5 -> 2633400 | F3: ='1.~8.항목별 사용 세부내역'!H4+'1.~8.항목별 사용 세부내역'!H5 -> 2633400 | G3: ='1.~8.항목별 사용 세부내역'!J4+'1.~8.항목별 사용 세부내역'!J5 -> 2633400
B4: 2. 안전시설비 등 | C4: =SUM(D4:O4) -> 0
B5: 3. 개인보호구 및 안전장구 구입비 등 | C5: =SUM(D5:O5) -> 3348340 | E5: ='3. 개인보호구 및 용품구매 세부내역'!F59 -> 2430000 | F5: ='3. 개인보호구 및 용품구매 세부내역'!H59+'3. 개인보호구 및 용품구매 세부내역'!J59 -> 248240 | G5: ='3. 개인보호구 및 용품구매 세부내역'!L59+'3. 개인보호구 및 용품구매 세부내역'!P59 -> 670100
B6: 4. 안전진단비 등 | C6: =SUM(D6:O6) -> 0
B7: 5. 안전보건교육비 및 행사비 등 | C7: =SUM(E7:O7) -> 270000 | F7: ='1.~8.항목별 사용 세부내역'!H15 -> 120000 | G7: ='1.~8.항목별 사용 세부내역'!J15 -> 150000
B8: 6. 근로자 건강관리비 등 | C8: =SUM(D8:O8) -> 0
B9: 7. 건설재해예방 기술지도비 | C9: =SUM(D9:O9) -> 0
B10: 8. 본사사용비 | C10: =SUM(D10:O10) -> 0
B11: 9. 위험성평가 및 산보위 안건 비용 | C11: =SUM(D11:O11) -> 2622000 | G11: ='3. 개인보호구 및 용품구매 세부내역'!N59 -> 2622000
A12: 합계 | C12: =SUM(C3:C11) -> 16773940 | D12: =SUM(D3:D11) -> 2633400 | E12: =SUM(E3:E11) -> 5063400 | F12: =SUM(F3:F11) -> 3001640 | G12: =SUM(G3:G11) -> 6075500 | H12: =SUM(H3:H11) -> 0 | I12: =SUM(I3:I11) -> 0 | J12: =SUM(J3:J11) -> 0 | ... O12: =SUM(O3:O11) -> 0

Sheet 1.~8.항목별 사용 세부내역
A1: ■ 항목별 사용세부내역_지급일자 기준(지출결의서 기준 지급일자)
A2: 구분 | B2: 세부항목 | C2: 합계 | D2: 1월 | F2: 2월 | H2: 3월 | J2: 4월 | L2: 5월 | N2: 6월 | P2: 7월 | R2: 8월 | T2: 9월 | V2: 10월 | X2: 11월 | Z2: 12월 | AB2: 비고
D3: 지급금액 | E3: 지급일자 | F3: 지급금액 | G3: 지급일자 | H3: 지급금액 | I3: 지급일자 | J3: 지급금액 | K3: 지급일자 | L3: 지급금액 | M3: 지급일자 | N3: 지급금액 | O3: 지급일자 | P3: 지급금액 | Q3: 지급일자 | R3: 지급금액 | S3: 지급일자 | T3: 지급금액 | U3: 지급일자 | V3: 지급금액 | W3: 지급일자 | X3: 지급금액 | Y3: 지급일자 | Z3: 지급금액 | AA3: 지급일자
A4: 1. 안전관리자 등 인건비 및 각종 업무수당 등 | B4: 안전관리자 대행료(VAT제외) | C4: =D4+F4+H4+J4+L4+N4+P4+R4+T4+V4+X4+Z4 -> 5517600 | D4: 1379400 | E4: 26.01.23 | F4: 1379400 | G4: 26.02.10 | H4: 1379400 | I4: 26.03.10 | J4: 1379400 | K4: 26.04.10
B5: 보건관리자 대행료(VAT포함) | C5: =D5+F5+H5+J5+L5+N5+P5+R5+T5+V5+X5+Z5 -> 5016000 | D5: 1254000 | E5: 26.01.09 | F5: 1254000 | G5: 26.02.10 | H5: 1254000 | I5: 26.03.10 | J5: 1254000 | K5: 26.04.10
A6: 2. 안전시설비 등 | C6: =D6+F6+H6+J6+L6+N6+P6+R6+T6+V6+X6+Z6 -> 0
A7: 4. 안전진단비 등 | B7: SH등급 평가 갱신(VAT제외) | C7: =D7+F7+H7+J7+L7+N7+P7+R7+T7+V7+X7+Z7 -> 0
B8: ISO45001 사후심사(VAT제외) | C8: =D8+F8+H8+J8+L8+N8+P8+R8+T8+V8+X8+Z8 -> 0
B9: 작업환경 측정(VAT포함) | C9: =D9+F9+H9+J9+L9+N9+P9+R9+T9+V9+X9+Z9 -> 0
A10: 5. 안전보건교육비 및 행사비 등 | B10: 안전보건관리책임자 | C10: =D10+F10+H10+J10+L10+N10+P10+R10+T10+V10+X10+Z10 -> 0
B11: 관리감독자(VAT포함) | C11: =D11+F11+H11+J11+L11+N11+P11+R12+T11+V11+X11+Z11 -> 0
B12: 근로자(VAT포함) | C12: =D12+F12+H12+J12+L12+N12+P12+R12+T12+V12+X12+Z12 -> 0
B13: 법정필수교육 | C13: =D13+F13+H13+J13+L13+N13+P13+R13+T13+V13+X13+Z13 -> 0
B14: 관리감독자 집체교육 | C14: =D14+F14+H14+J14+L14+N14+P14+R14+T14+V14+X14+Z14 -> 0
B15: 안전관리 포상(재량보상) | C15: =D15+F15+H15+J15+L15+N15+P15+R15+T15+V15+X15+Z15 -> 270000 | H15: 120000 | I15: 26.03.16 | J15: 150000 | K15: 26.04.30
A16: 6. 근로자 건강관리비 등 | B16: 개인 건강검진(VAT포함) | C16: =D16+F16+H16+J16+L16+N16+P16+R16+T16+V16+X16+Z16 -> 0
A17: 7. 건설재해예방 기술지도비 | C17: =D17+F17+H17+J17+L17+N17+P17+R17+T17+V17+X17+Z17 -> 0
A18: 8. 본사사용비 | C18: =D18+F18+H18+J18+L18+N18+P18+R18+T18+V18+X18+Z18 -> 0
C19: =D19+F19+H19+J19+L19+N19+P19+R19+T19+V19+X19+Z19 -> 0

Sheet 3. 개인보호구 및 용품구매 세부내역
A1: □ 2026년 보호구 및 안전용품 구매내역(대구본부)
A2: 구분 | C2: 합계 | E2: 2월 | G2: 3월 | K2: 4월 | Q2: 비고
E3: 2025-02-24(화) | G3: 2025-03-16(월) | I3: 2025-03-31(화) | K3: 2025-04-13(월) | M3: 2025-04-14(화) | O3: 2025-04-21(화)
C4: 구매수량 | D4: 비용(vat제외) | E4: 수량 | F4: 비용 | G4: 수량 | H4: 비용 | I4: 수량 | J4: 비용 | K4: 수량 | L4: 비용 | M4: 수량 | N4: 비용 | O4: 수량 | P4: 비용
A5: 보호구 | B5: 안전모 | C5: =E5+G5+I5+K5+M5+O5 -> 0 | D5: =F5+H5+J5+L5+N5+P5 -> 0
B6: 일반안전화 | C6: =E6+G6+I6+K6+M6+O6 -> 1 | D6: =F6+H6+J6+L6+N6+P6 -> 104000 | O6: 1 | P6: 104000
B7: 입회용 안전모 | C7: =E7+G7+I7+K7+M7+O7 -> 0 | D7: =F7+H7+J7+L7+N7+P7 -> 0
B8: 실내안전화 | C8: =E8+G8+I8+K8+M8+O8 -> 0 | D8: =F8+H8+J8+L8+N8+P8 -> 0
B9: 방수장갑 | C9: =E9+G9+I9+K9+M9+O9 -> 0 | D9: =F9+H9+J9+L9+N9+P9 -> 0
B10: 안전장갑 | C10: =E10+G10+I10+K10+M10+O10 -> 0 | D10: =F10+H10+J10+L10+N10+P10 -> 0
B11: 신호수용 안전모 | C11: =E11+G11+I11+K11+M11+O11 -> 0 | D11: =F11+H11+J11+L11+N11+P11 -> 0
B12: 통풍형 안전모 | C12: =E12+G12+I12+K12+M12+O12 -> 0 | D12: =F12+H12+J12+L12+N12+P12 -> 0
B13: 안전화(4인치) | C13: =E13+G13+I13+K13+M13+O13 -> 1 | D13: =F13+H13+J13+L13+N13+P13 -> 158000 | I13: 1 | J13: 158000
B14: 보안경 | C14: =E14+G14+I14+K14+M14+O14 -> 0 | D14: =F14+H14+J14+L14+N14+P14 -> 0
B15: 보안경(안경) | C15: =E15+G15+I15+K15+M15+O15 -> 0 | D15: =F15+H15+J15+L15+N15+P15 -> 0
B16: 방진마스크 | C16: =E16+G16+I16+K16+M16+O16 -> 0 | D16: =F16+H16+J16+L16+N16+P16 -> 0
B17: 안전장화 | C17: =E17+G17+I17+K17+M17+O17 -> 0 | D17: =F17+H17+J17+L17+N17+P17 -> 0
B18: 방독마스크 | C18: =E18+G18+I18+K18+M18+O18 -> 0 | D18: =F18+H18+J18+L18+N18+P18 -> 0
B19: 안전모 턱끈 | C19: =E19+G19+I19+K19+M19+O19 -> 0 | D19: =F19+H19+J19+L19+N19+P19 -> 0
B20: 안전모 내피 | C20: =E20+G20+I20+K20+M20+O20 -> 0 | D20: =F20+H20+J20+L20+N20+P20 -> 0
A21: 안전용품 | B21: 검전기 | C21: =E21+G21+I21+K21+M21+O21 -> 0 | D21: =F21+H21+J21+L21+N21+P21 -> 0
B22: 활선경보기 | C22: =E22+G22+I22+K22+M22+O22 -> 1 | D22: =F22+H22+J22+L22+N22+P22 -> 29000 | I22: 1 | J22: 29000
B23: 쿨토시 | C23: =E23+G23+I23+K23+M23+O23 -> 0 | D23: =F23+H23+J23+L23+N23+P23 -> 0
B24: 핸드폰 거치대 | C24: =E24+G24+I24+K24+M24+O24 -> 114 | D24: =F24+H24+J24+L24+N24+P24 -> 2622000 | M24: 114 | N24: 2622000
B25: 벌퇴치 스프레이 | C25: =E25+G25+I25+K25+M25+O25 -> 111 | D25: =F25+H25+J25+L25+N25+P25 -> 566100 | K25: 111 | L25: 566100
B26: 살충제 | C26: =E26+G26+I26+K26+M26+O26 -> 0 | D26: =F26+H26+J26+L26+N26+P26 -> 0
B27: 검전기(최신) | C27: =E27+G27+I27+K27+M27+O27 -> 0 | D27: =F27+H27+J27+L27+N27+P27 -> 0
B28: 차량용소화기 | C28: =E28+G28+I28+K28+M28+O28 -> 0 | D28: =F28+H28+J28+L28+N28+P28 -> 0
B29: 고임목(소형) | C29: =E29+G29+I29+K29+M29+O29 -> 4 | D29: =F29+H29+J29+L29+N29+P29 -> 23640 | G29: 4 | H29: 23640
B30: 고임목(중형) | C30: =E30+G30+I30+K30+M30+O30 -> 4 | D30: =F30+H30+J30+L30+N30+P30 -> 37600 | G30: 4 | H30: 37600
B31: 안전블록 | C31: =E31+G31+I31+K31+M31+O31 -> 0 | D31: =F31+H31+J31+L31+N31+P31 -> 0
B32: 수동구조용 삼각대 | C32: =E32+G32+I32+K32+M32+O32 -> 0 | D32: =F32+H32+J32+L32+N32+P32 -> 0
B33: 방독필터 | C33: =E33+G33+I33+K33+M33+O33 -> 0 | D33: =F33+H33+J33+L33+N33+P33 -> 0
B34: 방한마스크 | C34: =E34+G34+I34+K34+M34+O34 -> 0 | D34: =F34+H34+J34+L34+N34+P34 -> 0
B35: 넥워머 | C35: =E35+G35+I35+K35+M35+O35 -> 0 | D35: =F35+H35+J35+L35+N35+P35 -> 0
B36: 배풍기 | C36: =E36+G36+I36+K36+M36+O36 -> 0 | D36: =F36+H36+J36+L36+N36+P36 -> 0
B37: 핫팩 | C37: =E37+G37+I37+K37+M37+O37 -> 0 | D37: =F37+H37+J37+L37+N37+P37 -> 0
B38: 냉동고 | C38: =E38+G38+I38+K38+M38+O38 -> 0 | D38: =F38+H38+J38+L38+N38+P38 -> 0
B39: 위험물보관함 | C39: =E39+G39+I39+K39+M39+O39 -> 0 | D39: =F39+H39+J39+L39+N39+P39 -> 0
B40: 식염포도당 | C40: =E40+G40+I40+K40+M40+O40 -> 0 | D40: =F40+H40+J40+L40+N40+P40 -> 0
...
