Workbook

Sheet 대구본부(F)
A1: 대구본부 업무용 차량 유류비 사용 추이
A4: 유가정보 | B4: 유종별 평균가격 | C4: 1월 | D4: 2월 | E4: 3월 | F4: 4월 | G4: 5월 | H4: 6월 | I4: 7월 | J4: 8월 | K4: 9월 | L4: 10월 | M4: 11월 | N4: 12월 | O4: 비고
B5: 24년 휘발유 평균가격 | C5: 1569.25 | D5: 1614.51 | E5: 1639.1 | F5: 1687.79 | G5: 1697.47 | H5: 1657.37 | I5: 1707.13 | J5: 1691.28 | K5: 1622.2 | L5: 1591.34 | M5: 1628.29 | N5: 1653.64
B6: 25년 휘발유 평균가격 | C6: 1708.528 | D6: 1728.2596 | E6: 1688.9252 | F6: 1646.69 | G6: 1636.4429 | H6: 1642.084 | I6: 1667.5768 | J6: 1665.9094 | K6: - | L6: - | M6: - | N6: -
B7: 전년대비 증감비용 | C7: =C6-C5 -> 139.278 | D7: =D6-D5 -> 113.74964 | E7: =E6-E5 -> 49.825161 | F7: =F6-F5 -> -41.1 | G7: =G6-G5 -> -61.027097 | H7: =H6-H5 -> -15.286 | I7: =I6-I5 -> -39.553226 | J7: =J6-J5 -> -25.370645 | ... M7: =M6-M5 -> #VALUE! | N7: -
B8: 24년 경유 평균가격 | C8: 1480.07 | D8: 1517.75 | E8: 1538.97 | F8: 1557.77 | G8: 1539.59 | H8: 1487.36 | I8: 1542.46 | J8: 1528.85 | K8: 1458.22 | L8: 1421.44 | M8: 1461.04 | N8: 1497.25
B9: 25년 경유 평균가격 | C9: 1563.59 | D9: 1594.0139 | E9: 1555.0313 | F9: 1513.2103 | G9: 1502.1461 | H9: 1505.4363 | I9: 1531.5497 | J9: 1535.7429 | K9: - | L9: - | M9: - | N9: -
B10: 전년대비 증감비용 | C10: =C9-C8 -> 83.52 | D10: =D9-D8 -> 76.263929 | E10: =E9-E8 -> 16.06129 | F10: =F9-F8 -> -44.559667 | G10: =G9-G8 -> -37.443871 | H10: =H9-H8 -> 18.076333 | I10: =I9-I8 -> -10.910323 | J10: =J9-J8 -> 6.8929032 | ... M10: =M9-M8 -> #VALUE! | N10: -
A12: 유류비 추이 | B12: 유류비(원) | C12: 1월 | D12: 2월 | E12: 3월 | F12: 4월 | G12: 5월 | H12: 6월 | I12: 7월 | J12: 8월 | K12: 9월 | L12: 10월 | M12: 11월 | N12: 12월 | O12: 합계
B13: 24년 유류비 | C13: ='24년 1월'!M364 -> 26007285 | D13: ='24년 2월'!M361 -> 23750488 | E13: ='24년 3월'!M365 -> 25807555 | F13: ='24년 4월'!M359 -> 25479889 | G13: ='24년 5월'!M359 -> 26892799 | H13: ='24년 6월'!M356 -> 24934788 | I13: ='24년 7월'!M356 -> 31678997 | J13: ='24년 8월'!M381 -> 27914670 | K13: ='24년 9월'!M357 -> 22160555 | L13: ='24년 10월'!M357 -> 21949989 | M13: ='24년 11월'!M358 -> 20506508 | N13: ='24년 12월'!M357 -> 21911519 | O13: =SUM(C13:N13) -> 298995042
B14: 25년 유류비 | C14: =SUMIFS('25년 1월'!$M:$M,'25년 1월'!$C:$C,"대구본부") -> 20083108 | D14: =SUMIFS('25년 2월'!$M:$M,'25년 2월'!$C:$C,"대구본부") -> 24804772 | E14: =SUMIFS('25년 3월'!$M:$M,'25년 3월'!$C:$C,"대구본부") -> 25654882 | F14: =SUMIFS('25년 4월'!$M:$M,'25년 4월'!$C:$C,"대구본부") -> 26463113 | G14: =SUMIFS('25년 5월'!$M:$M,'25년 5월'!$C:$C,"대구본부") -> 22739833 | H14: =SUMIFS('25년 6월'!$M:$M,'25년 6월'!$C:$C,"대구본부") -> 24765125 | I14: =SUMIFS('25년 7월'!$M:$M,'25년 7월'!$C:$C,"대구본부") -> 37192081 | J14: =SUMIFS('25년 8월'!$M:$M,'25년 8월'!$C:$C,"대구본부") -> 33145274 | K14: =SUMIFS('25년 9월'!$M:$M,'25년 9월'!$C:$C,"대구본부") -> 33611150 | L14: =SUMIFS('25년 10월'!$M:$M,'25년 10월'!$C:$C,"대구본부") -> 28683813 | M14: =SUMIFS('25년 11월'!$M:$M,'25년 11월'!$C:$C,"대구본부") -> 27113280 | N14: =SUMIFS('25년 12월'!$M:$M,'25년 12월'!$C:$C,"대구본부") -> 28276434 | O14: =SUM(C14:N14) -> 332532865
B15: 전년대비 증감비용 | C15: =C13-C14 -> 5924177 | D15: =D13-D14 -> -1054284 | E15: =E13-E14 -> 152673 | F15: =F13-F14 -> -983224 | G15: =G13-G14 -> 4152966 | H15: =H13-H14 -> 169663 | I15: =I13-I14 -> -5513084 | J15: =J13-J14 -> -5230604 | ... N15: =N13-N14 -> -6364915 | O15: =SUM(C15:N15) -> -33537823
A17: 주행거리 추이 | B17: 총주행거리(km) | C17: 1월 | D17: 2월 | E17: 3월 | F17: 4월 | G17: 5월 | H17: 6월 | I17: 7월 | J17: 8월 | K17: 9월 | L17: 10월 | M17: 11월 | N17: 12월 | O17: 합계
B18: 24년 총주행거리 | C18: =SUMIFS('24년 1월'!$K:$K,'24년 1월'!$C:$C,"대구본부") -> 250386 | D18: =SUMIFS('24년 2월'!$K:$K,'24년 2월'!$C:$C,"대구본부") -> 222091 | E18: =SUMIFS('24년 3월'!$K:$K,'24년 3월'!$C:$C,"대구본부") -> 239023 | F18: =SUMIFS('24년 4월'!$K:$K,'24년 4월'!$C:$C,"대구본부") -> 241165 | G18: =SUMIFS('24년 5월'!$K:$K,'24년 5월'!$C:$C,"대구본부") -> 242634 | H18: =SUMIFS('24년 6월'!$K:$K,'24년 6월'!$C:$C,"대구본부") -> 222218 | I18: =SUMIFS('24년 7월'!$K:$K,'24년 7월'!$C:$C,"대구본부") -> 266937 | J18: =SUMIFS('24년 8월'!$K:$K,'24년 8월'!$C:$C,"대구본부") -> 233814 | K18: =SUMIFS('24년 9월'!$K:$K,'24년 9월'!$C:$C,"대구본부") -> 210131 | L18: =SUMIFS('24년 10월'!$K:$K,'24년 10월'!$C:$C,"대구본부") -> 221342 | M18: =SUMIFS('24년 11월'!$K:$K,'24년 11월'!$C:$C,"대구본부") -> 205845 | N18: =SUMIFS('24년 12월'!$K:$K,'24년 12월'!$C:$C,"대구본부") -> 197414 | O18: =SUM(C18:N18) -> 2753000
B19: 25년 총주행거리 | C19: =SUMIFS('25년 1월'!$K:$K,'25년 1월'!$C:$C,"대구본부") -> 181481 | D19: =SUMIFS('25년 2월'!$K:$K,'25년 2월'!$C:$C,"대구본부") -> 211941 | E19: =SUMIFS('25년 3월'!$K:$K,'25년 3월'!$C:$C,"대구본부") -> 247369 | F19: =SUMIFS('25년 4월'!$K:$K,'25년 4월'!$C:$C,"대구본부") -> 248953 | G19: =SUMIFS('25년 5월'!$K:$K,'25년 5월'!$C:$C,"대구본부") -> 219129 | H19: =SUMIFS('25년 6월'!$K:$K,'25년 6월'!$C:$C,"대구본부") -> 227896 | I19: =SUMIFS('25년 7월'!$K:$K,'25년 7월'!$C:$C,"대구본부") -> 273699 | J19: =SUMIFS('25년 8월'!$K:$K,'25년 8월'!$C:$C,"대구본부") -> 228192 | K19: =SUMIFS('25년 9월'!$K:$K,'25년 9월'!$C:$C,"대구본부") -> 251773 | L19: =SUMIFS('25년 10월'!$K:$K,'25년 10월'!$C:$C,"대구본부") -> 217816 | M19: =SUMIFS('25년 11월'!$K:$K,'25년 11월'!$C:$C,"대구본부") -> 208450 | N19: =SUMIFS('25년 12월'!$K:$K,'25년 12월'!$C:$C,"대구본부") -> 198276 | O19: =SUM(C19:N19) -> 2714975
B20: 전년대비 증감비용 | C20: =C18-C19 -> 68905 | D20: =D18-D19 -> 10150 | E20: =E18-E19 -> -8346 | F20: =F18-F19 -> -7788 | G20: =G18-G19 -> 23505 | H20: =H18-H19 -> -5678 | I20: =I18-I19 -> -6762 | J20: =J18-J19 -> 5622 | ... N20: =N18-N19 -> -862 | O20: =SUM(C20:N20) -> 38025

Sheet 운용팀별(F)
A1: 동대구운용팀 | AG1: 원인분석
A4: 구분 | B4: 24년 | E4: 25년
B5: 경유 유류비 | C5: 휘발유 유류비 | D5: EV 유류비 | E5: 경유 유류비 | F5: 휘발유 유류비 | G5: EV 유류비 | I5: 구분 | J5: 24년 유류비 | K5: 25년 유류비 | L5: 증감비용 | N5: 24년 주행거리 | O5: 25년 주행거리 | P5: 증감거리
A6: 1월 | B6: =SUMIFS('24년 1월'!$M:$M,'24년 1월'!$C:$C,"동대구운용팀",'24년 1월'!$I:$I,"경유") -> 2563000 | C6: =SUMIFS('24년 4월'!$M:$M,'24년 4월'!$C:$C,"동대구운용팀",'24년 4월'!$I:$I,"휘발유") -> 2002525 | D6: =SUMIFS('24년 4월'!$M:$M,'24년 4월'!$C:$C,"동대구운용팀",'24년 4월'!$I:$I,"EV") -> 0 | E6: =SUMIFS('25년 1월'!$M:$M,'25년 1월'!$C:$C,"동대구운용팀",'25년 1월'!$I:$I,"경유") -> 2694000 | F6: =SUMIFS('25년 4월'!$M:$M,'25년 4월'!$C:$C,"동대구운용팀",'25년 4월'!$I:$I,"휘발유") -> 3535671 | G6: =SUMIFS('25년 4월'!$M:$M,'25년 4월'!$C:$C,"동대구운용팀",'25년 4월'!$I:$I,"EV") -> 0 | I6: 1월 | J6: =B6+C6+D6 -> 4565525 | K6: =E6+F6+G6 -> 6229671 | L6: =K6-J6 -> 1664146 | N6: =SUMIFS('24년 4월'!$K:$K,'24년 4월'!$B:$B,"소계",'24년 4월'!$C:$C,"동대구운용팀") -> 46650 | O6: =SUMIFS('25년 4월'!$K:$K,'25년 4월'!$B:$B,"소계",'25년 4월'!$C:$C,"동대구운용팀") -> 49016 | P6: =O6-N6 -> 2366
A7: 2월 | B7: =SUMIFS('24년 2월'!$M:$M,'24년 2월'!$C:$C,"동대구운용팀",'24년 2월'!$I:$I,"경유") -> 2225000 | C7: =SUMIFS('24년 2월'!$M:$M,'24년 2월'!$C:$C,"동대구운용팀",'24년 2월'!$I:$I,"휘발유") -> 1688000 | D7: =SUMIFS('24년 2월'!$M:$M,'24년 2월'!$C:$C,"동대구운용팀",'24년 2월'!$I:$I,"EV") -> 0 | E7: =SUMIFS('25년 2월'!$M:$M,'25년 2월'!$C:$C,"동대구운용팀",'25년 2월'!$I:$I,"경유") -> 2808000 | F7: =SUMIFS('25년 2월'!$M:$M,'25년 2월'!$C:$C,"동대구운용팀",'25년 2월'!$I:$I,"휘발유") -> 3210933 | G7: =SUMIFS('25년 2월'!$M:$M,'25년 2월'!$C:$C,"동대구운용팀",'25년 2월'!$I:$I,"EV") -> 0 | I7: 2월 | J7: =B7+C7+D7 -> 3913000 | K7: =E7+F7+G7 -> 6018933 | L7: =K7-J7 -> 2105933 | N7: =SUMIFS('24년 2월'!$K:$K,'24년 2월'!$B:$B,"소계",'24년 2월'!$C:$C,"동대구운용팀") -> 40563 | O7: =SUMIFS('25년 2월'!$K:$K,'25년 2월'!$B:$B,"소계",'25년 2월'!$C:$C,"동대구운용팀") -> 41653 | P7: =O7-N7 -> 1090
A8: 3월 | B8: =SUMIFS('24년 3월'!$M:$M,'24년 3월'!$C:$C,"동대구운용팀",'24년 3월'!$I:$I,"경유") -> 2444399 | C8: =SUMIFS('24년 3월'!$M:$M,'24년 3월'!$C:$C,"동대구운용팀",'24년 3월'!$I:$I,"휘발유") -> 1788000 | D8: =SUMIFS('24년 3월'!$M:$M,'24년 3월'!$C:$C,"동대구운용팀",'24년 3월'!$I:$I,"EV") -> 0 | E8: =SUMIFS('25년 3월'!$M:$M,'25년 3월'!$C:$C,"동대구운용팀",'25년 3월'!$I:$I,"경유") -> 3338000 | F8: =SUMIFS('25년 3월'!$M:$M,'25년 3월'!$C:$C,"동대구운용팀",'25년 3월'!$I:$I,"휘발유") -> 3209292 | G8: =SUMIFS('25년 3월'!$M:$M,'25년 3월'!$C:$C,"동대구운용팀",'25년 3월'!$I:$I,"EV") -> 0 | I8: 3월 | J8: =B8+C8+D8 -> 4232399 | K8: =E8+F8+G8 -> 6547292 | L8: =K8-J8 -> 2314893 | N8: =SUMIFS('24년 3월'!$K:$K,'24년 3월'!$B:$B,"소계",'24년 3월'!$C:$C,"동대구운용팀") -> 44746 | O8: =SUMIFS('25년 3월'!$K:$K,'25년 3월'!$B:$B,"소계",'25년 3월'!$C:$C,"동대구운용팀") -> 48092 | P8: =O8-N8 -> 3346
A9: 4월 | B9: =SUMIFS('24년 4월'!$M:$M,'24년 4월'!$C:$C,"동대구운용팀",'24년 4월'!$I:$I,"경유") -> 2452000 | C9: =SUMIFS('24년 4월'!$M:$M,'24년 4월'!$C:$C,"동대구운용팀",'24년 4월'!$I:$I,"휘발유") -> 2002525 | D9: =SUMIFS('24년 4월'!$M:$M,'24년 4월'!$C:$C,"동대구운용팀",'24년 4월'!$I:$I,"EV") -> 0 | E9: =SUMIFS('25년 4월'!$M:$M,'25년 4월'!$C:$C,"동대구운용팀",'25년 4월'!$I:$I,"경유") -> 2997000 | F9: =SUMIFS('25년 4월'!$M:$M,'25년 4월'!$C:$C,"동대구운용팀",'25년 4월'!$I:$I,"휘발유") -> 3535671 | G9: =SUMIFS('25년 4월'!$M:$M,'25년 4월'!$C:$C,"동대구운용팀",'25년 4월'!$I:$I,"EV") -> 0 | I9: 4월 | J9: =B9+C9+D9 -> 4454525 | K9: =E9+F9+G9 -> 6532671 | L9: =K9-J9 -> 2078146 | N9: =SUMIFS('24년 4월'!$K:$K,'24년 4월'!$B:$B,"소계",'24년 4월'!$C:$C,"동대구운용팀") -> 46650 | O9: =SUMIFS('25년 4월'!$K:$K,'25년 4월'!$B:$B,"소계",'25년 4월'!$C:$C,"동대구운용팀") -> 49016 | P9: =O9-N9 -> 2366
A10: 5월 | B10: =SUMIFS('24년 5월'!$M:$M,'24년 5월'!$C:$C,"동대구운용팀",'24년 5월'!$I:$I,"경유") -> 2703000 | C10: =SUMIFS('24년 5월'!$M:$M,'24년 5월'!$C:$C,"동대구운용팀",'24년 5월'!$I:$I,"휘발유") -> 1866000 | D10: =SUMIFS('24년 5월'!$M:$M,'24년 5월'!$C:$C,"동대구운용팀",'24년 5월'!$I:$I,"EV") -> 11560 | E10: =SUMIFS('25년 5월'!$M:$M,'25년 5월'!$C:$C,"동대구운용팀",'25년 5월'!$I:$I,"경유") -> 2830000 | F10: =SUMIFS('25년 5월'!$M:$M,'25년 5월'!$C:$C,"동대구운용팀",'25년 5월'!$I:$I,"휘발유") -> 3203980 | G10: =SUMIFS('25년 5월'!$M:$M,'25년 5월'!$C:$C,"동대구운용팀",'25년 5월'!$I:$I,"EV") -> 0 | I10: 5월 | J10: =B10+C10+D10 -> 4580560 | K10: =E10+F10+G10 -> 6033980 | L10: =K10-J10 -> 1453420 | N10: =SUMIFS('24년 5월'!$K:$K,'24년 5월'!$B:$B,"소계",'24년 5월'!$C:$C,"동대구운용팀") -> 44950 | O10: =SUMIFS('25년 5월'!$K:$K,'25년 5월'!$B:$B,"소계",'25년 5월'!$C:$C,"동대구운용팀") -> 44070 | P10: =O10-N10 -> -880
A11: 6월 | B11: =SUMIFS('24년 6월'!$M:$M,'24년 6월'!$C:$C,"동대구운용팀",'24년 6월'!$I:$I,"경유") -> 2425000 | C11: =SUMIFS('24년 6월'!$M:$M,'24년 6월'!$C:$C,"동대구운용팀",'24년 6월'!$I:$I,"휘발유") -> 1674000 | D11: =SUMIFS('24년 6월'!$M:$M,'24년 6월'!$C:$C,"동대구운용팀",'24년 6월'!$I:$I,"EV") -> 212502 | E11: =SUMIFS('25년 6월'!$M:$M,'25년 6월'!$C:$C,"동대구운용팀",'25년 6월'!$I:$I,"경유") -> 3008000 | F11: =SUMIFS('25년 6월'!$M:$M,'25년 6월'!$C:$C,"동대구운용팀",'25년 6월'!$I:$I,"휘발유") -> 3503000 | G11: =SUMIFS('25년 6월'!$M:$M,'25년 6월'!$C:$C,"동대구운용팀",'25년 6월'!$I:$I,"EV") -> 0 | I11: 6월 | J11: =B11+C11+D11 -> 4311502 | K11: =E11+F11+G11 -> 6511000 | L11: =K11-J11 -> 2199498 | N11: =SUMIFS('24년 6월'!$K:$K,'24년 6월'!$B:$B,"소계",'24년 6월'!$C:$C,"동대구운용팀") -> 41817 | O11: =SUMIFS('25년 6월'!$K:$K,'25년 6월'!$B:$B,"소계",'25년 6월'!$C:$C,"동대구운용팀") -> 43719 | P11: =O11-N11 -> 1902
A12: 7월 | B12: =SUMIFS('24년 7월'!$M:$M,'24년 7월'!$C:$C,"동대구운용팀",'24년 7월'!$I:$I,"경유") -> 3445000 | C12: =SUMIFS('24년 7월'!$M:$M,'24년 7월'!$C:$C,"동대구운용팀",'24년 7월'!$I:$I,"휘발유") -> 1886000 | D12: =SUMIFS('24년 7월'!$M:$M,'24년 7월'!$C:$C,"동대구운용팀",'24년 7월'!$I:$I,"EV") -> 324904 | E12: =SUMIFS('25년 7월'!$M:$M,'25년 7월'!$C:$C,"동대구운용팀",'25년 7월'!$I:$I,"경유") -> 3460000 | F12: =SUMIFS('25년 7월'!$M:$M,'25년 7월'!$C:$C,"동대구운용팀",'25년 7월'!$I:$I,"휘발유") -> 5020255 | G12: =SUMIFS('25년 7월'!$M:$M,'25년 7월'!$C:$C,"동대구운용팀",'25년 7월'!$I:$I,"EV") -> 0 | I12: 7월 | J12: =B12+C12+D12 -> 5655904 | K12: =E12+F12+G12 -> 8480255 | L12: =K12-J12 -> 2824351 | N12: =SUMIFS('24년 7월'!$K:$K,'24년 7월'!$B:$B,"소계",'24년 7월'!$C:$C,"동대구운용팀") -> 49299 | O12: =SUMIFS('25년 7월'!$K:$K,'25년 7월'!$B:$B,"소계",'25년 7월'!$C:$C,"동대구운용팀") -> 54803 | P12: =O12-N12 -> 5504
A13: 8월 | B13: =SUMIFS('24년 8월'!$M:$M,'24년 8월'!$C:$C,"동대구운용팀",'24년 8월'!$I:$I,"경유") -> 3009000 | C13: =SUMIFS('24년 8월'!$M:$M,'24년 8월'!$C:$C,"동대구운용팀",'24년 8월'!$I:$I,"휘발유") -> 1864000 | D13: =SUMIFS('24년 8월'!$M:$M,'24년 8월'!$C:$C,"동대구운용팀",'24년 8월'!$I:$I,"EV") -> 324268 | E13: =SUMIFS('25년 8월'!$M:$M,'25년 8월'!$C:$C,"동대구운용팀",'25년 8월'!$I:$I,"경유") -> 2991000 | F13: =SUMIFS('25년 8월'!$M:$M,'25년 8월'!$C:$C,"동대구운용팀",'25년 8월'!$I:$I,"휘발유") -> 4198985 | G13: =SUMIFS('25년 8월'!$M:$M,'25년 8월'!$C:$C,"동대구운용팀",'25년 8월'!$I:$I,"EV") -> 0 | I13: 8월 | J13: =B13+C13+D13 -> 5197268 | K13: =E13+F13+G13 -> 7189985 | L13: =K13-J13 -> 1992717 | N13: =SUMIFS('24년 8월'!$K:$K,'24년 8월'!$B:$B,"소계",'24년 8월'!$C:$C,"동대구운용팀") -> 43963 | O13: =SUMIFS('25년 8월'!$K:$K,'25년 8월'!$B:$B,"소계",'25년 8월'!$C:$C,"동대구운용팀") -> 46778 | P13: =O13-N13 -> 2815
A14: 9월 | B14: =SUMIFS('24년 9월'!$M:$M,'24년 9월'!$C:$C,"동대구운용팀",'24년 9월'!$I:$I,"경유") -> 2730000 | C14: =SUMIFS('24년 9월'!$M:$M,'24년 9월'!$C:$C,"동대구운용팀",'24년 9월'!$I:$I,"휘발유") -> 2704000 | D14: =SUMIFS('24년 9월'!$M:$M,'24년 9월'!$C:$C,"동대구운용팀",'24년 9월'!$I:$I,"EV") -> 0 | E14: =SUMIFS('25년 9월'!$M:$M,'25년 9월'!$C:$C,"동대구운용팀",'25년 9월'!$I:$I,"경유") -> 2685000 | F14: =SUMIFS('25년 9월'!$M:$M,'25년 9월'!$C:$C,"동대구운용팀",'25년 9월'!$I:$I,"휘발유") -> 4452028 | G14: =SUMIFS('25년 9월'!$M:$M,'25년 9월'!$C:$C,"동대구운용팀",'25년 9월'!$I:$I,"EV") -> 0 | I14: 9월 | J14: =B14+C14+D14 -> 5434000 | K14: =E14+F14+G14 -> 7137028 | L14: =K14-J14 -> 1703028 | N14: =SUMIFS('24년 9월'!$K:$K,'24년 9월'!$B:$B,"소계",'24년 9월'!$C:$C,"동대구운용팀") -> 41310 | O14: =SUMIFS('25년 9월'!$K:$K,'25년 9월'!$B:$B,"소계",'25년 9월'!$C:$C,"동대구운용팀") -> 49797 | P14: =O14-N14 -> 8487
A15: 10월 | B15: =SUMIFS('24년 10월'!$M:$M,'24년 10월'!$C:$C,"동대구운용팀",'24년 10월'!$I:$I,"경유") -> 2591000 | C15: =SUMIFS('24년 10월'!$M:$M,'24년 10월'!$C:$C,"동대구운용팀",'24년 10월'!$I:$I,"휘발유") -> 2211609 | D15: =SUMIFS('24년 10월'!$M:$M,'24년 10월'!$C:$C,"동대구운용팀",'24년 10월'!$I:$I,"EV") -> 0 | E15: =SUMIFS('25년 10월'!$M:$M,'25년 10월'!$C:$C,"동대구운용팀",'25년 10월'!$I:$I,"경유") -> 2708000 | F15: =SUMIFS('25년 10월'!$M:$M,'25년 10월'!$C:$C,"동대구운용팀",'25년 10월'!$I:$I,"휘발유") -> 3636168 | G15: =SUMIFS('25년 10월'!$M:$M,'25년 10월'!$C:$C,"동대구운용팀",'25년 10월'!$I:$I,"EV") -> 0 | I15: 10월 | J15: =B15+C15+D15 -> 4802609 | K15: =E15+F15+G15 -> 6344168 | L15: =K15-J15 -> 1541559 | N15: =SUMIFS('24년 10월'!$K:$K,'24년 10월'!$B:$B,"소계",'24년 10월'!$C:$C,"동대구운용팀") -> 41249 | O15: =SUMIFS('25년 10월'!$K:$K,'25년 10월'!$B:$B,"소계",'25년 10월'!$C:$C,"동대구운용팀") -> 43692 | P15: =O15-N15 -> 2443
A16: 11월 | B16: =SUMIFS('24년 11월'!$M:$M,'24년 11월'!$C:$C,"동대구운용팀",'24년 11월'!$I:$I,"경유") -> 2574875 | C16: =SUMIFS('24년 11월'!$M:$M,'24년 11월'!$C:$C,"동대구운용팀",'24년 11월'!$I:$I,"휘발유") -> 2221198 | D16: =SUMIFS('24년 11월'!$M:$M,'24년 11월'!$C:$C,"동대구운용팀",'24년 11월'!$I:$I,"EV") -> 0 | E16: =SUMIFS('25년 11월'!$M:$M,'25년 11월'!$C:$C,"동대구운용팀",'25년 11월'!$I:$I,"경유") -> 2499000 | F16: =SUMIFS('25년 11월'!$M:$M,'25년 11월'!$C:$C,"동대구운용팀",'25년 11월'!$I:$I,"휘발유") -> 3313879 | G16: =SUMIFS('25년 11월'!$M:$M,'25년 11월'!$C:$C,"동대구운용팀",'25년 11월'!$I:$I,"EV") -> 0 | I16: 11월 | J16: =B16+C16+D16 -> 4796073 | K16: =E16+F16+G16 -> 5812879 | L16: =K16-J16 -> 1016806 | N16: =SUMIFS('24년 11월'!$K:$K,'24년 11월'!$B:$B,"소계",'24년 11월'!$C:$C,"동대구운용팀") -> 37873 | O16: =SUMIFS('25년 11월'!$K:$K,'25년 11월'!$B:$B,"소계",'25년 11월'!$C:$C,"동대구운용팀") -> 40462 | P16: =O16-N16 -> 2589
A17: 12월 | B17: =SUMIFS('24년 12월'!$M:$M,'24년 12월'!$C:$C,"동대구운용팀",'24년 12월'!$I:$I,"경유") -> 2650000 | C17: =SUMIFS('24년 12월'!$M:$M,'24년 12월'!$C:$C,"동대구운용팀",'24년 12월'!$I:$I,"휘발유") -> 2384606 | D17: =SUMIFS('24년 12월'!$M:$M,'24년 12월'!$C:$C,"동대구운용팀",'24년 12월'!$I:$I,"EV") -> 0 | E17: =SUMIFS('25년 12월'!$M:$M,'25년 12월'!$C:$C,"동대구운용팀",'25년 12월'!$I:$I,"경유") -> 2992000 | F17: =SUMIFS('25년 12월'!$M:$M,'25년 12월'!$C:$C,"동대구운용팀",'25년 12월'!$I:$I,"휘발유") -> 3457595 | G17: =SUMIFS('25년 12월'!$M:$M,'25년 12월'!$C:$C,"동대구운용팀",'25년 12월'!$I:$I,"EV") -> 0 | I17: 12월 | J17: =B17+C17+D17 -> 5034606 | K17: =E17+F17+G17 -> 6449595 | L17: =K17-J17 -> 1414989 | N17: =SUMIFS('24년 12월'!$K:$K,'24년 12월'!$B:$B,"소계",'24년 12월'!$C:$C,"동대구운용팀") -> 38888 | O17: =SUMIFS('25년 12월'!$K:$K,'25년 12월'!$B:$B,"소계",'25년 12월'!$C:$C,"동대구운용팀") -> 40966 | P17: =O17-N17 -> 2078
A18: 합계 | B18: =SUM(B6:B17) -> 31812274 | C18: =SUM(C6:C17) -> 24292463 | D18: =SUM(D6:D17) -> 873234 | E18: =SUM(E6:E17) -> 35010000 | F18: =SUM(F6:F17) -> 44277457 | G18: =SUM(G6:G17) -> 0 | P18: =SUM(P6:P17) -> 34106
A20: 서대구운용팀 | AG20: 원인분석
A24: 구분 | B24: 24년 | E24: 25년
B25: 경유 유류비 | C25: 휘발유 유류비 | D25: EV 유류비 | E25: 경유 유류비 | F25: 휘발유 유류비 | G25: EV 유류비 | I25: 구분 | J25: 24년 유류비 | K25: 25년 유류비 | L25: 증감비용 | N25: 24년 주행거리 | O25: 25년 주행거리 | P25: 증감거리
A26: 1월 | B26: =SUMIFS('24년 1월'!$M:$M,'24년 1월'!$C:$C,"서대구운용팀",'24년 1월'!$I:$I,"경유") -> 904000 | C26: =SUMIFS('24년 1월'!$M:$M,'24년 1월'!$C:$C,"서대구운용팀",'24년 1월'!$I:$I,"휘발유") -> 1181000 | D26: =SUMIFS('24년 1월'!$M:$M,'24년 1월'!$C:$C,"서대구운용팀",'24년 1월'!$I:$I,"EV") -> 0 | E26: =SUMIFS('25년 1월'!$M:$M,'25년 1월'!$C:$C,"서대구운용팀",'25년 1월'!$I:$I,"경유") -> 1047000 | F26: =SUMIFS('25년 1월'!$M:$M,'25년 1월'!$C:$C,"서대구운용팀",'25년 1월'!$I:$I,"휘발유") -> 1697000 | G26: =SUMIFS('25년 1월'!$M:$M,'25년 1월'!$C:$C,"서대구운용팀",'25년 1월'!$I:$I,"EV") -> 0 | I26: 1월 | J26: =B26+C26+D26 -> 2085000 | K26: =E26+F26+G26 -> 2744000 | L26: =K26-J26 -> 659000 | N26: =SUMIFS('24년 4월'!$K:$K,'24년 4월'!$B:$B,"소계",'24년 4월'!$C:$C,"서대구운용팀") -> 24287 | O26: =SUMIFS('25년 4월'!$K:$K,'25년 4월'!$B:$B,"소계",'25년 4월'!$C:$C,"서대구운용팀") -> 24887 | P26: =O26-N26 -> 600
A27: 2월 | B27: =SUMIFS('24년 2월'!$M:$M,'24년 2월'!$C:$C,"서대구운용팀",'24년 2월'!$I:$I,"경유") -> 1125000 | C27: =SUMIFS('24년 2월'!$M:$M,'24년 2월'!$C:$C,"서대구운용팀",'24년 2월'!$I:$I,"휘발유") -> 956462 | D27: =SUMIFS('24년 2월'!$M:$M,'24년 2월'!$C:$C,"서대구운용팀",'24년 2월'!$I:$I,"EV") -> 23845 | E27: =SUMIFS('25년 2월'!$M:$M,'25년 2월'!$C:$C,"서대구운용팀",'25년 2월'!$I:$I,"경유") -> 1340000 | F27: =SUMIFS('25년 2월'!$M:$M,'25년 2월'!$C:$C,"서대구운용팀",'25년 2월'!$I:$I,"휘발유") -> 1808915 | G27: =SUMIFS('25년 2월'!$M:$M,'25년 2월'!$C:$C,"서대구운용팀",'25년 2월'!$I:$I,"EV") -> 0 | I27: 2월 | J27: =B27+C27+D27 -> 2105307 | K27: =E27+F27+G27 -> 3148915 | L27: =K27-J27 -> 1043608 | N27: =SUMIFS('24년 2월'!$K:$K,'24년 2월'!$B:$B,"소계",'24년 2월'!$C:$C,"서대구운용팀") -> 22765 | O27: =SUMIFS('25년 2월'!$K:$K,'25년 2월'!$B:$B,"소계",'25년 2월'!$C:$C,"서대구운용팀") -> 19871 | P27: =O27-N27 -> -2894
A28: 3월 | B28: =SUMIFS('24년 3월'!$M:$M,'24년 1월'!$C:$C,"서대구운용팀",'24년 3월'!$I:$I,"경유") -> 1335000 | C28: =SUMIFS('24년 3월'!$M:$M,'24년 3월'!$C:$C,"서대구운용팀",'24년 3월'!$I:$I,"휘발유") -> 1163000 | D28: =SUMIFS('24년 3월'!$M:$M,'24년 3월'!$C:$C,"서대구운용팀",'24년 3월'!$I:$I,"EV") -> 0 | E28: =SUMIFS('25년 3월'!$M:$M,'25년 3월'!$C:$C,"서대구운용팀",'25년 3월'!$I:$I,"경유") -> 1753000 | F28: =SUMIFS('25년 3월'!$M:$M,'25년 3월'!$C:$C,"서대구운용팀",'25년 3월'!$I:$I,"휘발유") -> 1901000 | G28: =SUMIFS('25년 3월'!$M:$M,'25년 3월'!$C:$C,"서대구운용팀",'25년 3월'!$I:$I,"EV") -> 0 | I28: 3월 | J28: =B28+C28+D28 -> 2498000 | K28: =E28+F28+G28 -> 3654000 | L28: =K28-J28 -> 1156000 | N28: =SUMIFS('24년 3월'!$K:$K,'24년 3월'!$B:$B,"소계",'24년 3월'!$C:$C,"서대구운용팀") -> 25413 | O28: =SUMIFS('25년 3월'!$K:$K,'25년 3월'!$B:$B,"소계",'25년 3월'!$C:$C,"서대구운용팀") -> 26861 | P28: =O28-N28 -> 1448
A29: 4월 | B29: =SUMIFS('24년 4월'!$M:$M,'24년 4월'!$C:$C,"서대구운용팀",'24년 4월'!$I:$I,"경유") -> 1059000 | C29: =SUMIFS('24년 4월'!$M:$M,'24년 4월'!$C:$C,"서대구운용팀",'24년 4월'!$I:$I,"휘발유") -> 1153000 | D29: =SUMIFS('24년 4월'!$M:$M,'24년 4월'!$C:$C,"서대구운용팀",'24년 4월'!$I:$I,"EV") -> 0 | E29: =SUMIFS('25년 4월'!$M:$M,'25년 4월'!$C:$C,"서대구운용팀",'25년 4월'!$I:$I,"경유") -> 1653000 | F29: =SUMIFS('25년 4월'!$M:$M,'25년 4월'!$C:$C,"서대구운용팀",'25년 4월'!$I:$I,"휘발유") -> 1927000 | G29: =SUMIFS('25년 4월'!$M:$M,'25년 4월'!$C:$C,"서대구운용팀",'25년 4월'!$I:$I,"EV") -> 0 | I29: 4월 | J29: =B29+C29+D29 -> 2212000 | K29: =E29+F29+G29 -> 3580000 | L29: =K29-J29 -> 1368000 | N29: =SUMIFS('24년 4월'!$K:$K,'24년 4월'!$B:$B,"소계",'24년 4월'!$C:$C,"서대구운용팀") -> 24287 | O29: =SUMIFS('25년 4월'!$K:$K,'25년 4월'!$B:$B,"소계",'25년 4월'!$C:$C,"서대구운용팀") -> 24887 | P29: =O29-N29 -> 600
A30: 5월 | B30: =SUMIFS('24년 5월'!$M:$M,'24년 5월'!$C:$C,"서대구운용팀",'24년 5월'!$I:$I,"경유") -> 977000 | C30: =SUMIFS('24년 5월'!$M:$M,'24년 5월'!$C:$C,"서대구운용팀",'24년 5월'!$I:$I,"휘발유") -> 1164527 | D30: =SUMIFS('24년 5월'!$M:$M,'24년 5월'!$C:$C,"서대구운용팀",'24년 5월'!$I:$I,"EV") -> 0 | E30: =SUMIFS('25년 5월'!$M:$M,'25년 5월'!$C:$C,"서대구운용팀",'25년 5월'!$I:$I,"경유") -> 1386000 | F30: =SUMIFS('25년 5월'!$M:$M,'25년 5월'!$C:$C,"서대구운용팀",'25년 5월'!$I:$I,"휘발유") -> 1680000 | G30: =SUMIFS('25년 5월'!$M:$M,'25년 5월'!$C:$C,"서대구운용팀",'25년 5월'!$I:$I,"EV") -> 0 | I30: 5월 | J30: =B30+C30+D30 -> 2141527 | K30: =E30+F30+G30 -> 3066000 | L30: =K30-J30 -> 924473 | N30: =SUMIFS('24년 5월'!$K:$K,'24년 5월'!$B:$B,"소계",'24년 5월'!$C:$C,"서대구운용팀") -> 22995 | O30: =SUMIFS('25년 5월'!$K:$K,'25년 5월'!$B:$B,"소계",'25년 5월'!$C:$C,"서대구운용팀") -> 23461 | P30: =O30-N30 -> 466
A31: 6월 | B31: =SUMIFS('24년 6월'!$M:$M,'24년 6월'!$C:$C,"서대구운용팀",'24년 6월'!$I:$I,"경유") -> 844000 | C31: =SUMIFS('24년 6월'!$M:$M,'24년 6월'!$C:$C,"서대구운용팀",'24년 6월'!$I:$I,"휘발유") -> 1126000 | D31: =SUMIFS('24년 6월'!$M:$M,'24년 6월'!$C:$C,"서대구운용팀",'24년 6월'!$I:$I,"EV") -> 0 | E31: =SUMIFS('25년 6월'!$M:$M,'25년 6월'!$C:$C,"서대구운용팀",'25년 6월'!$I:$I,"경유") -> 1570000 | F31: =SUMIFS('25년 6월'!$M:$M,'25년 6월'!$C:$C,"서대구운용팀",'25년 6월'!$I:$I,"휘발유") -> 1990000 | G31: =SUMIFS('25년 6월'!$M:$M,'25년 6월'!$C:$C,"서대구운용팀",'25년 6월'!$I:$I,"EV") -> 0 | I31: 6월 | J31: =B31+C31+D31 -> 1970000 | K31: =E31+F31+G31 -> 3560000 | L31: =K31-J31 -> 1590000 | N31: =SUMIFS('24년 6월'!$K:$K,'24년 6월'!$B:$B,"소계",'24년 6월'!$C:$C,"서대구운용팀") -> 20042 | O31: =SUMIFS('25년 6월'!$K:$K,'25년 6월'!$B:$B,"소계",'25년 6월'!$C:$C,"서대구운용팀") -> 22151 | P31: =O31-N31 -> 2109
A32: 7월 | B32: =SUMIFS('24년 7월'!$M:$M,'24년 7월'!$C:$C,"서대구운용팀",'24년 7월'!$I:$I,"경유") -> 1093000 | C32: =SUMIFS('24년 7월'!$M:$M,'24년 7월'!$C:$C,"서대구운용팀",'24년 7월'!$I:$I,"휘발유") -> 1587000 | D32: =SUMIFS('24년 7월'!$M:$M,'24년 7월'!$C:$C,"서대구운용팀",'24년 7월'!$I:$I,"EV") -> 0 | E32: =SUMIFS('25년 7월'!$M:$M,'25년 7월'!$C:$C,"서대구운용팀",'25년 7월'!$I:$I,"경유") -> 924000 | F32: =SUMIFS('25년 7월'!$M:$M,'25년 7월'!$C:$C,"서대구운용팀",'25년 7월'!$I:$I,"휘발유") -> 4232000 | G32: =SUMIFS('25년 7월'!$M:$M,'25년 7월'!$C:$C,"서대구운용팀",'25년 7월'!$I:$I,"EV") -> 0 | I32: 7월 | J32: =B32+C32+D32 -> 2680000 | K32: =E32+F32+G32 -> 5156000 | L32: =K32-J32 -> 2476000 | N32: =SUMIFS('24년 7월'!$K:$K,'24년 7월'!$B:$B,"소계",'24년 7월'!$C:$C,"서대구운용팀") -> 25278 | O32: =SUMIFS('25년 7월'!$K:$K,'25년 7월'!$B:$B,"소계",'25년 7월'!$C:$C,"서대구운용팀") -> 28523 | P32: =O32-N32 -> 3245
A33: 8월 | B33: =SUMIFS('24년 8월'!$M:$M,'24년 8월'!$C:$C,"서대구운용팀",'24년 8월'!$I:$I,"경유") -> 1024000 | C33: =SUMIFS('24년 8월'!$M:$M,'24년 8월'!$C:$C,"서대구운용팀",'24년 8월'!$I:$I,"휘발유") -> 1212000 | D33: =SUMIFS('24년 8월'!$M:$M,'24년 8월'!$C:$C,"서대구운용팀",'24년 8월'!$I:$I,"EV") -> 0 | E33: =SUMIFS('25년 8월'!$M:$M,'25년 8월'!$C:$C,"서대구운용팀",'25년 8월'!$I:$I,"경유") -> 918000 | F33: =SUMIFS('25년 8월'!$M:$M,'25년 8월'!$C:$C,"서대구운용팀",'25년 8월'!$I:$I,"휘발유") -> 3328000 | G33: =SUMIFS('25년 8월'!$M:$M,'25년 8월'!$C:$C,"서대구운용팀",'25년 8월'!$I:$I,"EV") -> 0 | I33: 8월 | J33: =B33+C33+D33 -> 2236000 | K33: =E33+F33+G33 -> 4246000 | L33: =K33-J33 -> 2010000 | N33: =SUMIFS('24년 8월'!$K:$K,'24년 8월'!$B:$B,"소계",'24년 8월'!$C:$C,"서대구운용팀") -> 21808 | O33: =SUMIFS('25년 8월'!$K:$K,'25년 8월'!$B:$B,"소계",'25년 8월'!$C:$C,"서대구운용팀") -> 22804 | P33: =O33-N33 -> 996
A34: 9월 | B34: =SUMIFS('24년 9월'!$M:$M,'24년 9월'!$C:$C,"서대구운용팀",'24년 9월'!$I:$I,"경유") -> 1200000 | C34: =SUMIFS('24년 9월'!$M:$M,'24년 9월'!$C:$C,"서대구운용팀",'24년 9월'!$I:$I,"휘발유") -> 1606000 | D34: =SUMIFS('24년 9월'!$M:$M,'24년 9월'!$C:$C,"서대구운용팀",'24년 9월'!$I:$I,"EV") -> 0 | E34: =SUMIFS('25년 9월'!$M:$M,'25년 9월'!$C:$C,"서대구운용팀",'25년 9월'!$I:$I,"경유") -> 870000 | F34: =SUMIFS('25년 9월'!$M:$M,'25년 9월'!$C:$C,"서대구운용팀",'25년 9월'!$I:$I,"휘발유") -> 3895000 | G34: =SUMIFS('25년 9월'!$M:$M,'25년 9월'!$C:$C,"서대구운용팀",'25년 9월'!$I:$I,"EV") -> 0 | I34: 9월 | J34: =B34+C34+D34 -> 2806000 | K34: =E34+F34+G34 -> 4765000 | L34: =K34-J34 -> 1959000 | N34: =SUMIFS('24년 9월'!$K:$K,'24년 9월'!$B:$B,"소계",'24년 9월'!$C:$C,"서대구운용팀") -> 21834 | O34: =SUMIFS('25년 9월'!$K:$K,'25년 9월'!$B:$B,"소계",'25년 9월'!$C:$C,"서대구운용팀") -> 30010 | P34: =O34-N34 -> 8176
A35: 10월 | B35: =SUMIFS('24년 10월'!$M:$M,'24년 10월'!$C:$C,"서대구운용팀",'24년 10월'!$I:$I,"경유") -> 1397000 | C35: =SUMIFS('24년 10월'!$M:$M,'24년 10월'!$C:$C,"서대구운용팀",'24년 10월'!$I:$I,"휘발유") -> 1876801 | D35: =SUMIFS('24년 10월'!$M:$M,'24년 10월'!$C:$C,"서대구운용팀",'24년 10월'!$I:$I,"EV") -> 0 | E35: =SUMIFS('25년 10월'!$M:$M,'25년 10월'!$C:$C,"서대구운용팀",'25년 10월'!$I:$I,"경유") -> 695000 | F35: =SUMIFS('25년 10월'!$M:$M,'25년 10월'!$C:$C,"서대구운용팀",'25년 10월'!$I:$I,"휘발유") -> 2982000 | G35: =SUMIFS('25년 10월'!$M:$M,'25년 10월'!$C:$C,"서대구운용팀",'25년 10월'!$I:$I,"EV") -> 0 | I35: 10월 | J35: =B35+C35+D35 -> 3273801 | K35: =E35+F35+G35 -> 3677000 | L35: =K35-J35 -> 403199 | N35: =SUMIFS('24년 10월'!$K:$K,'24년 10월'!$B:$B,"소계",'24년 10월'!$C:$C,"서대구운용팀") -> 24474 | O35: =SUMIFS('25년 10월'!$K:$K,'25년 10월'!$B:$B,"소계",'25년 10월'!$C:$C,"서대구운용팀") -> 24965 | P35: =O35-N35 -> 491
A36: 11월 | B36: =SUMIFS('24년 11월'!$M:$M,'24년 11월'!$C:$C,"서대구운용팀",'24년 11월'!$I:$I,"경유") -> 922000 | C36: =SUMIFS('24년 11월'!$M:$M,'24년 11월'!$C:$C,"서대구운용팀",'24년 11월'!$I:$I,"휘발유") -> 1804105 | D36: =SUMIFS('24년 11월'!$M:$M,'24년 11월'!$C:$C,"서대구운용팀",'24년 11월'!$I:$I,"EV") -> 0 | E36: =SUMIFS('25년 11월'!$M:$M,'25년 11월'!$C:$C,"서대구운용팀",'25년 11월'!$I:$I,"경유") -> 770000 | F36: =SUMIFS('25년 11월'!$M:$M,'25년 11월'!$C:$C,"서대구운용팀",'25년 11월'!$I:$I,"휘발유") -> 2711000 | G36: =SUMIFS('25년 11월'!$M:$M,'25년 11월'!$C:$C,"서대구운용팀",'25년 11월'!$I:$I,"EV") -> 0 | I36: 11월 | J36: =B36+C36+D36 -> 2726105 | K36: =E36+F36+G36 -> 3481000 | L36: =K36-J36 -> 754895 | N36: =SUMIFS('24년 11월'!$K:$K,'24년 11월'!$B:$B,"소계",'24년 11월'!$C:$C,"서대구운용팀") -> 18559 | O36: =SUMIFS('25년 11월'!$K:$K,'25년 11월'!$B:$B,"소계",'25년 11월'!$C:$C,"서대구운용팀") -> 22153 | P36: =O36-N36 -> 3594
A37: 12월 | B37: =SUMIFS('24년 12월'!$M:$M,'24년 12월'!$C:$C,"서대구운용팀",'24년 12월'!$I:$I,"경유") -> 1167000 | C37: =SUMIFS('24년 12월'!$M:$M,'24년 12월'!$C:$C,"서대구운용팀",'24년 12월'!$I:$I,"휘발유") -> 1719000 | D37: =SUMIFS('24년 12월'!$M:$M,'24년 12월'!$C:$C,"서대구운용팀",'24년 12월'!$I:$I,"EV") -> 0 | E37: =SUMIFS('25년 12월'!$M:$M,'25년 12월'!$C:$C,"서대구운용팀",'25년 12월'!$I:$I,"경유") -> 732000 | F37: =SUMIFS('25년 12월'!$M:$M,'25년 12월'!$C:$C,"서대구운용팀",'25년 12월'!$I:$I,"휘발유") -> 2446000 | G37: =SUMIFS('25년 12월'!$M:$M,'25년 12월'!$C:$C,"서대구운용팀",'25년 12월'!$I:$I,"EV") -> 0 | I37: 12월 | J37: =B37+C37+D37 -> 2886000 | N37: =SUMIFS('24년 12월'!$K:$K,'24년 12월'!$B:$B,"소계",'24년 12월'!$C:$C,"서대구운용팀") -> 17533 | O37: -
A38: 합계 | B38: =SUM(B26:B37) -> 13047000 | C38: =SUM(C26:C37) -> 16548895 | D38: =SUM(D26:D37) -> 23845 | E38: =SUM(E26:E37) -> 13658000 | F38: =SUM(F26:F37) -> 30597915 | G38: =SUM(G26:G37) -> 0 | P38: =SUM(P26:P37) -> 18831
A41: 남대구운용팀 | AG41: 원인분석
B44: 24년 | E44: 25년
A45: 구분 | B45: 경유 유류비 | C45: 휘발유 유류비 | D45: EV 유류비 | E45: 경유 유류비 | F45: 휘발유 유류비 | G45: EV 유류비 | I45: 구분 | J45: 24년 유류비 | K45: 25년 유류비 | L45: 증감비용 | N45: 24년 주행거리 | O45: 25년 주행거리 | P45: 증감거리
A46: 1월 | B46: =SUMIFS('24년 1월'!$M:$M,'24년 1월'!$C:$C,"남대구운용팀",'24년 1월'!$I:$I,"경유") -> 758000 | C46: =SUMIFS('24년 1월'!$M:$M,'24년 1월'!$C:$C,"남대구운용팀",'24년 1월'!$I:$I,"휘발유") -> 898000 | D46: =SUMIFS('24년 1월'!$M:$M,'24년 1월'!$C:$C,"남대구운용팀",'24년 1월'!$I:$I,"EV") -> 0 | E46: =SUMIFS('25년 1월'!$M:$M,'25년 1월'!$C:$C,"남대구운용팀",'25년 1월'!$I:$I,"경유") -> 702000 | F46: =SUMIFS('25년 1월'!$M:$M,'25년 1월'!$C:$C,"남대구운용팀",'25년 1월'!$I:$I,"휘발유") -> 197000 | G46: =SUMIFS('25년 1월'!$M:$M,'25년 1월'!$C:$C,"남대구운용팀",'25년 1월'!$I:$I,"EV") -> 281748 | I46: 1월 | J46: =B46+C46+D46 -> 1656000 | K46: =E46+F46+G46 -> 1180748 | L46: =K46-J46 -> -475252 | N46: =SUMIFS('24년 4월'!$K:$K,'24년 4월'!$B:$B,"소계",'24년 4월'!$C:$C,"남대구운용팀") -> 22696 | O46: =SUMIFS('25년 4월'!$K:$K,'25년 4월'!$B:$B,"소계",'25년 4월'!$C:$C,"남대구운용팀") -> 22901 | P46: =O46-N46 -> 205
A47: 2월 | B47: =SUMIFS('24년 2월'!$M:$M,'24년 2월'!$C:$C,"남대구운용팀",'24년 2월'!$I:$I,"경유") -> 772000 | C47: =SUMIFS('24년 2월'!$M:$M,'24년 2월'!$C:$C,"남대구운용팀",'24년 2월'!$I:$I,"휘발유") -> 990000 | D47: =SUMIFS('24년 2월'!$M:$M,'24년 2월'!$C:$C,"남대구운용팀",'24년 2월'!$I:$I,"EV") -> 0 | E47: =SUMIFS('25년 2월'!$M:$M,'25년 2월'!$C:$C,"남대구운용팀",'25년 2월'!$I:$I,"경유") -> 764000 | F47: =SUMIFS('25년 2월'!$M:$M,'25년 2월'!$C:$C,"남대구운용팀",'25년 2월'!$I:$I,"휘발유") -> 260000 | G47: =SUMIFS('25년 2월'!$M:$M,'25년 2월'!$C:$C,"남대구운용팀",'25년 2월'!$I:$I,"EV") -> 152583 | I47: 2월 | J47: =B47+C47+D47 -> 1762000 | K47: =E47+F47+G47 -> 1176583 | L47: =K47-J47 -> -585417 | N47: =SUMIFS('24년 2월'!$K:$K,'24년 2월'!$B:$B,"소계",'24년 2월'!$C:$C,"남대구운용팀") -> 19504 | O47: =SUMIFS('25년 2월'!$K:$K,'25년 2월'!$B:$B,"소계",'25년 2월'!$C:$C,"남대구운용팀") -> 19820 | P47: =O47-N47 -> 316
A48: 3월 | B48: =SUMIFS('24년 3월'!$M:$M,'24년 3월'!$C:$C,"남대구운용팀",'24년 3월'!$I:$I,"경유") -> 1037000 | C48: =SUMIFS('24년 3월'!$M:$M,'24년 3월'!$C:$C,"남대구운용팀",'24년 3월'!$I:$I,"휘발유") -> 1093000 | D48: =SUMIFS('24년 3월'!$M:$M,'24년 3월'!$C:$C,"남대구운용팀",'24년 3월'!$I:$I,"EV") -> 0 | E48: =SUMIFS('25년 3월'!$M:$M,'25년 3월'!$C:$C,"남대구운용팀",'25년 3월'!$I:$I,"경유") -> 789000 | F48: =SUMIFS('25년 3월'!$M:$M,'25년 3월'!$C:$C,"남대구운용팀",'25년 3월'!$I:$I,"휘발유") -> 276000 | G48: =SUMIFS('25년 3월'!$M:$M,'25년 3월'!$C:$C,"남대구운용팀",'25년 3월'!$I:$I,"EV") -> 197132 | I48: 3월 | J48: =B48+C48+D48 -> 2130000 | K48: =E48+F48+G48 -> 1262132 | L48: =K48-J48 -> -867868 | N48: =SUMIFS('24년 3월'!$K:$K,'24년 3월'!$B:$B,"소계",'24년 3월'!$C:$C,"남대구운용팀") -> 23215 | O48: =SUMIFS('25년 3월'!$K:$K,'25년 3월'!$B:$B,"소계",'25년 3월'!$C:$C,"남대구운용팀") -> 25065 | P48: =O48-N48 -> 1850
A49: 4월 | B49: =SUMIFS('24년 4월'!$M:$M,'24년 4월'!$C:$C,"남대구운용팀",'24년 4월'!$I:$I,"경유") -> 864000 | C49: =SUMIFS('24년 4월'!$M:$M,'24년 4월'!$C:$C,"남대구운용팀",'24년 4월'!$I:$I,"휘발유") -> 1209000 | D49: =SUMIFS('24년 4월'!$M:$M,'24년 4월'!$C:$C,"남대구운용팀",'24년 4월'!$I:$I,"EV") -> 0 | E49: =SUMIFS('25년 4월'!$M:$M,'25년 4월'!$C:$C,"남대구운용팀",'25년 4월'!$I:$I,"경유") -> 676000 | F49: =SUMIFS('25년 4월'!$M:$M,'25년 4월'!$C:$C,"남대구운용팀",'25년 4월'!$I:$I,"휘발유") -> 309000 | G49: =SUMIFS('25년 4월'!$M:$M,'25년 4월'!$C:$C,"남대구운용팀",'25년 4월'!$I:$I,"EV") -> 110984 | I49: 4월 | J49: =B49+C49+D49 -> 2073000 | K49: =E49+F49+G49 -> 1095984 | L49: =K49-J49 -> -977016 | N49: =SUMIFS('24년 4월'!$K:$K,'24년 4월'!$B:$B,"소계",'24년 4월'!$C:$C,"남대구운용팀") -> 22696 | O49: =SUMIFS('25년 4월'!$K:$K,'25년 4월'!$B:$B,"소계",'25년 4월'!$C:$C,"남대구운용팀") -> 22901 | P49: =O49-N49 -> 205
A50: 5월 | B50: =SUMIFS('24년 5월'!$M:$M,'24년 5월'!$C:$C,"남대구운용팀",'24년 5월'!$I:$I,"경유") -> 1180000 | C50: =SUMIFS('24년 5월'!$M:$M,'24년 5월'!$C:$C,"남대구운용팀",'24년 5월'!$I:$I,"휘발유") -> 965000 | D50: =SUMIFS('24년 5월'!$M:$M,'24년 5월'!$C:$C,"남대구운용팀",'24년 5월'!$I:$I,"EV") -> 105870 | E50: =SUMIFS('25년 5월'!$M:$M,'25년 5월'!$C:$C,"남대구운용팀",'25년 5월'!$I:$I,"경유") -> 690000 | F50: =SUMIFS('25년 5월'!$M:$M,'25년 5월'!$C:$C,"남대구운용팀",'25년 5월'!$I:$I,"휘발유") -> 270000 | G50: =SUMIFS('25년 5월'!$M:$M,'25년 5월'!$C:$C,"남대구운용팀",'25년 5월'!$I:$I,"EV") -> 8093 | I50: 5월 | J50: =B50+C50+D50 -> 2250870 | K50: =E50+F50+G50 -> 968093 | L50: =K50-J50 -> -1282777 | N50: =SUMIFS('24년 5월'!$K:$K,'24년 5월'!$B:$B,"소계",'24년 5월'!$C:$C,"남대구운용팀") -> 22352 | O50: =SUMIFS('25년 5월'!$K:$K,'25년 5월'!$B:$B,"소계",'25년 5월'!$C:$C,"남대구운용팀") -> 19307 | P50: =O50-N50 -> -3045
...

Sheet 스탭
A1: 운용지원팀
A3: 구분 | B3: 24년 | E3: 25년 | I3: 운용지원팀
B4: 경유 유류비 | C4: 휘발유 유류비 | D4: EV 유류비 | E4: 경유 유류비 | F4: 휘발유 유류비 | G4: EV 유류비 | I4: 구분 | J4: 24년 유류비 | K4: 25년 유류비 | L4: 증감비용
A5: 1월 | B5: =SUMIFS('24년 1월'!$M:$M,'24년 1월'!$C:$C,"운용지원팀",'24년 1월'!$I:$I,"경유") -> 240000 | C5: =SUMIFS('24년 1월'!$M:$M,'24년 1월'!$C:$C,"운용지원팀",'24년 1월'!$I:$I,"휘발유") -> 0 | D5: =SUMIFS('24년 1월'!$M:$M,'24년 1월'!$C:$C,"운용지원팀",'24년 1월'!$I:$I,"EV") -> 0 | E5: =SUMIFS('25년 1월'!$M:$M,'25년 1월'!$C:$C,"운용지원팀",'25년 1월'!$I:$I,"경유") -> 90000 | F5: =SUMIFS('25년 1월'!$M:$M,'25년 1월'!$C:$C,"운용지원팀",'25년 1월'!$I:$I,"휘발유") -> 0 | G5: =SUMIFS('25년 1월'!$M:$M,'25년 1월'!$C:$C,"운용지원팀",'25년 1월'!$I:$I,"EV") -> 0 | I5: 1월 | J5: =B5+C5+D5 -> 240000 | K5: =E5+F5+G5 -> 90000 | L5: =K5-J5 -> -150000
A6: 2월 | B6: =SUMIFS('24년 2월'!$M:$M,'24년 2월'!$C:$C,"운용지원팀",'24년 2월'!$I:$I,"경유") -> 233000 | C6: =SUMIFS('24년 2월'!$M:$M,'24년 2월'!$C:$C,"운용지원팀",'24년 2월'!$I:$I,"휘발유") -> 0 | D6: =SUMIFS('24년 2월'!$M:$M,'24년 2월'!$C:$C,"운용지원팀",'24년 2월'!$I:$I,"EV") -> 0 | E6: =SUMIFS('25년 2월'!$M:$M,'25년 2월'!$C:$C,"운용지원팀",'25년 2월'!$I:$I,"경유") -> 200000 | F6: =SUMIFS('25년 2월'!$M:$M,'25년 2월'!$C:$C,"운용지원팀",'25년 2월'!$I:$I,"휘발유") -> 0 | G6: =SUMIFS('25년 2월'!$M:$M,'25년 2월'!$C:$C,"운용지원팀",'25년 2월'!$I:$I,"EV") -> 0 | I6: 2월 | J6: =B6+C6+D6 -> 233000 | K6: =E6+F6+G6 -> 200000 | L6: =K6-J6 -> -33000
A7: 3월 | B7: =SUMIFS('24년 3월'!$M:$M,'24년 3월'!$C:$C,"운용지원팀",'24년 3월'!$I:$I,"경유") -> 152000 | C7: =SUMIFS('24년 3월'!$M:$M,'24년 3월'!$C:$C,"운용지원팀",'24년 3월'!$I:$I,"휘발유") -> 0 | D7: =SUMIFS('24년 3월'!$M:$M,'24년 3월'!$C:$C,"운용지원팀",'24년 3월'!$I:$I,"EV") -> 0 | E7: =SUMIFS('25년 3월'!$M:$M,'25년 3월'!$C:$C,"운용지원팀",'25년 3월'!$I:$I,"경유") -> 290000 | F7: =SUMIFS('25년 3월'!$M:$M,'25년 3월'!$C:$C,"운용지원팀",'25년 3월'!$I:$I,"휘발유") -> 0 | G7: =SUMIFS('25년 3월'!$M:$M,'25년 3월'!$C:$C,"운용지원팀",'25년 3월'!$I:$I,"EV") -> 0 | I7: 3월 | J7: =B7+C7+D7 -> 152000 | K7: =E7+F7+G7 -> 290000 | L7: =K7-J7 -> 138000
A8: 4월 | B8: =SUMIFS('24년 4월'!$M:$M,'24년 4월'!$C:$C,"운용지원팀",'24년 4월'!$I:$I,"경유") -> 200000 | C8: =SUMIFS('24년 4월'!$M:$M,'24년 4월'!$C:$C,"운용지원팀",'24년 4월'!$I:$I,"휘발유") -> 0 | D8: =SUMIFS('24년 4월'!$M:$M,'24년 4월'!$C:$C,"운용지원팀",'24년 4월'!$I:$I,"EV") -> 0 | E8: =SUMIFS('25년 4월'!$M:$M,'25년 4월'!$C:$C,"운용지원팀",'25년 4월'!$I:$I,"경유") -> 216000 | F8: =SUMIFS('25년 4월'!$M:$M,'25년 4월'!$C:$C,"운용지원팀",'25년 4월'!$I:$I,"휘발유") -> 0 | G8: =SUMIFS('25년 4월'!$M:$M,'25년 4월'!$C:$C,"운용지원팀",'25년 4월'!$I:$I,"EV") -> 0 | I8: 4월 | J8: =B8+C8+D8 -> 200000 | K8: =E8+F8+G8 -> 216000 | L8: =K8-J8 -> 16000
A9: 5월 | B9: =SUMIFS('24년 5월'!$M:$M,'24년 5월'!$C:$C,"운용지원팀",'24년 5월'!$I:$I,"경유") -> 230000 | C9: =SUMIFS('24년 5월'!$M:$M,'24년 5월'!$C:$C,"운용지원팀",'24년 5월'!$I:$I,"휘발유") -> 0 | D9: =SUMIFS('24년 5월'!$M:$M,'24년 5월'!$C:$C,"운용지원팀",'24년 5월'!$I:$I,"EV") -> 0 | E9: =SUMIFS('25년 5월'!$M:$M,'25년 5월'!$C:$C,"운용지원팀",'25년 5월'!$I:$I,"경유") -> 240000 | F9: =SUMIFS('25년 5월'!$M:$M,'25년 5월'!$C:$C,"운용지원팀",'25년 5월'!$I:$I,"휘발유") -> 0 | G9: =SUMIFS('25년 5월'!$M:$M,'25년 5월'!$C:$C,"운용지원팀",'25년 5월'!$I:$I,"EV") -> 0 | I9: 5월 | J9: =B9+C9+D9 -> 230000 | K9: =E9+F9+G9 -> 240000 | L9: =K9-J9 -> 10000
A10: 6월 | B10: =SUMIFS('24년 6월'!$M:$M,'24년 6월'!$C:$C,"운용지원팀",'24년 6월'!$I:$I,"경유") -> 230000 | C10: =SUMIFS('24년 6월'!$M:$M,'24년 6월'!$C:$C,"운용지원팀",'24년 6월'!$I:$I,"휘발유") -> 0 | D10: =SUMIFS('24년 6월'!$M:$M,'24년 6월'!$C:$C,"운용지원팀",'24년 6월'!$I:$I,"EV") -> 0 | E10: =SUMIFS('25년 6월'!$M:$M,'25년 6월'!$C:$C,"운용지원팀",'25년 6월'!$I:$I,"경유") -> 236017 | F10: =SUMIFS('25년 6월'!$M:$M,'25년 6월'!$C:$C,"운용지원팀",'25년 6월'!$I:$I,"휘발유") -> 0 | G10: =SUMIFS('25년 6월'!$M:$M,'25년 6월'!$C:$C,"운용지원팀",'25년 6월'!$I:$I,"EV") -> 0 | I10: 6월 | J10: =B10+C10+D10 -> 230000 | K10: =E10+F10+G10 -> 236017 | L10: =K10-J10 -> 6017
A11: 7월 | B11: =SUMIFS('24년 7월'!$M:$M,'24년 7월'!$C:$C,"운용지원팀",'24년 7월'!$I:$I,"경유") -> 272000 | C11: =SUMIFS('24년 7월'!$M:$M,'24년 7월'!$C:$C,"운용지원팀",'24년 7월'!$I:$I,"휘발유") -> 0 | D11: =SUMIFS('24년 7월'!$M:$M,'24년 7월'!$C:$C,"운용지원팀",'24년 7월'!$I:$I,"EV") -> 0 | E11: =SUMIFS('25년 7월'!$M:$M,'25년 7월'!$C:$C,"운용지원팀",'25년 7월'!$I:$I,"경유") -> 315000 | F11: =SUMIFS('25년 7월'!$M:$M,'25년 7월'!$C:$C,"운용지원팀",'25년 7월'!$I:$I,"휘발유") -> 206000 | G11: =SUMIFS('25년 7월'!$M:$M,'25년 7월'!$C:$C,"운용지원팀",'25년 7월'!$I:$I,"EV") -> 0 | I11: 7월 | J11: =B11+C11+D11 -> 272000 | K11: =E11+F11+G11 -> 521000 | L11: =K11-J11 -> 249000
A12: 8월 | B12: =SUMIFS('24년 8월'!$M:$M,'24년 8월'!$C:$C,"운용지원팀",'24년 8월'!$I:$I,"경유") -> 230000 | C12: =SUMIFS('24년 8월'!$M:$M,'24년 8월'!$C:$C,"운용지원팀",'24년 8월'!$I:$I,"휘발유") -> 0 | D12: =SUMIFS('24년 8월'!$M:$M,'24년 8월'!$C:$C,"운용지원팀",'24년 8월'!$I:$I,"EV") -> 0 | E12: =SUMIFS('25년 8월'!$M:$M,'25년 8월'!$C:$C,"운용지원팀",'25년 8월'!$I:$I,"경유") -> 170000 | F12: =SUMIFS('25년 8월'!$M:$M,'25년 8월'!$C:$C,"운용지원팀",'25년 8월'!$I:$I,"휘발유") -> 100000 | G12: =SUMIFS('25년 8월'!$M:$M,'25년 8월'!$C:$C,"운용지원팀",'25년 8월'!$I:$I,"EV") -> 0 | I12: 8월 | J12: =B12+C12+D12 -> 230000 | K12: =E12+F12+G12 -> 270000 | L12: =K12-J12 -> 40000
A13: 9월 | B13: =SUMIFS('24년 9월'!$M:$M,'24년 9월'!$C:$C,"운용지원팀",'24년 9월'!$I:$I,"경유") -> 145000 | C13: =SUMIFS('24년 9월'!$M:$M,'24년 9월'!$C:$C,"운용지원팀",'24년 9월'!$I:$I,"휘발유") -> 0 | D13: =SUMIFS('24년 9월'!$M:$M,'24년 9월'!$C:$C,"운용지원팀",'24년 9월'!$I:$I,"EV") -> 0 | E13: =SUMIFS('25년 9월'!$M:$M,'25년 9월'!$C:$C,"운용지원팀",'25년 9월'!$I:$I,"경유") -> 130000 | F13: =SUMIFS('25년 9월'!$M:$M,'25년 9월'!$C:$C,"운용지원팀",'25년 9월'!$I:$I,"휘발유") -> 160000 | G13: =SUMIFS('25년 9월'!$M:$M,'25년 9월'!$C:$C,"운용지원팀",'25년 9월'!$I:$I,"EV") -> 0 | I13: 9월 | J13: =B13+C13+D13 -> 145000 | K13: =E13+F13+G13 -> 290000 | L13: =K13-J13 -> 145000
A14: 10월 | B14: =SUMIFS('24년 10월'!$M:$M,'24년 10월'!$C:$C,"운용지원팀",'24년 10월'!$I:$I,"경유") -> 200000 | C14: =SUMIFS('24년 10월'!$M:$M,'24년 10월'!$C:$C,"운용지원팀",'24년 10월'!$I:$I,"휘발유") -> 0 | D14: =SUMIFS('24년 10월'!$M:$M,'24년 10월'!$C:$C,"운용지원팀",'24년 10월'!$I:$I,"EV") -> 0 | E14: =SUMIFS('25년 10월'!$M:$M,'25년 10월'!$C:$C,"운용지원팀",'25년 10월'!$I:$I,"경유") -> 260000 | F14: =SUMIFS('25년 10월'!$M:$M,'25년 10월'!$C:$C,"운용지원팀",'25년 10월'!$I:$I,"휘발유") -> 180000 | G14: =SUMIFS('25년 10월'!$M:$M,'25년 10월'!$C:$C,"운용지원팀",'25년 10월'!$I:$I,"EV") -> 0 | I14: 10월 | J14: =B14+C14+D14 -> 200000 | K14: =E14+F14+G14 -> 440000 | L14: =K14-J14 -> 240000
A15: 11월 | B15: =SUMIFS('24년 11월'!$M:$M,'24년 11월'!$C:$C,"운용지원팀",'24년 11월'!$I:$I,"경유") -> 251000 | C15: =SUMIFS('24년 11월'!$M:$M,'24년 11월'!$C:$C,"운용지원팀",'24년 11월'!$I:$I,"휘발유") -> 0 | D15: =SUMIFS('24년 11월'!$M:$M,'24년 11월'!$C:$C,"운용지원팀",'24년 11월'!$I:$I,"EV") -> 0 | E15: =SUMIFS('25년 11월'!$M:$M,'25년 11월'!$C:$C,"운용지원팀",'25년 11월'!$I:$I,"경유") -> 285000 | F15: =SUMIFS('25년 11월'!$M:$M,'25년 11월'!$C:$C,"운용지원팀",'25년 11월'!$I:$I,"휘발유") -> 212000 | G15: =SUMIFS('25년 11월'!$M:$M,'25년 11월'!$C:$C,"운용지원팀",'25년 11월'!$I:$I,"EV") -> 0 | I15: 11월 | J15: =B15+C15+D15 -> 251000 | K15: =E15+F15+G15 -> 497000 | L15: =K15-J15 -> 246000
A16: 12월 | B16: =SUMIFS('24년 12월'!$M:$M,'24년 12월'!$C:$C,"운용지원팀",'24년 12월'!$I:$I,"경유") -> 210000 | C16: =SUMIFS('24년 12월'!$M:$M,'24년 12월'!$C:$C,"운용지원팀",'24년 12월'!$I:$I,"휘발유") -> 0 | D16: =SUMIFS('24년 12월'!$M:$M,'24년 12월'!$C:$C,"운용지원팀",'24년 12월'!$I:$I,"EV") -> 0 | E16: =SUMIFS('25년 12월'!$M:$M,'25년 12월'!$C:$C,"운용지원팀",'25년 12월'!$I:$I,"경유") -> 160000 | F16: =SUMIFS('25년 12월'!$M:$M,'25년 12월'!$C:$C,"운용지원팀",'25년 12월'!$I:$I,"휘발유") -> 129249 | G16: =SUMIFS('25년 12월'!$M:$M,'25년 12월'!$C:$C,"운용지원팀",'25년 12월'!$I:$I,"EV") -> 0 | I16: 12월 | J16: =B16+C16+D16 -> 210000 | K16: =E16+F16+G16 -> 289249 | L16: =K16-J16 -> 79249
A17: 합계 | B17: =SUM(B5:B16) -> 2593000 | C17: =SUM(C5:C16) -> 0 | D17: =SUM(D5:D16) -> 0 | E17: =SUM(E5:E16) -> 2592017 | F17: =SUM(F5:F16) -> 987249 | G17: =SUM(G5:G16) -> 0 | L17: =SUM(L5:L16) -> 986266
A18: 사업지원팀
A20: 구분 | B20: 24년 | E20: 25년 | I20: 사업지원팀
B21: 경유 유류비 | C21: 휘발유 유류비 | D21: EV 유류비 | E21: 경유 유류비 | F21: 휘발유 유류비 | G21: EV 유류비 | I21: 구분 | J21: 24년 유류비 | K21: 25년 유류비 | L21: 증감비용
A22: 1월 | B22: =SUMIFS('24년 1월'!$M:$M,'24년 1월'!$C:$C,"미래사업팀",'24년 1월'!$I:$I,"경유") -> 0 | C22: =SUMIFS('24년 1월'!$M:$M,'24년 1월'!$C:$C,"전원지원팀",'24년 1월'!$I:$I,"휘발유") -> 0 | D22: =SUMIFS('24년 1월'!$M:$M,'24년 1월'!$C:$C,"미래사업팀",'24년 1월'!$I:$I,"EV") -> 0 | E22: =SUMIFS('25년 1월'!$M:$M,'25년 1월'!$C:$C,"사업지원팀",'25년 1월'!$I:$I,"경유") -> 0 | F22: =SUMIFS('25년 1월'!$M:$M,'25년 1월'!$C:$C,"사업지원팀",'25년 1월'!$I:$I,"휘발유") -> 0 | G22: =SUMIFS('25년 1월'!$M:$M,'25년 1월'!$C:$C,"사업지원팀",'25년 1월'!$I:$I,"EV") -> 0 | I22: 1월 | J22: =B22+C22+D22 -> 0 | K22: =E22+F22+G22 -> 0 | L22: =K22-J22 -> 0
A23: 2월 | B23: =SUMIFS('24년 2월'!$M:$M,'24년 2월'!$C:$C,"미래사업팀",'24년 2월'!$I:$I,"경유") -> 0 | C23: =SUMIFS('24년 2월'!$M:$M,'24년 2월'!$C:$C,"전원지원팀",'24년 2월'!$I:$I,"휘발유") -> 0 | D23: =SUMIFS('24년 2월'!$M:$M,'24년 2월'!$C:$C,"미래사업팀",'24년 2월'!$I:$I,"EV") -> 0 | E23: =SUMIFS('25년 2월'!$M:$M,'25년 2월'!$C:$C,"사업지원팀",'25년 2월'!$I:$I,"경유") -> 0 | F23: =SUMIFS('25년 2월'!$M:$M,'25년 2월'!$C:$C,"사업지원팀",'25년 2월'!$I:$I,"휘발유") -> 196000 | G23: =SUMIFS('25년 2월'!$M:$M,'25년 2월'!$C:$C,"사업지원팀",'25년 2월'!$I:$I,"EV") -> 0 | I23: 2월 | J23: =B23+C23+D23 -> 0 | K23: =E23+F23+G23 -> 196000 | L23: =K23-J23 -> 196000
A24: 3월 | B24: =SUMIFS('24년 3월'!$M:$M,'24년 3월'!$C:$C,"미래사업팀",'24년 3월'!$I:$I,"경유") -> 0 | C24: =SUMIFS('24년 3월'!$M:$M,'24년 3월'!$C:$C,"전원지원팀",'24년 3월'!$I:$I,"휘발유") -> 0 | D24: =SUMIFS('24년 3월'!$M:$M,'24년 3월'!$C:$C,"미래사업팀",'24년 3월'!$I:$I,"EV") -> 0 | E24: =SUMIFS('25년 3월'!$M:$M,'25년 3월'!$C:$C,"사업지원팀",'25년 3월'!$I:$I,"경유") -> 0 | F24: =SUMIFS('25년 3월'!$M:$M,'25년 3월'!$C:$C,"사업지원팀",'25년 3월'!$I:$I,"휘발유") -> 110000 | G24: =SUMIFS('25년 3월'!$M:$M,'25년 3월'!$C:$C,"사업지원팀",'25년 3월'!$I:$I,"EV") -> 0 | I24: 3월 | J24: =B24+C24+D24 -> 0 | K24: =E24+F24+G24 -> 110000 | L24: =K24-J24 -> 110000
A25: 4월 | B25: =SUMIFS('24년 4월'!$M:$M,'24년 4월'!$C:$C,"미래사업팀",'24년 4월'!$I:$I,"경유") -> 0 | C25: =SUMIFS('24년 4월'!$M:$M,'24년 4월'!$C:$C,"전원지원팀",'24년 4월'!$I:$I,"휘발유") -> 0 | D25: =SUMIFS('24년 4월'!$M:$M,'24년 4월'!$C:$C,"미래사업팀",'24년 4월'!$I:$I,"EV") -> 0 | E25: =SUMIFS('25년 4월'!$M:$M,'25년 4월'!$C:$C,"사업지원팀",'25년 4월'!$I:$I,"경유") -> 0 | F25: =SUMIFS('25년 4월'!$M:$M,'25년 4월'!$C:$C,"사업지원팀",'25년 4월'!$I:$I,"휘발유") -> 307000 | G25: =SUMIFS('25년 4월'!$M:$M,'25년 4월'!$C:$C,"사업지원팀",'25년 4월'!$I:$I,"EV") -> 0 | I25: 4월 | J25: =B25+C25+D25 -> 0 | K25: =E25+F25+G25 -> 307000 | L25: =K25-J25 -> 307000
A26: 5월 | B26: =SUMIFS('24년 5월'!$M:$M,'24년 5월'!$C:$C,"미래사업팀",'24년 5월'!$I:$I,"경유") -> 0 | C26: =SUMIFS('24년 5월'!$M:$M,'24년 5월'!$C:$C,"전원지원팀",'24년 5월'!$I:$I,"휘발유") -> 0 | D26: =SUMIFS('24년 5월'!$M:$M,'24년 5월'!$C:$C,"미래사업팀",'24년 5월'!$I:$I,"EV") -> 0 | E26: =SUMIFS('25년 5월'!$M:$M,'25년 5월'!$C:$C,"사업지원팀",'25년 5월'!$I:$I,"경유") -> 0 | F26: =SUMIFS('25년 5월'!$M:$M,'25년 5월'!$C:$C,"사업지원팀",'25년 5월'!$I:$I,"휘발유") -> 120000 | G26: =SUMIFS('25년 5월'!$M:$M,'25년 5월'!$C:$C,"사업지원팀",'25년 5월'!$I:$I,"EV") -> 0 | I26: 5월 | J26: =B26+C26+D26 -> 0 | K26: =E26+F26+G26 -> 120000 | L26: =K26-J26 -> 120000
A27: 6월 | B27: =SUMIFS('24년 6월'!$M:$M,'24년 6월'!$C:$C,"미래사업팀",'24년 6월'!$I:$I,"경유") -> 0 | C27: =SUMIFS('24년 6월'!$M:$M,'24년 6월'!$C:$C,"전원지원팀",'24년 6월'!$I:$I,"휘발유") -> 0 | D27: =SUMIFS('24년 6월'!$M:$M,'24년 6월'!$C:$C,"미래사업팀",'24년 6월'!$I:$I,"EV") -> 0 | E27: =SUMIFS('25년 6월'!$M:$M,'25년 6월'!$C:$C,"사업지원팀",'25년 6월'!$I:$I,"경유") -> 0 | F27: =SUMIFS('25년 6월'!$M:$M,'25년 6월'!$C:$C,"사업지원팀",'25년 6월'!$I:$I,"휘발유") -> 128000 | G27: =SUMIFS('25년 6월'!$M:$M,'25년 6월'!$C:$C,"사업지원팀",'25년 6월'!$I:$I,"EV") -> 0 | I27: 6월 | J27: =B27+C27+D27 -> 0 | K27: =E27+F27+G27 -> 128000 | L27: =K27-J27 -> 128000
A28: 7월 | B28: =SUMIFS('24년 7월'!$M:$M,'24년 7월'!$C:$C,"미래사업팀",'24년 7월'!$I:$I,"경유") -> 0 | C28: =SUMIFS('24년 7월'!$M:$M,'24년 7월'!$C:$C,"전원지원팀",'24년 7월'!$I:$I,"휘발유") -> 0 | D28: =SUMIFS('24년 7월'!$M:$M,'24년 7월'!$C:$C,"미래사업팀",'24년 7월'!$I:$I,"EV") -> 0 | E28: =SUMIFS('25년 7월'!$M:$M,'25년 7월'!$C:$C,"사업지원팀",'25년 7월'!$I:$I,"경유") -> 0 | F28: =SUMIFS('25년 7월'!$M:$M,'25년 7월'!$C:$C,"사업지원팀",'25년 7월'!$I:$I,"휘발유") -> 120000 | G28: =SUMIFS('25년 7월'!$M:$M,'25년 7월'!$C:$C,"사업지원팀",'25년 7월'!$I:$I,"EV") -> 0 | I28: 7월 | J28: =B28+C28+D28 -> 0 | K28: =E28+F28+G28 -> 120000 | L28: =K28-J28 -> 120000
A29: 8월 | B29: =SUMIFS('24년 8월'!$M:$M,'24년 8월'!$C:$C,"미래사업팀",'24년 8월'!$I:$I,"경유") -> 0 | C29: =SUMIFS('24년 8월'!$M:$M,'24년 8월'!$C:$C,"전원지원팀",'24년 8월'!$I:$I,"휘발유") -> 0 | D29: =SUMIFS('24년 8월'!$M:$M,'24년 8월'!$C:$C,"미래사업팀",'24년 8월'!$I:$I,"EV") -> 0 | E29: =SUMIFS('25년 8월'!$M:$M,'25년 8월'!$C:$C,"사업지원팀",'25년 8월'!$I:$I,"경유") -> 0 | F29: =SUMIFS('25년 8월'!$M:$M,'25년 8월'!$C:$C,"사업지원팀",'25년 8월'!$I:$I,"휘발유") -> 182000 | G29: =SUMIFS('25년 8월'!$M:$M,'25년 8월'!$C:$C,"사업지원팀",'25년 8월'!$I:$I,"EV") -> 0 | I29: 8월 | J29: =B29+C29+D29 -> 0 | K29: =E29+F29+G29 -> 182000 | L29: =K29-J29 -> 182000
A30: 9월 | B30: =SUMIFS('24년 9월'!$M:$M,'24년 9월'!$C:$C,"미래사업팀",'24년 9월'!$I:$I,"경유") -> 0 | C30: =SUMIFS('24년 9월'!$M:$M,'24년 9월'!$C:$C,"미래사업팀",'24년 9월'!$I:$I,"휘발유") -> 100000 | D30: =SUMIFS('24년 9월'!$M:$M,'24년 9월'!$C:$C,"미래사업팀",'24년 9월'!$I:$I,"EV") -> 0 | E30: =SUMIFS('25년 9월'!$M:$M,'25년 9월'!$C:$C,"사업지원팀",'25년 9월'!$I:$I,"경유") -> 0 | F30: =SUMIFS('25년 9월'!$M:$M,'25년 9월'!$C:$C,"사업지원팀",'25년 9월'!$I:$I,"휘발유") -> 220000 | G30: =SUMIFS('25년 9월'!$M:$M,'25년 9월'!$C:$C,"사업지원팀",'25년 9월'!$I:$I,"EV") -> 0 | I30: 9월 | J30: =B30+C30+D30 -> 100000 | K30: =E30+F30+G30 -> 220000 | L30: =K30-J30 -> 120000
A31: 10월 | B31: =SUMIFS('24년 10월'!$M:$M,'24년 10월'!$C:$C,"미래사업팀",'24년 10월'!$I:$I,"경유") -> 0 | C31: =SUMIFS('24년 10월'!$M:$M,'24년 10월'!$C:$C,"미래사업팀",'24년 10월'!$I:$I,"휘발유") -> 338000 | D31: =SUMIFS('24년 10월'!$M:$M,'24년 10월'!$C:$C,"미래사업팀",'24년 10월'!$I:$I,"EV") -> 0 | E31: =SUMIFS('25년 10월'!$M:$M,'25년 10월'!$C:$C,"사업지원팀",'25년 10월'!$I:$I,"경유") -> 0 | F31: =SUMIFS('25년 10월'!$M:$M,'25년 10월'!$C:$C,"사업지원팀",'25년 10월'!$I:$I,"휘발유") -> 130000 | G31: =SUMIFS('25년 10월'!$M:$M,'25년 10월'!$C:$C,"사업지원팀",'25년 10월'!$I:$I,"EV") -> 0 | I31: 10월 | J31: =B31+C31+D31 -> 338000 | K31: =E31+F31+G31 -> 130000 | L31: =K31-J31 -> -208000
A32: 11월 | B32: =SUMIFS('24년 11월'!$M:$M,'24년 11월'!$C:$C,"미래사업팀",'24년 11월'!$I:$I,"경유") -> 0 | C32: =SUMIFS('24년 11월'!$M:$M,'24년 11월'!$C:$C,"미래사업팀",'24년 11월'!$I:$I,"휘발유") -> 187000 | D32: =SUMIFS('24년 11월'!$M:$M,'24년 11월'!$C:$C,"미래사업팀",'24년 11월'!$I:$I,"EV") -> 0 | E32: =SUMIFS('25년 11월'!$M:$M,'25년 11월'!$C:$C,"사업지원팀",'25년 11월'!$I:$I,"경유") -> 0 | F32: =SUMIFS('25년 11월'!$M:$M,'25년 11월'!$C:$C,"사업지원팀",'25년 11월'!$I:$I,"휘발유") -> 259000 | G32: =SUMIFS('25년 11월'!$M:$M,'25년 11월'!$C:$C,"사업지원팀",'25년 11월'!$I:$I,"EV") -> 0 | I32: 11월 | J32: =B32+C32+D32 -> 187000 | K32: =E32+F32+G32 -> 259000 | L32: =K32-J32 -> 72000
A33: 12월 | B33: =SUMIFS('24년 12월'!$M:$M,'24년 12월'!$C:$C,"미래사업팀",'24년 12월'!$I:$I,"경유") -> 0 | C33: =SUMIFS('24년 12월'!$M:$M,'24년 12월'!$C:$C,"미래사업팀",'24년 12월'!$I:$I,"휘발유") -> 210000 | D33: =SUMIFS('24년 12월'!$M:$M,'24년 12월'!$C:$C,"미래사업팀",'24년 12월'!$I:$I,"EV") -> 0 | E33: =SUMIFS('25년 12월'!$M:$M,'25년 12월'!$C:$C,"사업지원팀",'25년 12월'!$I:$I,"경유") -> 0 | F33: =SUMIFS('25년 12월'!$M:$M,'25년 12월'!$C:$C,"사업지원팀",'25년 12월'!$I:$I,"휘발유") -> 60000 | G33: =SUMIFS('25년 12월'!$M:$M,'25년 12월'!$C:$C,"사업지원팀",'25년 12월'!$I:$I,"EV") -> 0 | I33: 12월 | J33: =B33+C33+D33 -> 210000 | K33: =E33+F33+G33 -> 60000 | L33: =K33-J33 -> -150000
A34: 합계 | B34: =SUM(B22:B33) -> 0 | C34: =SUM(C22:C33) -> 835000 | D34: =SUM(D22:D33) -> 0 | E34: =SUM(E22:E33) -> 0 | F34: =SUM(F22:F33) -> 1832000 | G34: =SUM(G22:G33) -> 0 | L34: =SUM(L22:L33) -> 997000
A35: 현장경영팀
A37: 구분 | B37: 24년 | E37: 25년 | I37: 현장경영팀
B38: 경유 유류비 | C38: 휘발유 유류비 | D38: EV 유류비 | E38: 경유 유류비 | F38: 휘발유 유류비 | G38: EV 유류비 | I38: 구분 | J38: 24년 유류비 | K38: 25년 유류비 | L38: 증감비용
A39: 1월 | B39: =SUMIFS('24년 1월'!$M:$M,'24년 1월'!$C:$C,"현장경영팀",'24년 1월'!$I:$I,"경유") -> 0 | C39: =SUMIFS('24년 1월'!$M:$M,'24년 1월'!$C:$C,"현장경영팀",'24년 1월'!$I:$I,"휘발유") -> 170000 | D39: =SUMIFS('24년 1월'!$M:$M,'24년 1월'!$C:$C,"현장경영팀",'24년 1월'!$I:$I,"EV") -> 0 | E39: =SUMIFS('25년 1월'!$M:$M,'25년 1월'!$C:$C,"현장경영팀",'25년 1월'!$I:$I,"경유") -> 0 | F39: =SUMIFS('25년 1월'!$M:$M,'25년 1월'!$C:$C,"현장경영팀",'25년 1월'!$I:$I,"휘발유") -> 0 | G39: =SUMIFS('25년 1월'!$M:$M,'25년 1월'!$C:$C,"현장경영팀",'25년 1월'!$I:$I,"EV") -> 0 | I39: 1월 | J39: =B39+C39+D39 -> 170000 | K39: =E39+F39+G39 -> 0 | L39: =K39-J39 -> -170000
A40: 2월 | B40: =SUMIFS('24년 2월'!$M:$M,'24년 2월'!$C:$C,"현장경영팀",'24년 2월'!$I:$I,"경유") -> 0 | C40: =SUMIFS('24년 2월'!$M:$M,'24년 2월'!$C:$C,"현장경영팀",'24년 2월'!$I:$I,"휘발유") -> 200000 | D40: =SUMIFS('24년 2월'!$M:$M,'24년 2월'!$C:$C,"현장경영팀",'24년 2월'!$I:$I,"EV") -> 0 | E40: =SUMIFS('25년 2월'!$M:$M,'25년 2월'!$C:$C,"현장경영팀",'25년 2월'!$I:$I,"경유") -> 0 | F40: =SUMIFS('25년 2월'!$M:$M,'25년 2월'!$C:$C,"현장경영팀",'25년 2월'!$I:$I,"휘발유") -> 270000 | G40: =SUMIFS('25년 2월'!$M:$M,'25년 2월'!$C:$C,"현장경영팀",'25년 2월'!$I:$I,"EV") -> 0 | I40: 2월 | J40: =B40+C40+D40 -> 200000 | K40: =E40+F40+G40 -> 270000 | L40: =K40-J40 -> 70000
A41: 3월 | B41: =SUMIFS('24년 3월'!$M:$M,'24년 3월'!$C:$C,"현장경영팀",'24년 3월'!$I:$I,"경유") -> 0 | C41: =SUMIFS('24년 3월'!$M:$M,'24년 3월'!$C:$C,"현장경영팀",'24년 3월'!$I:$I,"휘발유") -> 150000 | D41: =SUMIFS('24년 3월'!$M:$M,'24년 3월'!$C:$C,"현장경영팀",'24년 3월'!$I:$I,"EV") -> 0 | E41: =SUMIFS('25년 3월'!$M:$M,'25년 3월'!$C:$C,"현장경영팀",'25년 3월'!$I:$I,"경유") -> 0 | F41: =SUMIFS('25년 3월'!$M:$M,'25년 3월'!$C:$C,"현장경영팀",'25년 3월'!$I:$I,"휘발유") -> 230000 | G41: =SUMIFS('25년 3월'!$M:$M,'25년 3월'!$C:$C,"현장경영팀",'25년 3월'!$I:$I,"EV") -> 0 | I41: 3월 | J41: =B41+C41+D41 -> 150000 | K41: =E41+F41+G41 -> 230000 | L41: =K41-J41 -> 80000
A42: 4월 | B42: =SUMIFS('24년 4월'!$M:$M,'24년 4월'!$C:$C,"현장경영팀",'24년 4월'!$I:$I,"경유") -> 0 | C42: =SUMIFS('24년 4월'!$M:$M,'24년 4월'!$C:$C,"현장경영팀",'24년 4월'!$I:$I,"휘발유") -> 270000 | D42: =SUMIFS('24년 4월'!$M:$M,'24년 4월'!$C:$C,"현장경영팀",'24년 4월'!$I:$I,"EV") -> 0 | E42: =SUMIFS('25년 4월'!$M:$M,'25년 4월'!$C:$C,"현장경영팀",'25년 4월'!$I:$I,"경유") -> 0 | F42: =SUMIFS('25년 4월'!$M:$M,'25년 4월'!$C:$C,"현장경영팀",'25년 4월'!$I:$I,"휘발유") -> 440000 | G42: =SUMIFS('25년 4월'!$M:$M,'25년 4월'!$C:$C,"현장경영팀",'25년 4월'!$I:$I,"EV") -> 0 | I42: 4월 | J42: =B42+C42+D42 -> 270000 | K42: =E42+F42+G42 -> 440000 | L42: =K42-J42 -> 170000
A43: 5월 | B43: =SUMIFS('24년 5월'!$M:$M,'24년 5월'!$C:$C,"현장경영팀",'24년 5월'!$I:$I,"경유") -> 0 | C43: =SUMIFS('24년 5월'!$M:$M,'24년 5월'!$C:$C,"현장경영팀",'24년 5월'!$I:$I,"휘발유") -> 245000 | D43: =SUMIFS('24년 5월'!$M:$M,'24년 5월'!$C:$C,"현장경영팀",'24년 5월'!$I:$I,"EV") -> 0 | E43: =SUMIFS('25년 5월'!$M:$M,'25년 5월'!$C:$C,"현장경영팀",'25년 5월'!$I:$I,"경유") -> 0 | F43: =SUMIFS('25년 5월'!$M:$M,'25년 5월'!$C:$C,"현장경영팀",'25년 5월'!$I:$I,"휘발유") -> 230000 | G43: =SUMIFS('25년 5월'!$M:$M,'25년 5월'!$C:$C,"현장경영팀",'25년 5월'!$I:$I,"EV") -> 0 | I43: 5월 | J43: =B43+C43+D43 -> 245000 | K43: =E43+F43+G43 -> 230000 | L43: =K43-J43 -> -15000
...

Sheet 25년 12월
A1: 순번 | B1: 본부 | C1: 팀/파트 | D1: 사용자 | E1: 구입형태 | F1: 차종 | G1: 모델명 | H1: 차량번호 | I1: 연료 | J1: 평균운행일수 | K1: 총주행거리 (Km) | L1: 업무용 사용거리 (km) | M1: 법인카드 | X1: 현금사용 | AI1: 합계 ①+② | AJ1: 평균주유비(Km)
M2: 유류비 | N2: 하이패스 | O2: 주차비 | P2: 통행료 | Q2: 세차비 | R2: 도선료 | S2: 수선비 | T2: 경정비 | U2: 비상주유 | V2: 발전기유류비 | W2: 소계① | X2: 유류비 | Y2: 하이패스 | Z2: 주차비 | AA2: 통행료 | AB2: 세차비 | AC2: 도선료 | AD2: 수선비 | AE2: 경정비 | AF2: 비상주유 | AG2: 발전기유류비 | AH2: 소계② | AJ2: 평균주유비(Km)
A3: 1 | B3: 대구본부 | C3: 운용지원팀 | E3: 렌트 | F3: 경차 | G3: 모닝(L) | H3: 52하9955 | I3: 휘발유 | J3: 0 | K3: 0 | L3: 0 | M3: 0 | N3: 0 | O3: 0 | P3: 0 | Q3: 0 | R3: 0 | S3: 0 | T3: 0 | U3: 0 | V3: 0 | W3: 0 | X3: 0 | Y3: 0 | Z3: 0 | AA3: 0 | AB3: 0 | AC3: 0 | AD3: 0 | AE3: 0 | AF3: 0 | AG3: 0 | AH3: 0 | AI3: 0 | AJ3: 0
A4: 2 | B4: 대구본부 | C4: 운용지원팀 | E4: 자차 | F4: 기타 | G4: 포터 | H4: 91주1465 | I4: 경유 | J4: 0 | K4: 0 | L4: 0 | M4: 0 | N4: 0 | O4: 0 | P4: 0 | Q4: 0 | R4: 0 | S4: 0 | T4: 0 | U4: 0 | V4: 0 | W4: 0 | X4: 0 | Y4: 0 | Z4: 0 | AA4: 0 | AB4: 0 | AC4: 0 | AD4: 0 | AE4: 0 | AF4: 0 | AG4: 0 | AH4: 0 | AI4: 0 | AJ4: 0
A5: 3 | B5: 대구본부 | C5: 운용지원팀 | E5: 자차 | F5: 기타 | G5: 포터 | H5: 81더6676 | I5: 경유 | J5: 0 | K5: 0 | L5: 0 | M5: 0 | N5: 0 | O5: 0 | P5: 0 | Q5: 0 | R5: 0 | S5: 0 | T5: 0 | U5: 0 | V5: 0 | W5: 0 | X5: 0 | Y5: 0 | Z5: 0 | AA5: 0 | AB5: 0 | AC5: 0 | AD5: 0 | AE5: 0 | AF5: 0 | AG5: 0 | AH5: 0 | AI5: 0 | AJ5: 0
A6: 4 | B6: 대구본부 | C6: 운용지원팀 | E6: 렌트 | F6: RV/SUV | G6: 티볼리 | H6: 104허4264 | I6: 경유 | J6: 0 | K6: 0 | L6: 0 | M6: 0 | N6: 0 | O6: 0 | P6: 0 | Q6: 0 | R6: 0 | S6: 0 | T6: 0 | U6: 0 | V6: 0 | W6: 0 | X6: 0 | Y6: 0 | Z6: 0 | AA6: 0 | AB6: 0 | AC6: 0 | AD6: 0 | AE6: 0 | AF6: 0 | AG6: 0 | AH6: 0 | AI6: 0 | AJ6: 0
A7: 5 | B7: 대구본부 | C7: 운용지원팀 | E7: 리스 | F7: RV/SUV | G7: 스타리아 | H7: 86부5462 | I7: 경유 | J7: 0 | K7: 0 | L7: 0 | M7: 0 | N7: 0 | O7: 0 | P7: 0 | Q7: 0 | R7: 0 | S7: 0 | T7: 0 | U7: 0 | V7: 0 | W7: 0 | X7: 0 | Y7: 0 | Z7: 0 | AA7: 0 | AB7: 0 | AC7: 0 | AD7: 0 | AE7: 0 | AF7: 0 | AG7: 0 | AH7: 0 | AI7: 0 | AJ7: 0
A8: 6 | B8: 대구본부 | C8: 운용지원팀 | E8: 렌트 | F8: 기타 | G8: 카니발 | H8: 대차/145호1899(104허4264) | I8: 경유 | J8: 0 | K8: 0 | L8: 0 | M8: 0 | N8: 0 | O8: 0 | P8: 0 | Q8: 0 | R8: 0 | S8: 0 | T8: 0 | U8: 0 | V8: 0 | W8: 0 | X8: 0 | Y8: 0 | Z8: 0 | AA8: 0 | AB8: 0 | AC8: 0 | AD8: 0 | AE8: 0 | AF8: 0 | AG8: 0 | AH8: 0 | AI8: 0 | AJ8: 0
A9: 7 | B9: 대구본부 | C9: 운용지원팀 | E9: 렌트 | F9: 중형승용 | G9: K5 | H9: 대차/52호0200(104허4264) | I9: 휘발유 | J9: 0 | K9: 0 | L9: 0 | M9: 0 | N9: 0 | O9: 0 | P9: 0 | Q9: 0 | R9: 0 | S9: 0 | T9: 0 | U9: 0 | V9: 0 | W9: 0 | X9: 0 | Y9: 0 | Z9: 0 | AA9: 0 | AB9: 0 | AC9: 0 | AD9: 0 | AE9: 0 | AF9: 0 | AG9: 0 | AH9: 0 | AI9: 0 | AJ9: 0
A10: 8 | B10: 대구본부 | C10: 운용지원팀 | E10: 렌트 | F10: 소형승용 | G10: 아반떼CN7 | H10: 대차/03호7536(104허4264) | I10: 휘발유 | J10: 0 | K10: 0 | L10: 0 | M10: 0 | N10: 0 | O10: 0 | P10: 0 | Q10: 0 | R10: 0 | S10: 0 | T10: 0 | U10: 0 | V10: 0 | W10: 0 | X10: 0 | Y10: 0 | Z10: 0 | AA10: 0 | AB10: 0 | AC10: 0 | AD10: 0 | AE10: 0 | AF10: 0 | AG10: 0 | AH10: 0 | AI10: 0 | AJ10: 0
A11: 9 | B11: 대구본부 | C11: 운용지원팀 | E11: 렌트 | F11: RV/SUV | G11: K5 | H11: 대차/104허1705(104허4264) | I11: 경유 | J11: 0 | K11: 0 | L11: 0 | M11: 0 | N11: 0 | O11: 0 | P11: 0 | Q11: 0 | R11: 0 | S11: 0 | T11: 0 | U11: 0 | V11: 0 | W11: 0 | X11: 0 | Y11: 0 | Z11: 0 | AA11: 0 | AB11: 0 | AC11: 0 | AD11: 0 | AE11: 0 | AF11: 0 | AG11: 0 | AH11: 0 | AI11: 0 | AJ11: 0
A12: 10 | B12: 대구본부 | C12: 운용지원팀 | D12: 이승욱 | E12: 렌트 | F12: RV/SUV | G12: 셀토스 | H12: 231허4115 | I12: 휘발유 | J12: 12 | K12: 696 | L12: 696 | M12: 129249 | N12: 0 | O12: 0 | P12: 0 | Q12: 49000 | R12: 0 | S12: 0 | T12: 0 | U12: 0 | V12: 0 | W12: 178249 | X12: 0 | Y12: 0 | Z12: 0 | AA12: 0 | AB12: 0 | AC12: 0 | AD12: 0 | AE12: 0 | AF12: 0 | AG12: 0 | AH12: 0 | AI12: 178249 | AJ12: 185
A13: 11 | B13: 대구본부 | C13: 운용지원팀 | D13: 권재은 | E13: 렌트 | F13: RV/SUV | G13: 스타리아 | H13: 815머9749 | I13: 경유 | J13: 12 | K13: 1414 | L13: 1414 | M13: 160000 | N13: 0 | O13: 0 | P13: 0 | Q13: 66000 | R13: 0 | S13: 0 | T13: 0 | U13: 0 | V13: 0 | W13: 226000 | X13: 0 | Y13: 0 | Z13: 0 | AA13: 0 | AB13: 0 | AC13: 0 | AD13: 0 | AE13: 0 | AF13: 0 | AG13: 0 | AH13: 0 | AI13: 226000 | AJ13: 113
B14: 소계 | C14: 운용지원팀 | K14: 2110 | L14: 2110 | M14: 289249 | N14: 0 | O14: 0 | P14: 0 | Q14: 115000 | R14: 0 | S14: 0 | T14: 0 | U14: 0 | V14: 0 | W14: 404249 | X14: 0 | Y14: 0 | Z14: 0 | AA14: 0 | AB14: 0 | AC14: 0 | AD14: 0 | AE14: 0 | AF14: 0 | AG14: 0 | AH14: 0 | AI14: 404249
A15: 1 | B15: 대구본부 | C15: 현장경영팀 | E15: 자차 | F15: EV | G15: 아이오닉 | H15: 48머6029 | I15: EV | J15: 0 | K15: 0 | L15: 0 | M15: 0 | N15: 0 | O15: 0 | P15: 0 | Q15: 0 | R15: 0 | S15: 0 | T15: 0 | U15: 0 | V15: 0 | W15: 0 | X15: 0 | Y15: 0 | Z15: 0 | AA15: 0 | AB15: 0 | AC15: 0 | AD15: 0 | AE15: 0 | AF15: 0 | AG15: 0 | AH15: 0 | AI15: 0 | AJ15: 0
A16: 2 | B16: 대구본부 | C16: 현장경영팀 | E16: 렌트 | F16: 중형승용 | G16: 쏘나타(뉴라이즈) | H16: 57하0412 | I16: 휘발유 | J16: 0 | K16: 0 | L16: 0 | M16: 0 | N16: 0 | O16: 0 | P16: 0 | Q16: 0 | R16: 0 | S16: 0 | T16: 0 | U16: 0 | V16: 0 | W16: 0 | X16: 0 | Y16: 0 | Z16: 0 | AA16: 0 | AB16: 0 | AC16: 0 | AD16: 0 | AE16: 0 | AF16: 0 | AG16: 0 | AH16: 0 | AI16: 0 | AJ16: 0
A17: 3 | B17: 대구본부 | C17: 현장경영팀 | D17: 류재하 | E17: 렌트 | F17: 소형승용 | G17: K3 | H17: 160허3488 | I17: 휘발유 | J17: 13 | K17: 1202 | L17: 1202 | M17: 100000 | N17: 0 | O17: 0 | P17: 0 | Q17: 0 | R17: 0 | S17: 0 | T17: 0 | U17: 0 | V17: 0 | W17: 100000 | X17: 0 | Y17: 0 | Z17: 0 | AA17: 0 | AB17: 0 | AC17: 0 | AD17: 0 | AE17: 0 | AF17: 0 | AG17: 0 | AH17: 0 | AI17: 100000 | AJ17: 83
A18: 4 | B18: 대구본부 | C18: 현장경영팀 | E18: 렌트 | F18: 중형승용 | G18: K5(Hybrid) | H18: 193허1626 | I18: 휘발유 | J18: 0 | K18: 0 | L18: 0 | M18: 0 | N18: 0 | O18: 0 | P18: 0 | Q18: 0 | R18: 0 | S18: 0 | T18: 0 | U18: 0 | V18: 0 | W18: 0 | X18: 0 | Y18: 0 | Z18: 0 | AA18: 0 | AB18: 0 | AC18: 0 | AD18: 0 | AE18: 0 | AF18: 0 | AG18: 0 | AH18: 0 | AI18: 0 | AJ18: 0
A19: 5 | B19: 대구본부 | C19: 현장경영팀 | D19: 류재하 | E19: 렌트 | F19: 중형승용 | G19: K5 | H19: 192허4930 | I19: 휘발유 | J19: 17 | K19: 929 | L19: 929 | M19: 94000 | N19: 0 | O19: 0 | P19: 0 | Q19: 0 | R19: 0 | S19: 0 | T19: 0 | U19: 0 | V19: 0 | W19: 94000 | X19: 0 | Y19: 0 | Z19: 0 | AA19: 0 | AB19: 0 | AC19: 0 | AD19: 0 | AE19: 0 | AF19: 0 | AG19: 0 | AH19: 0 | AI19: 94000 | AJ19: 101
B20: 소계 | C20: 현장경영팀 | K20: 2131 | L20: 2131 | M20: 194000 | N20: 0 | O20: 0 | P20: 0 | Q20: 0 | R20: 0 | S20: 0 | T20: 0 | U20: 0 | V20: 0 | W20: 194000 | X20: 0 | Y20: 0 | Z20: 0 | AA20: 0 | AB20: 0 | AC20: 0 | AD20: 0 | AE20: 0 | AF20: 0 | AG20: 0 | AH20: 0 | AI20: 194000
A21: 1 | B21: 대구본부 | C21: 동대구운용팀 | E21: 렌트 | F21: RV/SUV | G21: 스포티지 | H21: 04호8776 | I21: 경유 | J21: 0 | K21: 0 | L21: 0 | M21: 0 | N21: 0 | O21: 0 | P21: 0 | Q21: 0 | R21: 0 | S21: 0 | T21: 0 | U21: 0 | V21: 0 | W21: 0 | X21: 0 | Y21: 0 | Z21: 0 | AA21: 0 | AB21: 0 | AC21: 0 | AD21: 0 | AE21: 0 | AF21: 0 | AG21: 0 | AH21: 0 | AI21: 0 | AJ21: 0
A22: 2 | B22: 대구본부 | C22: 동대구운용팀 | E22: 렌트 | F22: EV | G22: SOUL EV | H22: 14허8876 | I22: EV | J22: 0 | K22: 0 | L22: 0 | M22: 0 | N22: 0 | O22: 0 | P22: 0 | Q22: 0 | R22: 0 | S22: 0 | T22: 0 | U22: 0 | V22: 0 | W22: 0 | X22: 0 | Y22: 0 | Z22: 0 | AA22: 0 | AB22: 0 | AC22: 0 | AD22: 0 | AE22: 0 | AF22: 0 | AG22: 0 | AH22: 0 | AI22: 0 | AJ22: 0
A23: 3 | B23: 대구본부 | C23: 동대구운용팀 | E23: 렌트 | F23: EV | G23: SOUL EV | H23: 14허8880 | I23: EV | J23: 0 | K23: 0 | L23: 0 | M23: 0 | N23: 0 | O23: 0 | P23: 0 | Q23: 0 | R23: 0 | S23: 0 | T23: 0 | U23: 0 | V23: 0 | W23: 0 | X23: 0 | Y23: 0 | Z23: 0 | AA23: 0 | AB23: 0 | AC23: 0 | AD23: 0 | AE23: 0 | AF23: 0 | AG23: 0 | AH23: 0 | AI23: 0 | AJ23: 0
A24: 4 | B24: 대구본부 | C24: 동대구운용팀 | E24: 렌트 | F24: RV/SUV | G24: 스포티지 | H24: 18하9596 | I24: 경유 | J24: 0 | K24: 0 | L24: 0 | M24: 0 | N24: 0 | O24: 0 | P24: 0 | Q24: 0 | R24: 0 | S24: 0 | T24: 0 | U24: 0 | V24: 0 | W24: 0 | X24: 0 | Y24: 0 | Z24: 0 | AA24: 0 | AB24: 0 | AC24: 0 | AD24: 0 | AE24: 0 | AF24: 0 | AG24: 0 | AH24: 0 | AI24: 0 | AJ24: 0
A25: 5 | B25: 대구본부 | C25: 동대구운용팀 | E25: 렌트 | F25: 경차 | G25: 모닝(L) | H25: 18호9534 | I25: 휘발유 | J25: 0 | K25: 0 | L25: 0 | M25: 0 | N25: 0 | O25: 0 | P25: 0 | Q25: 0 | R25: 0 | S25: 0 | T25: 0 | U25: 0 | V25: 0 | W25: 0 | X25: 0 | Y25: 0 | Z25: 0 | AA25: 0 | AB25: 0 | AC25: 0 | AD25: 0 | AE25: 0 | AF25: 0 | AG25: 0 | AH25: 0 | AI25: 0 | AJ25: 0
A26: 6 | B26: 대구본부 | C26: 동대구운용팀 | E26: 렌트 | F26: RV/SUV | G26: 스포티지 | H26: 44호7855 | I26: 경유 | J26: 0 | K26: 0 | L26: 0 | M26: 0 | N26: 0 | O26: 0 | P26: 0 | Q26: 0 | R26: 0 | S26: 0 | T26: 0 | U26: 0 | V26: 0 | W26: 0 | X26: 0 | Y26: 0 | Z26: 0 | AA26: 0 | AB26: 0 | AC26: 0 | AD26: 0 | AE26: 0 | AF26: 0 | AG26: 0 | AH26: 0 | AI26: 0 | AJ26: 0
A27: 7 | B27: 대구본부 | C27: 동대구운용팀 | E27: 렌트 | F27: 경차 | G27: 모닝 | H27: 62호6573 | I27: 휘발유 | J27: 0 | K27: 0 | L27: 0 | M27: 0 | N27: 0 | O27: 0 | P27: 0 | Q27: 0 | R27: 0 | S27: 0 | T27: 0 | U27: 0 | V27: 0 | W27: 0 | X27: 0 | Y27: 0 | Z27: 0 | AA27: 0 | AB27: 0 | AC27: 0 | AD27: 0 | AE27: 0 | AF27: 0 | AG27: 0 | AH27: 0 | AI27: 0 | AJ27: 0
A28: 8 | B28: 대구본부 | C28: 동대구운용팀 | E28: 렌트 | F28: RV/SUV | G28: 스포티지 | H28: 64하2008 | I28: 경유 | J28: 0 | K28: 0 | L28: 0 | M28: 0 | N28: 0 | O28: 0 | P28: 0 | Q28: 0 | R28: 0 | S28: 0 | T28: 0 | U28: 0 | V28: 0 | W28: 0 | X28: 0 | Y28: 0 | Z28: 0 | AA28: 0 | AB28: 0 | AC28: 0 | AD28: 0 | AE28: 0 | AF28: 0 | AG28: 0 | AH28: 0 | AI28: 0 | AJ28: 0
A29: 9 | B29: 대구본부 | C29: 동대구운용팀 | E29: 렌트 | F29: 경차 | G29: 모닝 | H29: 64하9806 | I29: 휘발유 | J29: 0 | K29: 0 | L29: 0 | M29: 0 | N29: 0 | O29: 0 | P29: 0 | Q29: 0 | R29: 0 | S29: 0 | T29: 0 | U29: 0 | V29: 0 | W29: 0 | X29: 0 | Y29: 0 | Z29: 0 | AA29: 0 | AB29: 0 | AC29: 0 | AD29: 0 | AE29: 0 | AF29: 0 | AG29: 0 | AH29: 0 | AI29: 0 | AJ29: 0
A30: 10 | B30: 대구본부 | C30: 동대구운용팀 | E30: 렌트 | F30: RV/SUV | G30: 스포티지 | H30: 66하5803 | I30: 경유 | J30: 0 | K30: 0 | L30: 0 | M30: 0 | N30: 0 | O30: 0 | P30: 0 | Q30: 0 | R30: 0 | S30: 0 | T30: 0 | U30: 0 | V30: 0 | W30: 0 | X30: 0 | Y30: 0 | Z30: 0 | AA30: 0 | AB30: 0 | AC30: 0 | AD30: 0 | AE30: 0 | AF30: 0 | AG30: 0 | AH30: 0 | AI30: 0 | AJ30: 0
A31: 11 | B31: 대구본부 | C31: 동대구운용팀 | E31: 렌트 | F31: 경차 | G31: 모닝(L) | H31: 52하9940 | I31: 휘발유 | J31: 0 | K31: 0 | L31: 0 | M31: 0 | N31: 0 | O31: 0 | P31: 0 | Q31: 0 | R31: 0 | S31: 0 | T31: 0 | U31: 0 | V31: 0 | W31: 0 | X31: 0 | Y31: 0 | Z31: 0 | AA31: 0 | AB31: 0 | AC31: 0 | AD31: 0 | AE31: 0 | AF31: 0 | AG31: 0 | AH31: 0 | AI31: 0 | AJ31: 0
A32: 12 | B32: 대구본부 | C32: 동대구운용팀 | E32: 리스 | F32: 고소작업_2.5톤 | G32: 마이티2.5톤(고소작업차) | H32: 98조7255 | I32: 경유 | J32: 0 | K32: 0 | L32: 0 | M32: 0 | N32: 0 | O32: 0 | P32: 0 | Q32: 0 | R32: 0 | S32: 0 | T32: 0 | U32: 0 | V32: 0 | W32: 0 | X32: 0 | Y32: 0 | Z32: 0 | AA32: 0 | AB32: 0 | AC32: 0 | AD32: 0 | AE32: 0 | AF32: 0 | AG32: 0 | AH32: 0 | AI32: 0 | AJ32: 0
... A41: 21 | B41: 대구본부 | C41: 동대구운용팀 | E41: 렌트 | F41: RV/SUV | G41: 싼타페 | H41: 대차/03하8919(128허4949) | I41: 경유 | J41: 0 | K41: 0 | L41: 0 | M41: 0 | N41: 0 | O41: 0 | P41: 0 | Q41: 0 | R41: 0 | S41: 0 | T41: 0 | U41: 0 | V41: 0 | W41: 0 | X41: 0 | Y41: 0 | Z41: 0 | AA41: 0 | AB41: 0 | AC41: 0 | AD41: 0 | AE41: 0 | AF41: 0 | AG41: 0 | AH41: 0 | AI41: 0 | AJ41: 0
A42: 22 | B42: 대구본부 | C42: 동대구운용팀 | D42: 공재민 | E42: 렌트 | F42: 경차 | G42: 모닝(승용) | H42: 165허9309 | I42: 휘발유 | J42: 13 | K42: 1496 | L42: 1496 | M42: 121000 | N42: 0 | O42: 0 | P42: 0 | Q42: 0 | R42: 0 | S42: 0 | T42: 0 | U42: 0 | V42: 0 | W42: 121000 | X42: 0 | Y42: 0 | Z42: 0 | AA42: 0 | AB42: 0 | AC42: 0 | AD42: 0 | AE42: 0 | AF42: 0 | AG42: 0 | AH42: 0 | AI42: 121000 | AJ42: 80
A43: 23 | B43: 대구본부 | C43: 동대구운용팀 | D43: 이상우 | E43: 렌트 | F43: 경차 | G43: 모닝(승용) | H43: 165허9310 | I43: 휘발유 | J43: 15 | K43: 1777 | L43: 1777 | M43: 257000 | N43: 0 | O43: 0 | P43: 0 | Q43: 0 | R43: 0 | S43: 0 | T43: 0 | U43: 0 | V43: 0 | W43: 257000 | X43: 0 | Y43: 0 | Z43: 0 | AA43: 0 | AB43: 0 | AC43: 0 | AD43: 0 | AE43: 0 | AF43: 0 | AG43: 0 | AH43: 0 | AI43: 257000 | AJ43: 144
A44: 24 | B44: 대구본부 | C44: 동대구운용팀 | D44: 김두종 | E44: 렌트 | F44: RV/SUV | G44: 스포티지 | H44: 165허9671 | I44: 경유 | J44: 23 | K44: 2302 | L44: 2302 | M44: 360000 | N44: 0 | O44: 0 | P44: 0 | Q44: 0 | R44: 0 | S44: 0 | T44: 0 | U44: 0 | V44: 0 | W44: 360000 | X44: 0 | Y44: 0 | Z44: 0 | AA44: 0 | AB44: 0 | AC44: 0 | AD44: 0 | AE44: 0 | AF44: 0 | AG44: 0 | AH44: 0 | AI44: 360000 | AJ44: 156
